Workbook

Sheet Resumen de exportación
B3: Este documento se exportó de Numbers. Cada tabla se convirtió en una hoja de cálculo de Excel. Los demás objetos de las hojas de Numbers se colocaron en distintas hojas de cálculo. Recuerda que el cálculo de fórmulas puede ser diferente en Excel.
B7: Nombre de hoja de Numbers | C7: Nombre de tabla de Numbers | D7: Nombre de hoja de cálculo de Excel
B9: Inicio
C10: Tabla 1 | D10: Inicio
B11: Resumen TIMSS y PISA
C12: Tabla 1 | D12: Resumen TIMSS y PISA
B13: Apego TIMSS y PISA
C14: Tabla 1 | D14: Apego TIMSS y PISA
B15: Presupuesto de temas
C16: Tabla 1 | D16: Presupuesto de temas
B17: TIMSS - Balance por ciclo
C18: Tabla 1 | D18: TIMSS - Balance por ciclo
B19: TIMSS - Balance por grado
C20: Tabla 1 | D20: TIMSS - Balance por grado
B21: TIMSS - Semáforo de objetivos
C22: Tabla 1 | D22: TIMSS - Semáforo de objetivos
B23: TIMSS - Conocer-Aplicar-Razonar
C24: Tabla 1 | D24: TIMSS - Conocer-Aplicar-Razonar
B25: TIMSS - Medio ambiente
C26: Tabla 1 | D26: TIMSS - Medio ambiente
B27: TIMSS - Investigación
C28: Tabla 1 | D28: TIMSS - Investigación
B29: TIMSS - Otros países
C30: Tabla 1 | D30: TIMSS - Otros países
B31: PISA - Contenidos
C32: Tabla 1 | D32: PISA - Contenidos
B33: PISA - Competencias
C34: Tabla 1 | D34: PISA - Competencias
B35: PISA - Tipos de conocimiento
C36: Tabla 1 | D36: PISA - Tipos de conocimiento
B37: PISA - Contextos
C38: Tabla 1 | D38: PISA - Contextos
B39: Datos - Temas
C40: Tabla 1 | D40: Datos - Temas
B41: Datos - Catálogo TIMSS
C42: Tabla 1 | D42: Datos - Catálogo TIMSS
B43: Datos - Catálogo PISA
C44: Tabla 1 | D44: Datos - Catálogo PISA
B45: Datos - Objetivos de países
C46: Tabla 1 | D46: Datos - Objetivos de países
...

Sheet Inicio
B1: Cobertura de la malla de Ciencia y Tecnología frente a TIMSS 2027 y PISA 2025 — hallazgos, cómo se construyó y cómo leerla
B2: Versión 3 (TIMSS 2027 + PISA 2025) · 2 de octubre de 2026 · Elaborado con Claude Code a partir de las mallas del equipo de Ciencias (MINED). Las versiones anteriores (TIMSS 2023) se conservan en Cobertura_TIMSS_Ciencias_SV.xlsx.
B3: {="TIMSS 2027 y PISA 2025"&" "&"BIEN · En lo acumulado la malla se parece a las pruebas: "&FIXED('Apego TIMSS y PISA'!F17*100,0)&" %"&" (TIMSS 4.°), "&FIXED('Apego TIMSS y PISA'!F18*100,0)&" %"&" (TIMSS 8.°) y "&FIXED('Apego TIMSS y PISA'!F23*100,0)&" %"&" (PISA) de apego."&" "&"OJO · TIMSS: falta Biología en 5.°, luz-sonido-electricidad en 4.° y más Razonar en 6.° y 8.°."&" "&"OJO · PISA: falta biología en 9.°, Tierra y espacio en 8.°, y enseñar a evaluar información y el porqué de la ciencia."&" "&"→ Empieza por «Resumen TIMSS y PISA» y «Presupuesto de temas». Las pestañas que empiezan con TIMSS o PISA tienen el detalle de cada prueba."} -> TIMSS 2027 y PISA 2025 BIEN · En lo acumulado la malla se parece a las pruebas: 92 % (TIMSS 4.°), 88 % (TIMSS 8.°) y 88 % (PISA) de apego. OJO · TIMSS: falta Biología en 5.°, luz-sonido-electricidad en 4.° y más Razonar en 6.° y 8.°. OJO · PISA: falta biología en 9.°, Tierra y espacio en 8.°, y enseñar a evaluar información y el porqué de la ciencia. → Empieza por «Resumen TIMSS y PISA» y «Presupuesto de temas». Las pestañas que empiezan con TIMSS o PISA tienen el detalle de cada prueba.
B5: Resumen ejecutivo (las cifras se recalculan con el libro)
B6: {="1. Apego general. En lo acumulado, la malla se parece mucho a lo que piden las pruebas: índice de apego de "&FIXED('Apego TIMSS y PISA'!F17*100,0)&" %"&" frente a TIMSS 4.° (2.°–4.°), "&FIXED('Apego TIMSS y PISA'!F18*100,0)&" %"&" frente a TIMSS 8.° (5.°–8.°) y "&FIXED('Apego TIMSS y PISA'!F23*100,0)&" %"&" frente a PISA (7.°–9.°). Cubre "&'TIMSS - Semáforo de objetivos'!D115&" de "&'TIMSS - Semáforo de objetivos'!C115&" objetivos de TIMSS 4.°, "&'TIMSS - Semáforo de objetivos'!D120&" de "&'TIMSS - Semáforo de objetivos'!C120&" de TIMSS 8.° y "&'PISA - Contenidos'!C55&" de 21 categorías de contenido de PISA. Los problemas están en el reparto entre grados y en las capas propias de PISA."} -> 1. Apego general. En lo acumulado, la malla se parece mucho a lo que piden las pruebas: índice de apego de 92 % frente a TIMSS 4.° (2.°–4.°), 88 % frente a TIMSS 8.° (5.°–8.°) y 88 % frente a PISA (7.°–9.°). Cubre 31 de 32 objetivos de TIMSS 4.°, 45 de 48 de TIMSS 8.° y 20 de 21 categorías de contenido de PISA. Los problemas están en el reparto entre grados y en las capas propias de PISA.
B7: {="2. Grados a mejorar. 5.° es el grado con menor apego ("&FIXED('Apego TIMSS y PISA'!F11*100,0)&" %"&"): le faltan unos "&FIXED('TIMSS - Balance por grado'!I21,0)&" temas de Biología del marco de 8.°, que Uruguay, Colombia y Singapur enseñan en 5.°–6.° y El Salvador recién en 6.°–7.°. En 4.° faltan unos "&FIXED('TIMSS - Balance por grado'!I17,0)&" temas de Ciencias físicas (luz, sonido, electricidad, imanes). 8.° tiene solo "&'PISA - Contenidos'!D13&" temas de Tierra y espacio y 9.° solo "&'PISA - Contenidos'!D17&" de sistemas vivos (ni célula, ni genética, ni salud humana). En 6.° y 8.° Razonar queda en "&FIXED('TIMSS - Conocer-Aplicar-Razonar'!I9*100,0)&" %"&" y "&FIXED('TIMSS - Conocer-Aplicar-Razonar'!I11*100,0)&" %"&" (meta TIMSS 30 %)."} -> 2. Grados a mejorar. 5.° es el grado con menor apego (69 %): le faltan unos 19 temas de Biología del marco de 8.°, que Uruguay, Colombia y Singapur enseñan en 5.°–6.° y El Salvador recién en 6.°–7.°. En 4.° faltan unos 13 temas de Ciencias físicas (luz, sonido, electricidad, imanes). 8.° tiene solo 6 temas de Tierra y espacio y 9.° solo 3 de sistemas vivos (ni célula, ni genética, ni salud humana). En 6.° y 8.° Razonar queda en 19 % y 21 % (meta TIMSS 30 %).
B8: {="3. Competencias PISA. La malla declara una competencia y cinco subcompetencias por tema (columnas de la propia malla). En 7.°–9.° la competencia 3, «Investigar, evaluar y usar información para decidir», llega a "&FIXED('PISA - Competencias'!H16*100,0)&" %"&" de los temas (PISA: 24–36 %); distinguir evidencia de opinión (I2), criticar argumentos (I4) y formular hipótesis (E5) casi no aparecen. La competencia 2 está sobrerrepresentada ("&FIXED('PISA - Competencias'!G16*100,0)&" %"&")."} -> 3. Competencias PISA. La malla declara una competencia y cinco subcompetencias por tema (columnas de la propia malla). En 7.°–9.° la competencia 3, «Investigar, evaluar y usar información para decidir», llega a 14 % de los temas (PISA: 24–36 %); distinguir evidencia de opinión (I2), criticar argumentos (I4) y formular hipótesis (E5) casi no aparecen. La competencia 2 está sobrerrepresentada (50 %).
B9: {="4. Conocimiento procedimental y epistémico (lo que más agrega PISA). Solo "&FIXED('PISA - Tipos de conocimiento'!G16*100,0)&" %"&" de los temas de 7.°–9.° tienen como foco el conocimiento procedimental (PISA: 27–33 %) y ninguno el epistémico (24–30 %). "&'PISA - Tipos de conocimiento'!E57&" de los 20 elementos epistémicos (modelos frente a realidad, consenso, revisión por pares, límites de la certeza) no se trabajan en ningún tema."} -> 4. Conocimiento procedimental y epistémico (lo que más agrega PISA). Solo 5 % de los temas de 7.°–9.° tienen como foco el conocimiento procedimental (PISA: 27–33 %) y ninguno el epistémico (24–30 %). 12 de los 20 elementos epistémicos (modelos frente a realidad, consenso, revisión por pares, límites de la certeza) no se trabajan en ningún tema.
B10: {="5. Contextos. "&FIXED('PISA - Contextos'!G16*100,0)&" %"&" de los temas de 7.°–9.° no sitúan la ciencia en una situación real ("&FIXED('PISA - Contextos'!G14*100,0)&" %"&" en 8.°). Cuando hay contexto, el reparto personal / local / global se parece al 1:2:1 de PISA."} -> 5. Contextos. 64 % de los temas de 7.°–9.° no sitúan la ciencia en una situación real (86 % en 8.°). Cuando hay contexto, el reparto personal / local / global se parece al 1:2:1 de PISA.
B11: {="6. Frente a otros países, El Salvador introduce "&COUNTIF('TIMSS - Otros países'!$K$5:$K$84,"El Salvador llega más tarde")&" objetivos TIMSS más tarde que la mediana, "&COUNTIF('TIMSS - Otros países'!$K$5:$K$84,"El Salvador va adelantado")&" antes y no trabaja "&COUNTIF('TIMSS - Otros países'!$K$5:$K$84,"El Salvador no llega")&" que otros sí (herencia y propiedades de la luz)."} -> 6. Frente a otros países, El Salvador introduce 24 objetivos TIMSS más tarde que la mediana, 40 antes y no trabaja 2 que otros sí (herencia y propiedades de la luz).
B13: Recomendaciones
B14: R1. Decidir el peso de PISA en 7.° y 8.° (hoja Apego TIMSS y PISA, celda E4). Sugerencia mientras se decide: PISA como guía en 7.° y 9.°, y 50/50 en 8.° si El Salvador rinde TIMSS 2027 (8.° es el grado que TIMSS evalúa).
B15: {="R2. 2.°–4.° (hoja Presupuesto de temas): fusionar temas repetidos de Biología para liberar "&FIXED('Presupuesto de temas'!J9,0)&" espacios e insertar "&FIXED('Presupuesto de temas'!G9,0)&" temas de Ciencias físicas y de la Tierra (luz, sonido, circuitos, imanes, tiempo atmosférico) y "&FIXED('Presupuesto de temas'!H9,0)&" de herencia (B2.2), sin cambiar el total."} -> R2. 2.°–4.° (hoja Presupuesto de temas): fusionar temas repetidos de Biología para liberar 13 espacios e insertar 12 temas de Ciencias físicas y de la Tierra (luz, sonido, circuitos, imanes, tiempo atmosférico) y 1 de herencia (B2.2), sin cambiar el total.
B16: R3. 5.°–8.°: el total por dominio ya está en meta; no hace falta agregar temas. Conviene REUBICAR (Presupuesto, acción «reubicar»): adelantar Biología de 7.° a 5.°, insertar luz (con una fusión de Física) y traer al ciclo los movimientos de la Tierra y la Luna (hoy en 9.°), y subir tareas de Razonar en 6.° y 8.°.
B17: {="R4. 7.°–9.° (PISA): fusionar temas de física y química que se repiten (liberan "&FIXED('Presupuesto de temas'!J20,0)&") para insertar "&FIXED('Presupuesto de temas'!G20,0)&" temas de sistemas vivos (sobre todo en 9.°: célula, salud, genética, evolución) y de Tierra y espacio (sobre todo en 8.°: universo, historia de la Tierra)."} -> R4. 7.°–9.° (PISA): fusionar temas de física y química que se repiten (liberan 33) para insertar 33 temas de sistemas vivos (sobre todo en 9.°: célula, salud, genética, evolución) y de Tierra y espacio (sobre todo en 8.°: universo, historia de la Tierra).
B18: R5. Capas PISA: en cada unidad de 7.°–9.°, al menos un tema o fase que trabaje lo epistémico (por qué se confía en un modelo o en una conclusión) y la competencia 3 (evaluar fuentes, distinguir evidencia de opinión, criticar argumentos con datos), situado en un contexto local o personal. No requiere temas nuevos: cambia la fase «Reforzar».
B19: R6. Validar antes de decidir: las clasificaciones y los candidatos del presupuesto son asistidos por IA. El equipo de Ciencias debe revisar primero los de confianza baja (columna «Decisión del equipo» en Presupuesto y outputs/revision_confianza_baja_timss2027.csv).
B21: Qué responde este libro
B22: 1. Balance: ¿el reparto de temas entre Vida / Física / Química / Tierra se parece al peso que TIMSS da a cada dominio? ¿Cuántos temas faltan o sobran para llegar a la meta?
B23: 2. Amplitud: ¿qué objetivos de contenido de TIMSS aparecen en la malla, en qué grado, con cuántos temas, y cuáles no aparecen?
B24: 3. Profundidad cognitiva: ¿la proporción Conocer / Aplicar / Razonar se parece a la de TIMSS? 4. PISA (7.°–9.°): ¿cubre los sistemas y categorías de contenido, las tres competencias y sus subcompetencias, el conocimiento procedimental y epistémico, y los contextos que PISA evalúa? 5. ¿Qué insertar y qué fusionar para acercarse a las metas sin aumentar la carga?
B26: Proceso (de dónde salen los números)
B27: Paso 1 · Extracción. Se leyeron las 11 mallas (2.° a 9.° y Física, Química, Biología de 10.° y 11.°). Cada fila con «Procedimental» es un TEMA: 1.260 en total. Se conservan archivo, hoja y fila de origen (hoja Datos - Temas, columnas D-F) para poder volver a la malla.
B28: Paso 2 · Catálogo de referencia. Objetivos de contenido de TIMSS 2027 (4.° grado: 32; 8.° grado: 48), construidos desde el PDF oficial con página citada, y TIMSS Advanced 2015 Física (23), con su dominio y el % que TIMSS asigna a cada dominio (hoja Datos - Catálogo TIMSS, celdas ámbar = valores tomados del marco y editables). Novedades 2027: áreas de Investigaciones en cada dominio y subescala de conocimiento ambiental.
B29: Paso 3 · Clasificación. Los 622 temas de 2.° a 9.° se reclasificaron contra TIMSS 2027 con agentes de IA (instrucciones fijas, un lote por grado), usando la clasificación 2023 y la tabla de equivalencias solo como referencia. Física 10.°–11.° conserva la clasificación TIMSS Advanced 2015. Un tema va a un área de Investigaciones solo si su foco es la práctica científica; si trabaja un contenido mediante indagación, la investigación va como secundaria.
B30: Paso 4 · Reglas de grado. 2.°–4.° → TIMSS 2027 4.°; 5.°–8.° → TIMSS 2027 8.°; 7.°–9.° → PISA 2025 (7.° y 8.° con los dos marcos, 9.° solo PISA); Física 10.°–11.° → TIMSS Advanced 2015. Química y Biología de Bachillerato no tienen marco de contenido.
B31: Paso 4-bis · PISA 2025. Catálogo desde el marco final (OECD 2026, cap. 2, con página). Los temas de 7.°–9.° se clasificaron con IA por categoría de contenido, tipo de conocimiento, elementos procedimentales y epistémicos, contexto, área de aplicación y demanda cognitiva. La competencia y las subcompetencias NO se clasificaron: salen de la propia malla (columnas «Competencia PISA 2025» y microhabilidades E/D/I por fase).
... B52: • 1.° grado no tiene malla, así que no entra en el ciclo 2.°–4.°.

Sheet Resumen TIMSS y PISA
A1: Resumen por grado: TIMSS 2027 (2.°–8.° y Física) arriba · PISA 2025 (7.°–9.°) abajo
A2: {="TIMSS 2027 y PISA 2025"&" "&"OJO · TIMSS (2.°–8.°): faltan "&FIXED(MAX($G$5:$G$11),0)&" temas de "&INDEX($F$5:$F$11,MATCH(MAX($G$5:$G$11),$G$5:$G$11,0))&" en "&SUBSTITUTE(INDEX($A$5:$A$11,MATCH(MAX($G$5:$G$11),$G$5:$G$11,0)),"°",".°")&", el grado más desbalanceado."&" "&"OJO · PISA (7.°–9.°): faltan "&FIXED(G25,0)&" temas de "&LOWER(F25)&" en 9.°; en 7.°–9.° sobran "&FIXED(I26,0)&" de "&LOWER(H26)&"."&" "&"● Arriba: tabla TIMSS. Abajo: tabla PISA. Al final: qué significa cada columna."} -> TIMSS 2027 y PISA 2025 OJO · TIMSS (2.°–8.°): faltan 19 temas de Biología en 5.°, el grado más desbalanceado. OJO · PISA (7.°–9.°): faltan 28 temas de sistemas vivos en 9.°; en 7.°–9.° sobran 33 de sistemas físicos. ● Arriba: tabla TIMSS. Abajo: tabla PISA. Al final: qué significa cada columna.
A3: Lo contrario de «sin objetivo en el marco» (objetivos que TIMSS evalúa y la malla NO trabaja) está en el bloque por ciclo, columna «Objetivos no cubiertos», y en rojo en TIMSS - Semáforo de objetivos. Al final de esta hoja hay una guía de cada columna.
A4: Grupo | B4: Marco de referencia | C4: Temas totales | D4: Temas de la malla SIN objetivo en el marco (la malla los tiene; TIMSS no los evalúa) | E4: % de temas sin objetivo en el marco | F4: Dominio TIMSS con MÁS temas faltantes (frente a su meta) | G4: Temas que faltan en ese dominio | H4: Dominio TIMSS con MÁS temas de sobra | I4: Temas que sobran en ese dominio | J4: Temas a AGREGAR, sin quitar ninguno, para que TODOS los dominios lleguen a su meta | K4: Dominios en meta (±tolerancia) | L4: % Razonar actual | M4: % Razonar meta
A5: 2° | B5: TIMSS 2027 4.° | C5: {=_xlfn.COUNTIFS('Datos - Temas'!$V$5:$V$1264,$A5)} -> 70 | D5: {='TIMSS - Balance por grado'!N6} -> 11 | E5: {=IF(C5=0,0,D5/C5)} -> 0.15714286 | F5: {=INDEX('TIMSS - Balance por grado'!$C$6:$C$8,MATCH(MAX('TIMSS - Balance por grado'!$I$6:$I$8),'TIMSS - Balance por grado'!$I$6:$I$8,0))} -> Ciencias de la Tierra | G5: {=ROUND(MAX('TIMSS - Balance por grado'!$I$6:$I$8),0)} -> 4 | H5: {=INDEX('TIMSS - Balance por grado'!$C$6:$C$8,MATCH(MIN('TIMSS - Balance por grado'!$I$6:$I$8),'TIMSS - Balance por grado'!$I$6:$I$8,0))} -> Ciencias físicas | I5: {=ROUND(-MIN('TIMSS - Balance por grado'!$I$6:$I$8),0)} -> 6 | J5: {='TIMSS - Balance por grado'!M9} -> 19 | K5: {=COUNTIF('TIMSS - Balance por grado'!$K$6:$K$8,"En meta")&" de "&ROWS('TIMSS - Balance por grado'!$K$6:$K$8)} -> 1 de 3 | L5: {='TIMSS - Conocer-Aplicar-Razonar'!I5} -> 0.27142857 | M5: {='TIMSS - Conocer-Aplicar-Razonar'!L5} -> 0.25
A6: 3° | B6: TIMSS 2027 4.° | C6: {=_xlfn.COUNTIFS('Datos - Temas'!$V$5:$V$1264,$A6)} -> 66 | D6: {='TIMSS - Balance por grado'!N11} -> 6 | E6: {=IF(C6=0,0,D6/C6)} -> 0.090909091 | F6: {=INDEX('TIMSS - Balance por grado'!$C$11:$C$13,MATCH(MAX('TIMSS - Balance por grado'!$I$11:$I$13),'TIMSS - Balance por grado'!$I$11:$I$13,0))} -> Ciencias de la Tierra | G6: {=ROUND(MAX('TIMSS - Balance por grado'!$I$11:$I$13),0)} -> 3 | H6: {=INDEX('TIMSS - Balance por grado'!$C$11:$C$13,MATCH(MIN('TIMSS - Balance por grado'!$I$11:$I$13),'TIMSS - Balance por grado'!$I$11:$I$13,0))} -> Biología | I6: {=ROUND(-MIN('TIMSS - Balance por grado'!$I$11:$I$13),0)} -> 5 | J6: {='TIMSS - Balance por grado'!M14} -> 12 | K6: {=COUNTIF('TIMSS - Balance por grado'!$K$11:$K$13,"En meta")&" de "&ROWS('TIMSS - Balance por grado'!$K$11:$K$13)} -> 2 de 3 | L6: {='TIMSS - Conocer-Aplicar-Razonar'!I6} -> 0.26515152 | M6: {='TIMSS - Conocer-Aplicar-Razonar'!L6} -> 0.25
A7: 4° | B7: TIMSS 2027 4.° | C7: {=_xlfn.COUNTIFS('Datos - Temas'!$V$5:$V$1264,$A7)} -> 72 | D7: {='TIMSS - Balance por grado'!N16} -> 9 | E7: {=IF(C7=0,0,D7/C7)} -> 0.125 | F7: {=INDEX('TIMSS - Balance por grado'!$C$16:$C$18,MATCH(MAX('TIMSS - Balance por grado'!$I$16:$I$18),'TIMSS - Balance por grado'!$I$16:$I$18,0))} -> Ciencias físicas | G7: {=ROUND(MAX('TIMSS - Balance por grado'!$I$16:$I$18),0)} -> 13 | H7: {=INDEX('TIMSS - Balance por grado'!$C$16:$C$18,MATCH(MIN('TIMSS - Balance por grado'!$I$16:$I$18),'TIMSS - Balance por grado'!$I$16:$I$18,0))} -> Biología | I7: {=ROUND(-MIN('TIMSS - Balance por grado'!$I$16:$I$18),0)} -> 10 | J7: {='TIMSS - Balance por grado'!M19} -> 22 | K7: {=COUNTIF('TIMSS - Balance por grado'!$K$16:$K$18,"En meta")&" de "&ROWS('TIMSS - Balance por grado'!$K$16:$K$18)} -> 0 de 3 | L7: {='TIMSS - Conocer-Aplicar-Razonar'!I7} -> 0.20138889 | M7: {='TIMSS - Conocer-Aplicar-Razonar'!L7} -> 0.25
A8: 5° | B8: TIMSS 2027 8.° | C8: {=_xlfn.COUNTIFS('Datos - Temas'!$V$5:$V$1264,$A8)} -> 72 | D8: {='TIMSS - Balance por grado'!N21} -> 11 | E8: {=IF(C8=0,0,D8/C8)} -> 0.15277778 | F8: {=INDEX('TIMSS - Balance por grado'!$C$21:$C$24,MATCH(MAX('TIMSS - Balance por grado'!$I$21:$I$24),'TIMSS - Balance por grado'!$I$21:$I$24,0))} -> Biología | G8: {=ROUND(MAX('TIMSS - Balance por grado'!$I$21:$I$24),0)} -> 19 | H8: {=INDEX('TIMSS - Balance por grado'!$C$21:$C$24,MATCH(MIN('TIMSS - Balance por grado'!$I$21:$I$24),'TIMSS - Balance por grado'!$I$21:$I$24,0))} -> Ciencias de la Tierra | I8: {=ROUND(-MIN('TIMSS - Balance por grado'!$I$21:$I$24),0)} -> 8 | J8: {='TIMSS - Balance por grado'!M25} -> 39 | K8: {=COUNTIF('TIMSS - Balance por grado'!$K$21:$K$24,"En meta")&" de "&ROWS('TIMSS - Balance por grado'!$K$21:$K$24)} -> 0 de 4 | L8: {='TIMSS - Conocer-Aplicar-Razonar'!I8} -> 0.24305556 | M8: {='TIMSS - Conocer-Aplicar-Razonar'!L8} -> 0.3
A9: 6° | B9: TIMSS 2027 8.° | C9: {=_xlfn.COUNTIFS('Datos - Temas'!$V$5:$V$1264,$A9)} -> 68 | D9: {='TIMSS - Balance por grado'!N27} -> 5 | E9: {=IF(C9=0,0,D9/C9)} -> 0.073529412 | F9: {=INDEX('TIMSS - Balance por grado'!$C$27:$C$30,MATCH(MAX('TIMSS - Balance por grado'!$I$27:$I$30),'TIMSS - Balance por grado'!$I$27:$I$30,0))} -> Ciencias de la Tierra | G9: {=ROUND(MAX('TIMSS - Balance por grado'!$I$27:$I$30),0)} -> 13 | H9: {=INDEX('TIMSS - Balance por grado'!$C$27:$C$30,MATCH(MIN('TIMSS - Balance por grado'!$I$27:$I$30),'TIMSS - Balance por grado'!$I$27:$I$30,0))} -> Física | I9: {=ROUND(-MIN('TIMSS - Balance por grado'!$I$27:$I$30),0)} -> 8 | J9: {='TIMSS - Balance por grado'!M31} -> 35 | K9: {=COUNTIF('TIMSS - Balance por grado'!$K$27:$K$30,"En meta")&" de "&ROWS('TIMSS - Balance por grado'!$K$27:$K$30)} -> 1 de 4 | L9: {='TIMSS - Conocer-Aplicar-Razonar'!I9} -> 0.19117647 | M9: {='TIMSS - Conocer-Aplicar-Razonar'!L9} -> 0.3
A10: 7° | B10: TIMSS 2027 8.° | C10: {=_xlfn.COUNTIFS('Datos - Temas'!$V$5:$V$1264,$A10)} -> 91 | D10: {='TIMSS - Balance por grado'!N33} -> 6 | E10: {=IF(C10=0,0,D10/C10)} -> 0.065934066 | F10: {=INDEX('TIMSS - Balance por grado'!$C$33:$C$36,MATCH(MAX('TIMSS - Balance por grado'!$I$33:$I$36),'TIMSS - Balance por grado'!$I$33:$I$36,0))} -> Física | G10: {=ROUND(MAX('TIMSS - Balance por grado'!$I$33:$I$36),0)} -> 19 | H10: {=INDEX('TIMSS - Balance por grado'!$C$33:$C$36,MATCH(MIN('TIMSS - Balance por grado'!$I$33:$I$36),'TIMSS - Balance por grado'!$I$33:$I$36,0))} -> Biología | I10: {=ROUND(-MIN('TIMSS - Balance por grado'!$I$33:$I$36),0)} -> 15 | J10: {='TIMSS - Balance por grado'!M37} -> 61 | K10: {=COUNTIF('TIMSS - Balance por grado'!$K$33:$K$36,"En meta")&" de "&ROWS('TIMSS - Balance por grado'!$K$33:$K$36)} -> 0 de 4 | L10: {='TIMSS - Conocer-Aplicar-Razonar'!I10} -> 0.28571429 | M10: {='TIMSS - Conocer-Aplicar-Razonar'!L10} -> 0.3
A11: 8° | B11: TIMSS 2027 8.° | C11: {=_xlfn.COUNTIFS('Datos - Temas'!$V$5:$V$1264,$A11)} -> 93 | D11: {='TIMSS - Balance por grado'!N39} -> 0 | E11: {=IF(C11=0,0,D11/C11)} -> 0 | F11: {=INDEX('TIMSS - Balance por grado'!$C$39:$C$42,MATCH(MAX('TIMSS - Balance por grado'!$I$39:$I$42),'TIMSS - Balance por grado'!$I$39:$I$42,0))} -> Ciencias de la Tierra | G11: {=ROUND(MAX('TIMSS - Balance por grado'!$I$39:$I$42),0)} -> 15 | H11: {=INDEX('TIMSS - Balance por grado'!$C$39:$C$42,MATCH(MIN('TIMSS - Balance por grado'!$I$39:$I$42),'TIMSS - Balance por grado'!$I$39:$I$42,0))} -> Física | I11: {=ROUND(-MIN('TIMSS - Balance por grado'!$I$39:$I$42),0)} -> 14 | J11: {='TIMSS - Balance por grado'!M43} -> 56 | K11: {=COUNTIF('TIMSS - Balance por grado'!$K$39:$K$42,"En meta")&" de "&ROWS('TIMSS - Balance por grado'!$K$39:$K$42)} -> 0 de 4 | L11: {='TIMSS - Conocer-Aplicar-Razonar'!I11} -> 0.20967742 | M11: {='TIMSS - Conocer-Aplicar-Razonar'!L11} -> 0.3
A12: Física 10° | B12: TIMSS Advanced 2015 Física | C12: {=_xlfn.COUNTIFS('Datos - Temas'!$V$5:$V$1264,$A12)} -> 121 | D12: {='TIMSS - Balance por grado'!N45} -> 41 | E12: {=IF(C12=0,0,D12/C12)} -> 0.33884298 | F12: {=INDEX('TIMSS - Balance por grado'!$C$45:$C$47,MATCH(MAX('TIMSS - Balance por grado'!$I$45:$I$47),'TIMSS - Balance por grado'!$I$45:$I$47,0))} -> Electricidad y magnetismo | G12: {=ROUND(MAX('TIMSS - Balance por grado'!$I$45:$I$47),0)} -> 20 | H12: {=INDEX('TIMSS - Balance por grado'!$C$45:$C$47,MATCH(MIN('TIMSS - Balance por grado'!$I$45:$I$47),'TIMSS - Balance por grado'!$I$45:$I$47,0))} -> Mecánica y termodinámica | I12: {=ROUND(-MIN('TIMSS - Balance por grado'!$I$45:$I$47),0)} -> 35 | J12: {='TIMSS - Balance por grado'!M48} -> 88 | K12: {=COUNTIF('TIMSS - Balance por grado'!$K$45:$K$47,"En meta")&" de "&ROWS('TIMSS - Balance por grado'!$K$45:$K$47)} -> 0 de 3 | L12: {='TIMSS - Conocer-Aplicar-Razonar'!I12} -> 0.48071625 | M12: {='TIMSS - Conocer-Aplicar-Razonar'!L12} -> 0.3
A13: Física 11° | B13: TIMSS Advanced 2015 Física | C13: {=_xlfn.COUNTIFS('Datos - Temas'!$V$5:$V$1264,$A13)} -> 146 | D13: {='TIMSS - Balance por grado'!N50} -> 27 | E13: {=IF(C13=0,0,D13/C13)} -> 0.18493151 | F13: {=INDEX('TIMSS - Balance por grado'!$C$50:$C$52,MATCH(MAX('TIMSS - Balance por grado'!$I$50:$I$52),'TIMSS - Balance por grado'!$I$50:$I$52,0))} -> Mecánica y termodinámica | G13: {=ROUND(MAX('TIMSS - Balance por grado'!$I$50:$I$52),0)} -> 44 | H13: {=INDEX('TIMSS - Balance por grado'!$C$50:$C$52,MATCH(MIN('TIMSS - Balance por grado'!$I$50:$I$52),'TIMSS - Balance por grado'!$I$50:$I$52,0))} -> Ondas y física atómica/nuclear | I13: {=ROUND(-MIN('TIMSS - Balance por grado'!$I$50:$I$52),0)} -> 30 | J13: {='TIMSS - Balance por grado'!M53} -> 89 | K13: {=COUNTIF('TIMSS - Balance por grado'!$K$50:$K$52,"En meta")&" de "&ROWS('TIMSS - Balance por grado'!$K$50:$K$52)} -> 0 de 3 | L13: {='TIMSS - Conocer-Aplicar-Razonar'!I13} -> 0.46575342 | M13: {='TIMSS - Conocer-Aplicar-Razonar'!L13} -> 0.3
A15: Por ciclo (comparación acumulada)
A16: Ciclo | B16: Marco de referencia | C16: Temas evaluables | D16: Dominio con mayor FALTANTE | E16: Faltan (temas) | F16: Dominio más SOBRErrepresentado | G16: Sobran (temas) | H16: Temas a agregar sin quitar | I16: Dominios en meta | J16: Objetivos TIMSS del marco | K16: Objetivos cubiertos | L16: % amplitud | M16: Objetivos del marco que la malla NO trabaja | N16: Objetivos cubiertos (2023) | O16: % amplitud (2023) | P16: Dominio con mayor FALTANTE (2023) | Q16: Cambio vs 2023 | R16: % temas ambientales (ref. ≈25 %) | S16: Temas en Investigaciones (principal)
A17: Ciclo 2°–4° | B17: TIMSS 2027 4.° | C17: {='TIMSS - Balance por ciclo'!E6} -> 182 | D17: {=INDEX('TIMSS - Balance por ciclo'!$C$6:$C$8,MATCH(MAX('TIMSS - Balance por ciclo'!$I$6:$I$8),'TIMSS - Balance por ciclo'!$I$6:$I$8,0))} -> Ciencias físicas | E17: {=ROUND(MAX('TIMSS - Balance por ciclo'!$I$6:$I$8),0)} -> 9 | F17: {=INDEX('TIMSS - Balance por ciclo'!$C$6:$C$8,MATCH(MIN('TIMSS - Balance por ciclo'!$I$6:$I$8),'TIMSS - Balance por ciclo'!$I$6:$I$8,0))} -> Biología | G17: {=ROUND(-MIN('TIMSS - Balance por ciclo'!$I$6:$I$8),0)} -> 12 | H17: {='TIMSS - Balance por ciclo'!M9} -> 29 | I17: {=COUNTIF('TIMSS - Balance por ciclo'!$K$6:$K$8,"En meta")&" de "&ROWS('TIMSS - Balance por ciclo'!$K$6:$K$8)} -> 2 de 3 | J17: {='TIMSS - Semáforo de objetivos'!C115} -> 32 | K17: {='TIMSS - Semáforo de objetivos'!D115} -> 31 | L17: {='TIMSS - Semáforo de objetivos'!E115} -> 0.96875 | M17: {='TIMSS - Semáforo de objetivos'!F115} -> 1 | N17: {='Datos - TIMSS 2023'!C110} -> 31 | O17: {='Datos - TIMSS 2023'!D110} -> 0.96875 | P17: {=INDEX('Datos - TIMSS 2023'!$C$117:$C$119,MATCH(MAX('Datos - TIMSS 2023'!$G$117:$G$119),'Datos - TIMSS 2023'!$G$117:$G$119,0))} -> Ciencias físicas | Q17: {="Cubiertos: "&N17&" de "&'Datos - TIMSS 2023'!B110&" (2023) → "&K17&" de "&J17&" (2027) · Mayor faltante: "&P17&" (2023) → "&D17&" (2027)"} -> Cubiertos: 31 de 32 (2023) → 31 de 32 (2027) · Mayor faltante: Ciencias físicas (2023) → Ciencias físicas (2027) | R17: {='TIMSS - Medio ambiente'!E16} -> 0.2967033 | S17: {='TIMSS - Investigación'!C15} -> 9
A18: Ciclo 5°–8° | B18: TIMSS 2027 8.° | C18: {='TIMSS - Balance por ciclo'!E11} -> 302 | D18: {=INDEX('TIMSS - Balance por ciclo'!$C$11:$C$14,MATCH(MAX('TIMSS - Balance por ciclo'!$I$11:$I$14),'TIMSS - Balance por ciclo'!$I$11:$I$14,0))} -> Ciencias de la Tierra | E18: {=ROUND(MAX('TIMSS - Balance por ciclo'!$I$11:$I$14),0)} -> 7 | F18: {=INDEX('TIMSS - Balance por ciclo'!$C$11:$C$14,MATCH(MIN('TIMSS - Balance por ciclo'!$I$11:$I$14),'TIMSS - Balance por ciclo'!$I$11:$I$14,0))} -> Física | G18: {=ROUND(-MIN('TIMSS - Balance por ciclo'!$I$11:$I$14),0)} -> 8 | H18: {='TIMSS - Balance por ciclo'!M15} -> 32 | I18: {=COUNTIF('TIMSS - Balance por ciclo'!$K$11:$K$14,"En meta")&" de "&ROWS('TIMSS - Balance por ciclo'!$K$11:$K$14)} -> 4 de 4 | J18: {='TIMSS - Semáforo de objetivos'!C120} -> 48 | K18: {='TIMSS - Semáforo de objetivos'!D120} -> 45 | L18: {='TIMSS - Semáforo de objetivos'!E120} -> 0.9375 | M18: {='TIMSS - Semáforo de objetivos'!F120} -> 3 | N18: {='Datos - TIMSS 2023'!C111} -> 43 | O18: {='Datos - TIMSS 2023'!D111} -> 0.93478261 | P18: {=INDEX('Datos - TIMSS 2023'!$C$121:$C$124,MATCH(MAX('Datos - TIMSS 2023'!$G$121:$G$124),'Datos - TIMSS 2023'!$G$121:$G$124,0))} -> Ciencias de la Tierra | Q18: {="Cubiertos: "&N18&" de "&'Datos - TIMSS 2023'!B111&" (2023) → "&K18&" de "&J18&" (2027) · Mayor faltante: "&P18&" (2023) → "&D18&" (2027)"} -> Cubiertos: 43 de 46 (2023) → 45 de 48 (2027) · Mayor faltante: Ciencias de la Tierra (2023) → Ciencias de la Tierra (2027) | R18: {='TIMSS - Medio ambiente'!E17} -> 0.29139073 | S18: {='TIMSS - Investigación'!C16} -> 15
A19: Física 10°–11° | B19: TIMSS Advanced 2015 Física | C19: {='TIMSS - Balance por ciclo'!E17} -> 199 | D19: {=INDEX('TIMSS - Balance por ciclo'!$C$17:$C$19,MATCH(MAX('TIMSS - Balance por ciclo'!$I$17:$I$19),'TIMSS - Balance por ciclo'!$I$17:$I$19,0))} -> Mecánica y termodinámica | E19: {=ROUND(MAX('TIMSS - Balance por ciclo'!$I$17:$I$19),0)} -> 9 | F19: {=INDEX('TIMSS - Balance por ciclo'!$C$17:$C$19,MATCH(MIN('TIMSS - Balance por ciclo'!$I$17:$I$19),'TIMSS - Balance por ciclo'!$I$17:$I$19,0))} -> Ondas y física atómica/nuclear | G19: {=ROUND(-MIN('TIMSS - Balance por ciclo'!$I$17:$I$19),0)} -> 15 | H19: {='TIMSS - Balance por ciclo'!M20} -> 46 | I19: {=COUNTIF('TIMSS - Balance por ciclo'!$K$17:$K$19,"En meta")&" de "&ROWS('TIMSS - Balance por ciclo'!$K$17:$K$19)} -> 2 de 3 | J19: {='TIMSS - Semáforo de objetivos'!C124} -> 23 | K19: {='TIMSS - Semáforo de objetivos'!D124} -> 23 | L19: {='TIMSS - Semáforo de objetivos'!E124} -> 1 | M19: {='TIMSS - Semáforo de objetivos'!F124} -> 0 | N19: {='Datos - TIMSS 2023'!C112} -> 23 | O19: {='Datos - TIMSS 2023'!D112} -> 1 | P19: {=INDEX('Datos - TIMSS 2023'!$C$131:$C$133,MATCH(MAX('Datos - TIMSS 2023'!$G$131:$G$133),'Datos - TIMSS 2023'!$G$131:$G$133,0))} -> Mecánica y termodinámica | Q19: {="Sin cambio de marco: Física sigue con TIMSS Advanced 2015"} -> Sin cambio de marco: Física sigue con TIMSS Advanced 2015 | R19: — | S19: —
A21: PISA 2025 (7.°, 8.°, 9.° y acumulado 7.°–9.°): 9.° se compara solo con PISA; 7.° y 8.° con los dos marcos (ver Apego TIMSS y PISA)
A22: Grupo | B22: Marco de referencia | C22: Temas totales | D22: Temas sin contenido PISA (la malla los tiene; PISA no los evalúa) | E22: % sin contenido PISA | F22: Sistema PISA con MÁS temas faltantes | G22: Temas que faltan | H22: Sistema PISA con MÁS temas de sobra | I22: Temas que sobran | J22: Temas a AGREGAR, sin quitar, para que todos los sistemas lleguen a su meta | K22: Sistemas en meta | L22: % competencia 3 «Investigar, evaluar y usar información» (meta 24–36 %) | M22: ÍNDICE DE APEGO PISA
A23: 7° | B23: PISA 2025 | C23: {=_xlfn.COUNTIFS('Datos - Temas'!$V$5:$V$1264,$A23,'Datos - Temas'!$AK$5:$AK$1264,"<>")} -> 91 | D23: {='PISA - Contenidos'!N6} -> 1 | E23: {=IF(C23=0,0,D23/C23)} -> 0.010989011 | F23: {=INDEX('PISA - Contenidos'!$C$6:$C$8,MATCH(MAX('PISA - Contenidos'!$I$6:$I$8),'PISA - Contenidos'!$I$6:$I$8,0))} -> Sistemas físicos | G23: {=ROUND(MAX('PISA - Contenidos'!$I$6:$I$8),0)} -> 17 | H23: {=INDEX('PISA - Contenidos'!$C$6:$C$8,MATCH(MIN('PISA - Contenidos'!$I$6:$I$8),'PISA - Contenidos'!$I$6:$I$8,0))} -> Sistemas vivos | I23: {=ROUND(-MIN('PISA - Contenidos'!$I$6:$I$8),0)} -> 18 | J23: {='PISA - Contenidos'!M9} -> 50 | K23: {=COUNTIF('PISA - Contenidos'!$K$6:$K$8,"En meta")&" de "&ROWS('PISA - Contenidos'!$K$6:$K$8)} -> 1 de 3 | L23: {='PISA - Competencias'!H13} -> 0.21978022 | M23: {='Apego TIMSS y PISA'!F20} -> 0.86155678
A24: 8° | B24: PISA 2025 | C24: {=_xlfn.COUNTIFS('Datos - Temas'!$V$5:$V$1264,$A24,'Datos - Temas'!$AK$5:$AK$1264,"<>")} -> 93 | D24: {='PISA - Contenidos'!N11} -> 5 | E24: {=IF(C24=0,0,D24/C24)} -> 0.053763441 | F24: {=INDEX('PISA - Contenidos'!$C$11:$C$13,MATCH(MAX('PISA - Contenidos'!$I$11:$I$13),'PISA - Contenidos'!$I$11:$I$13,0))} -> Sistemas de la Tierra y el espacio | G24: {=ROUND(MAX('PISA - Contenidos'!$I$11:$I$13),0)} -> 17 | H24: {=INDEX('PISA - Contenidos'!$C$11:$C$13,MATCH(MIN('PISA - Contenidos'!$I$11:$I$13),'PISA - Contenidos'!$I$11:$I$13,0))} -> Sistemas físicos | I24: {=ROUND(-MIN('PISA - Contenidos'!$I$11:$I$13),0)} -> 22 | J24: {='PISA - Contenidos'!M14} -> 63 | K24: {=COUNTIF('PISA - Contenidos'!$K$11:$K$13,"En meta")&" de "&ROWS('PISA - Contenidos'!$K$11:$K$13)} -> 0 de 3 | L24: {='PISA - Competencias'!H14} -> 0.064516129 | M24: {='Apego TIMSS y PISA'!F21} -> 0.71067204
A25: 9° | B25: PISA 2025 | C25: {=_xlfn.COUNTIFS('Datos - Temas'!$V$5:$V$1264,$A25,'Datos - Temas'!$AK$5:$AK$1264,"<>")} -> 90 | D25: {='PISA - Contenidos'!N16} -> 6 | E25: {=IF(C25=0,0,D25/C25)} -> 0.066666667 | F25: {=INDEX('PISA - Contenidos'!$C$16:$C$18,MATCH(MAX('PISA - Contenidos'!$I$16:$I$18),'PISA - Contenidos'!$I$16:$I$18,0))} -> Sistemas vivos | G25: {=ROUND(MAX('PISA - Contenidos'!$I$16:$I$18),0)} -> 28 | H25: {=INDEX('PISA - Contenidos'!$C$16:$C$18,MATCH(MIN('PISA - Contenidos'!$I$16:$I$18),'PISA - Contenidos'!$I$16:$I$18,0))} -> Sistemas físicos | I25: {=ROUND(-MIN('PISA - Contenidos'!$I$16:$I$18),0)} -> 28 | J25: {='PISA - Contenidos'!M19} -> 76 | K25: {=COUNTIF('PISA - Contenidos'!$K$16:$K$18,"En meta")&" de "&ROWS('PISA - Contenidos'!$K$16:$K$18)} -> 1 de 3 | L25: {='PISA - Competencias'!H15} -> 0.13333333 | M25: {='Apego TIMSS y PISA'!F22} -> 0.72730159
A26: Ciclo 7°–9° | B26: PISA 2025 | C26: {=_xlfn.COUNTIFS('Datos - Temas'!$AV$5:$AV$1264,$A26,'Datos - Temas'!$AK$5:$AK$1264,"<>")} -> 274 | D26: {='PISA - Contenidos'!N21} -> 12 | E26: {=IF(C26=0,0,D26/C26)} -> 0.04379562 | F26: {=INDEX('PISA - Contenidos'!$C$21:$C$23,MATCH(MAX('PISA - Contenidos'!$I$21:$I$23),'PISA - Contenidos'!$I$21:$I$23,0))} -> Sistemas de la Tierra y el espacio | G26: {=ROUND(MAX('PISA - Contenidos'!$I$21:$I$23),0)} -> 17 | H26: {=INDEX('PISA - Contenidos'!$C$21:$C$23,MATCH(MIN('PISA - Contenidos'!$I$21:$I$23),'PISA - Contenidos'!$I$21:$I$23,0))} -> Sistemas físicos | I26: {=ROUND(-MIN('PISA - Contenidos'!$I$21:$I$23),0)} -> 33 | J26: {='PISA - Contenidos'!M24} -> 90 | K26: {=COUNTIF('PISA - Contenidos'!$K$21:$K$23,"En meta")&" de "&ROWS('PISA - Contenidos'!$K$21:$K$23)} -> 0 de 3 | L26: {='PISA - Competencias'!H16} -> 0.13868613 | M26: {='Apego TIMSS y PISA'!F23} -> 0.87661579
A28: Cómo leer cada columna
A29: • Temas SIN objetivo en el marco: temas que la malla SÍ enseña pero que el marco no evalúa (p. ej. medición general, electrónica digital, gestión de riesgos). No son un error: indican cuánto de la malla va más allá de la prueba. Lo contrario —objetivos del marco que la malla NO trabaja— está en «Objetivos del marco que la malla NO trabaja».
A30: • Dominio TIMSS con MÁS temas faltantes: de los dominios de TIMSS (Biología, Química, Física, Tierra), el que más se queda por debajo del peso que TIMSS le da en la prueba. «Temas que faltan» = cuántos temas habría que pasar a ese dominio, con el mismo total de temas, para llegar a la meta.
A31: • Temas a AGREGAR sin quitar: si no se quiere quitar ningún tema, cuántos habría que SUMAR en total para que todos los dominios lleguen a su meta. Ejemplo: con 100 temas, 60 % Biología y meta 45 %, habría que llegar a 60 ÷ 0,45 ≈ 133 temas, sumando 33 en los otros dominios. Por eso suele ser una cifra alta: la alternativa realista (fusionar e insertar con el mismo total) está en la hoja Presupuesto de temas.
A32: • Dominios en meta: cuántos dominios están a ±5 puntos porcentuales de su meta (tolerancia editable en TIMSS - Balance por grado, celda H2).
A33: • ÍNDICE DE APEGO: parte del reparto de la malla que ya coincide con el del marco (100 % = igual). Detalle y escenarios TIMSS/PISA en Apego TIMSS y PISA.
A35: Cómo se calcula: Todo es fórmula sobre Temas. Balance = reparto de temas por dominio vs. metas TIMSS. Amplitud = objetivos TIMSS que aparecen. Profundidad cognitiva = Conocer/Aplicar/Razonar. Ver «Inicio» para el proceso completo.

Sheet Apego TIMSS y PISA
A1: Apego a los marcos: índice por grado y escenarios TIMSS / PISA para 7.° y 8.°
A2: {="TIMSS 2027 y PISA 2025"&" "&IF(MIN(F17,F18,F23)>=$H$4,"BIEN · ","OJO · ")&"Acumulado: TIMSS 4.° "&FIXED((F17)*100,0)&" %"&", TIMSS 8.° "&FIXED((F18)*100,0)&" %"&", PISA "&FIXED((F23)*100,0)&" %"&" de apego (alto = 85 % o más)."&" "&"OJO · Grado más flojo en TIMSS: "&SUBSTITUTE(INDEX($A$8:$A$14,MATCH(MIN($F$8:$F$14),$F$8:$F$14,0)),"°",".°")&" ("&FIXED((MIN($F$8:$F$14))*100,0)&" %"&"). En PISA: 9.° ("&FIXED((F22)*100,0)&" %"&")."&" "&"● 7.° y 8.° se miden con los dos marcos: el peso de PISA se elige en la celda E4 (hoy "&FIXED((E4)*100,0)&" %"&")."} -> TIMSS 2027 y PISA 2025 BIEN · Acumulado: TIMSS 4.° 92 %, TIMSS 8.° 88 %, PISA 88 % de apego (alto = 85 % o más). OJO · Grado más flojo en TIMSS: 5.° (69 %). En PISA: 9.° (73 %). ● 7.° y 8.° se miden con los dos marcos: el peso de PISA se elige en la celda E4 (hoy 50 %).
A4: Peso de PISA en 7.° y 8.° (0 % = solo TIMSS): | E4: 0.5 | G4: Lectura: alto desde | H4: 0.85 | I4: medio desde | J4: 0.7
A6: A · Índice de apego por grado y ciclo
A7: Grado / ciclo | B7: Marco | C7: Coincidencia de balance | D7: Coincidencia cognitiva | E7: Amplitud (ciclo) | F7: ÍNDICE DE APEGO | G7: Lectura
A8: 2° | B8: TIMSS 2027 4.° | C8: {='TIMSS - Balance por grado'!O9} -> 0.89237288 | D8: {='TIMSS - Conocer-Aplicar-Razonar'!O5} -> 0.82857143 | E8: — | F8: {=AVERAGE(C8:E8)} -> 0.86047215 | G8: {=IF(F8>=$H$4,"Alto",IF(F8>=$J$4,"Medio","Bajo: revisar"))} -> Alto
A9: 3° | B9: TIMSS 2027 4.° | C9: {='TIMSS - Balance por grado'!O14} -> 0.91666667 | D9: {='TIMSS - Conocer-Aplicar-Razonar'!O6} -> 0.86969697 | E9: — | F9: {=AVERAGE(C9:E9)} -> 0.89318182 | G9: {=IF(F9>=$H$4,"Alto",IF(F9>=$J$4,"Medio","Bajo: revisar"))} -> Alto
A10: 4° | B10: TIMSS 2027 4.° | C10: {='TIMSS - Balance por grado'!O19} -> 0.79285714 | D10: {='TIMSS - Conocer-Aplicar-Razonar'!O7} -> 0.8375 | E10: — | F10: {=AVERAGE(C10:E10)} -> 0.81517857 | G10: {=IF(F10>=$H$4,"Alto",IF(F10>=$J$4,"Medio","Bajo: revisar"))} -> Medio
A11: 5° | B11: TIMSS 2027 8.° | C11: {='TIMSS - Balance por grado'!O25} -> 0.68278689 | D11: {='TIMSS - Conocer-Aplicar-Razonar'!O8} -> 0.69027778 | E11: — | F11: {=AVERAGE(C11:E11)} -> 0.68653233 | G11: {=IF(F11>=$H$4,"Alto",IF(F11>=$J$4,"Medio","Bajo: revisar"))} -> Bajo: revisar
A12: 6° | B12: TIMSS 2027 8.° | C12: {='TIMSS - Balance por grado'!O31} -> 0.75873016 | D12: {='TIMSS - Conocer-Aplicar-Razonar'!O9} -> 0.66617647 | E12: — | F12: {=AVERAGE(C12:E12)} -> 0.71245331 | G12: {=IF(F12>=$H$4,"Alto",IF(F12>=$J$4,"Medio","Bajo: revisar"))} -> Medio
A13: 7° | B13: TIMSS 2027 8.° | C13: {='TIMSS - Balance por grado'!O37} -> 0.67941176 | D13: {='TIMSS - Conocer-Aplicar-Razonar'!O10} -> 0.83351648 | E13: — | F13: {=AVERAGE(C13:E13)} -> 0.75646412 | G13: {=IF(F13>=$H$4,"Alto",IF(F13>=$J$4,"Medio","Bajo: revisar"))} -> Medio
A14: 8° | B14: TIMSS 2027 8.° | C14: {='TIMSS - Balance por grado'!O43} -> 0.78333333 | D14: {='TIMSS - Conocer-Aplicar-Razonar'!O11} -> 0.71021505 | E14: — | F14: {=AVERAGE(C14:E14)} -> 0.74677419 | G14: {=IF(F14>=$H$4,"Alto",IF(F14>=$J$4,"Medio","Bajo: revisar"))} -> Medio
A15: Física 10° | B15: TIMSS Advanced 2015 Física | C15: {='TIMSS - Balance por grado'!O48} -> 0.5625 | D15: {='TIMSS - Conocer-Aplicar-Razonar'!O12} -> 0.76749311 | E15: — | F15: {=AVERAGE(C15:E15)} -> 0.66499656 | G15: {=IF(F15>=$H$4,"Alto",IF(F15>=$J$4,"Medio","Bajo: revisar"))} -> Bajo: revisar
A16: Física 11° | B16: TIMSS Advanced 2015 Física | C16: {='TIMSS - Balance por grado'!O53} -> 0.63361345 | D16: {='TIMSS - Conocer-Aplicar-Razonar'!O13} -> 0.79931507 | E16: — | F16: {=AVERAGE(C16:E16)} -> 0.71646426 | G16: {=IF(F16>=$H$4,"Alto",IF(F16>=$J$4,"Medio","Bajo: revisar"))} -> Medio
A17: Ciclo 2°–4° | B17: TIMSS 2027 4.° | C17: {='TIMSS - Balance por ciclo'!O9} -> 0.93351648 | D17: {=1-(ABS(_xlfn.SUMIFS('Datos - Temas'!$S$5:$S$1264,'Datos - Temas'!$W$5:$W$1264,$A17)/_xlfn.COUNTIFS('Datos - Temas'!$W$5:$W$1264,$A17)-0.35)+ABS(_xlfn.SUMIFS('Datos - Temas'!$T$5:$T$1264,'Datos - Temas'!$W$5:$W$1264,$A17)/_xlfn.COUNTIFS('Datos - Temas'!$W$5:$W$1264,$A17)-0.4)+ABS(_xlfn.SUMIFS('Datos - Temas'!$U$5:$U$1264,'Datos - Temas'!$W$5:$W$1264,$A17)/_xlfn.COUNTIFS('Datos - Temas'!$W$5:$W$1264,$A17)-0.25))/2} -> 0.85673077 | E17: {='TIMSS - Semáforo de objetivos'!E115} -> 0.96875 | F17: {=AVERAGE(C17:E17)} -> 0.91966575 | G17: {=IF(F17>=$H$4,"Alto",IF(F17>=$J$4,"Medio","Bajo: revisar"))} -> Alto
A18: Ciclo 5°–8° | B18: TIMSS 2027 8.° | C18: {='TIMSS - Balance por ciclo'!O15} -> 0.96655629 | D18: {=1-(ABS(_xlfn.SUMIFS('Datos - Temas'!$S$5:$S$1264,'Datos - Temas'!$W$5:$W$1264,$A18)/_xlfn.COUNTIFS('Datos - Temas'!$W$5:$W$1264,$A18)-0.35)+ABS(_xlfn.SUMIFS('Datos - Temas'!$T$5:$T$1264,'Datos - Temas'!$W$5:$W$1264,$A18)/_xlfn.COUNTIFS('Datos - Temas'!$W$5:$W$1264,$A18)-0.35)+ABS(_xlfn.SUMIFS('Datos - Temas'!$U$5:$U$1264,'Datos - Temas'!$W$5:$W$1264,$A18)/_xlfn.COUNTIFS('Datos - Temas'!$W$5:$W$1264,$A18)-0.3))/2} -> 0.73117284 | E18: {='TIMSS - Semáforo de objetivos'!E120} -> 0.9375 | F18: {=AVERAGE(C18:E18)} -> 0.87840971 | G18: {=IF(F18>=$H$4,"Alto",IF(F18>=$J$4,"Medio","Bajo: revisar"))} -> Alto
A19: Física 10°–11° | B19: TIMSS Advanced 2015 Física | C19: {='TIMSS - Balance por ciclo'!O20} -> 0.92286432 | D19: {=1-(ABS(_xlfn.SUMIFS('Datos - Temas'!$S$5:$S$1264,'Datos - Temas'!$W$5:$W$1264,$A19)/_xlfn.COUNTIFS('Datos - Temas'!$W$5:$W$1264,$A19)-0.3)+ABS(_xlfn.SUMIFS('Datos - Temas'!$T$5:$T$1264,'Datos - Temas'!$W$5:$W$1264,$A19)/_xlfn.COUNTIFS('Datos - Temas'!$W$5:$W$1264,$A19)-0.4)+ABS(_xlfn.SUMIFS('Datos - Temas'!$U$5:$U$1264,'Datos - Temas'!$W$5:$W$1264,$A19)/_xlfn.COUNTIFS('Datos - Temas'!$W$5:$W$1264,$A19)-0.3))/2} -> 0.78489388 | E19: {='TIMSS - Semáforo de objetivos'!E124} -> 1 | F19: {=AVERAGE(C19:E19)} -> 0.90258607 | G19: {=IF(F19>=$H$4,"Alto",IF(F19>=$J$4,"Medio","Bajo: revisar"))} -> Alto
A20: 7° · PISA | B20: PISA 2025 | C20: {='PISA - Contenidos'!O9} -> 0.80333333 | D20: {='PISA - Competencias'!L13} -> 0.91978022 | E20: — | F20: {=AVERAGE(C20:E20)} -> 0.86155678 | G20: {=IF(F20>=$H$4,"Alto",IF(F20>=$J$4,"Medio","Bajo: revisar"))} -> Alto
A21: 8° · PISA | B21: PISA 2025 | C21: {='PISA - Contenidos'!O14} -> 0.745 | D21: {='PISA - Competencias'!L14} -> 0.67634409 | E21: — | F21: {=AVERAGE(C21:E21)} -> 0.71067204 | G21: {=IF(F21>=$H$4,"Alto",IF(F21>=$J$4,"Medio","Bajo: revisar"))} -> Medio
A22: 9° · PISA | B22: PISA 2025 | C22: {='PISA - Contenidos'!O19} -> 0.66571429 | D22: {='PISA - Competencias'!L15} -> 0.78888889 | E22: — | F22: {=AVERAGE(C22:E22)} -> 0.72730159 | G22: {=IF(F22>=$H$4,"Alto",IF(F22>=$J$4,"Medio","Bajo: revisar"))} -> Medio
A23: Ciclo 7°–9° · PISA | B23: PISA 2025 | C23: {='PISA - Contenidos'!O24} -> 0.87381679 | D23: {='PISA - Competencias'!L16} -> 0.80364964 | E23: {='PISA - Contenidos'!D55} -> 0.95238095 | F23: {=AVERAGE(C23:E23)} -> 0.87661579 | G23: {=IF(F23>=$H$4,"Alto",IF(F23>=$J$4,"Medio","Bajo: revisar"))} -> Alto
A24: 7° · escenario elegido | B24: Mezcla según el peso de E4 | F24: {=(1-$E$4)*F13+$E$4*F20} -> 0.80901045 | G24: {=IF(F24>=$H$4,"Alto",IF(F24>=$J$4,"Medio","Bajo: revisar"))} -> Medio
A25: 8° · escenario elegido | B25: Mezcla según el peso de E4 | F25: {=(1-$E$4)*F14+$E$4*F21} -> 0.72872312 | G25: {=IF(F25>=$H$4,"Alto",IF(F25>=$J$4,"Medio","Bajo: revisar"))} -> Medio
A28: B · Escenarios para 7.° y 8.°: ¿cuántos temas faltan (+) o sobran (−) en cada sistema según el peso de cada marco?
A29: El eje común son los 3 sistemas de PISA. Las metas de TIMSS 8.° se agrupan igual: Sistemas físicos = Química 20 % + Física 25 %; vivos = Biología 35 %; Tierra y espacio = Ciencias de la Tierra 20 %. En cada escenario: meta = (1 − p)·TIMSS + p·PISA y % actual = (1 − p)·actual TIMSS + p·actual PISA (cada marco con su propia clasificación). Brecha (temas) = (meta − actual) × temas evaluables.
A30: Grado | B30: Sistema | C30: Meta TIMSS (agrupada) | D30: Meta PISA | E30: % actual TIMSS | F30: % actual PISA | G30: 100 % TIMSS · brecha (temas) | H30: 50 / 50 · brecha (temas) | I30: 100 % PISA · brecha (temas) | J30: Personalizado · brecha (temas) | K30: Evaluables TIMSS | L30: Evaluables PISA
A31: Peso de PISA → | G31: 0 | H31: 0.5 | I31: 1 | J31: {=$E$4} -> 0.5
A32: 7° | B32: Sistemas físicos | C32: 0.45 | D32: 0.37 | E32: {=IF(K32=0,0,(_xlfn.COUNTIFS('Datos - Temas'!$V$5:$V$1264,$A32,'Datos - Temas'!$M$5:$M$1264,"Química")+_xlfn.COUNTIFS('Datos - Temas'!$V$5:$V$1264,$A32,'Datos - Temas'!$M$5:$M$1264,"Física"))/K32)} -> 0.12941176 | F32: {=IF(L32=0,0,_xlfn.COUNTIFS('Datos - Temas'!$V$5:$V$1264,$A32,'Datos - Temas'!$AM$5:$AM$1264,$B32)/L32)} -> 0.17777778 | G32: {=((1-G$31)*C32+G$31*D32-((1-G$31)*E32+G$31*F32))*((1-G$31)*K32+G$31*L32)} -> 27.25 | H32: {=((1-H$31)*C32+H$31*D32-((1-H$31)*E32+H$31*F32))*((1-H$31)*K32+H$31*L32)} -> 22.435458 | I32: {=((1-I$31)*C32+I$31*D32-((1-I$31)*E32+I$31*F32))*((1-I$31)*K32+I$31*L32)} -> 17.3 | J32: {=((1-J$31)*C32+J$31*D32-((1-J$31)*E32+J$31*F32))*((1-J$31)*K32+J$31*L32)} -> 22.435458 | K32: {=_xlfn.COUNTIFS('Datos - Temas'!$V$5:$V$1264,$A32,'Datos - Temas'!$C$5:$C$1264,"Ciencias")-_xlfn.COUNTIFS('Datos - Temas'!$V$5:$V$1264,$A32,'Datos - Temas'!$K$5:$K$1264,"FUERA")-_xlfn.COUNTIFS('Datos - Temas'!$V$5:$V$1264,$A32,'Datos - Temas'!$K$5:$K$1264,"PENDIENTE")} -> 85 | L32: {=_xlfn.COUNTIFS('Datos - Temas'!$V$5:$V$1264,$A32,'Datos - Temas'!$AK$5:$AK$1264,"<>")-_xlfn.COUNTIFS('Datos - Temas'!$V$5:$V$1264,$A32,'Datos - Temas'!$AK$5:$AK$1264,"FUERA")} -> 90
A33: 7° | B33: Sistemas vivos | C33: 0.35 | D33: 0.37 | E33: {=IF(K33=0,0,(_xlfn.COUNTIFS('Datos - Temas'!$V$5:$V$1264,$A33,'Datos - Temas'!$M$5:$M$1264,"Biología"))/K33)} -> 0.52941176 | F33: {=IF(L33=0,0,_xlfn.COUNTIFS('Datos - Temas'!$V$5:$V$1264,$A33,'Datos - Temas'!$AM$5:$AM$1264,$B33)/L33)} -> 0.56666667 | G33: {=((1-G$31)*C33+G$31*D33-((1-G$31)*E33+G$31*F33))*((1-G$31)*K33+G$31*L33)} -> -15.25 | H33: {=((1-H$31)*C33+H$31*D33-((1-H$31)*E33+H$31*F33))*((1-H$31)*K33+H$31*L33)} -> -16.453431 | I33: {=((1-I$31)*C33+I$31*D33-((1-I$31)*E33+I$31*F33))*((1-I$31)*K33+I$31*L33)} -> -17.7 | J33: {=((1-J$31)*C33+J$31*D33-((1-J$31)*E33+J$31*F33))*((1-J$31)*K33+J$31*L33)} -> -16.453431 | K33: {=_xlfn.COUNTIFS('Datos - Temas'!$V$5:$V$1264,$A33,'Datos - Temas'!$C$5:$C$1264,"Ciencias")-_xlfn.COUNTIFS('Datos - Temas'!$V$5:$V$1264,$A33,'Datos - Temas'!$K$5:$K$1264,"FUERA")-_xlfn.COUNTIFS('Datos - Temas'!$V$5:$V$1264,$A33,'Datos - Temas'!$K$5:$K$1264,"PENDIENTE")} -> 85 | L33: {=_xlfn.COUNTIFS('Datos - Temas'!$V$5:$V$1264,$A33,'Datos - Temas'!$AK$5:$AK$1264,"<>")-_xlfn.COUNTIFS('Datos - Temas'!$V$5:$V$1264,$A33,'Datos - Temas'!$AK$5:$AK$1264,"FUERA")} -> 90
A34: 7° | B34: Sistemas de la Tierra y el espacio | C34: 0.2 | D34: 0.26 | E34: {=IF(K34=0,0,(_xlfn.COUNTIFS('Datos - Temas'!$V$5:$V$1264,$A34,'Datos - Temas'!$M$5:$M$1264,"Ciencias de la Tierra"))/K34)} -> 0.34117647 | F34: {=IF(L34=0,0,_xlfn.COUNTIFS('Datos - Temas'!$V$5:$V$1264,$A34,'Datos - Temas'!$AM$5:$AM$1264,$B34)/L34)} -> 0.25555556 | G34: {=((1-G$31)*C34+G$31*D34-((1-G$31)*E34+G$31*F34))*((1-G$31)*K34+G$31*L34)} -> -12 | H34: {=((1-H$31)*C34+H$31*D34-((1-H$31)*E34+H$31*F34))*((1-H$31)*K34+H$31*L34)} -> -5.9820261 | I34: {=((1-I$31)*C34+I$31*D34-((1-I$31)*E34+I$31*F34))*((1-I$31)*K34+I$31*L34)} -> 0.4 | J34: {=((1-J$31)*C34+J$31*D34-((1-J$31)*E34+J$31*F34))*((1-J$31)*K34+J$31*L34)} -> -5.9820261 | K34: {=_xlfn.COUNTIFS('Datos - Temas'!$V$5:$V$1264,$A34,'Datos - Temas'!$C$5:$C$1264,"Ciencias")-_xlfn.COUNTIFS('Datos - Temas'!$V$5:$V$1264,$A34,'Datos - Temas'!$K$5:$K$1264,"FUERA")-_xlfn.COUNTIFS('Datos - Temas'!$V$5:$V$1264,$A34,'Datos - Temas'!$K$5:$K$1264,"PENDIENTE")} -> 85 | L34: {=_xlfn.COUNTIFS('Datos - Temas'!$V$5:$V$1264,$A34,'Datos - Temas'!$AK$5:$AK$1264,"<>")-_xlfn.COUNTIFS('Datos - Temas'!$V$5:$V$1264,$A34,'Datos - Temas'!$AK$5:$AK$1264,"FUERA")} -> 90
B35: Coincidencia de balance | G35: {=1-(ABS((1-G$31)*C32+G$31*D32-((1-G$31)*E32+G$31*F32))+ABS((1-G$31)*C33+G$31*D33-((1-G$31)*E33+G$31*F33))+ABS((1-G$31)*C34+G$31*D34-((1-G$31)*E34+G$31*F34)))/2} -> 0.67941176 | H35: {=1-(ABS((1-H$31)*C32+H$31*D32-((1-H$31)*E32+H$31*F32))+ABS((1-H$31)*C33+H$31*D33-((1-H$31)*E33+H$31*F33))+ABS((1-H$31)*C34+H$31*D34-((1-H$31)*E34+H$31*F34)))/2} -> 0.74359477 | I35: {=1-(ABS((1-I$31)*C32+I$31*D32-((1-I$31)*E32+I$31*F32))+ABS((1-I$31)*C33+I$31*D33-((1-I$31)*E33+I$31*F33))+ABS((1-I$31)*C34+I$31*D34-((1-I$31)*E34+I$31*F34)))/2} -> 0.80333333 | J35: {=1-(ABS((1-J$31)*C32+J$31*D32-((1-J$31)*E32+J$31*F32))+ABS((1-J$31)*C33+J$31*D33-((1-J$31)*E33+J$31*F33))+ABS((1-J$31)*C34+J$31*D34-((1-J$31)*E34+J$31*F34)))/2} -> 0.74359477
B36: Índice de apego del escenario | G36: {=(1-G$31)*$F$13+G$31*$F$20} -> 0.75646412 | H36: {=(1-H$31)*$F$13+H$31*$F$20} -> 0.80901045 | I36: {=(1-I$31)*$F$13+I$31*$F$20} -> 0.86155678 | J36: {=(1-J$31)*$F$13+J$31*$F$20} -> 0.80901045
A38: 8° | B38: Sistemas físicos | C38: 0.45 | D38: 0.37 | E38: {=IF(K38=0,0,(_xlfn.COUNTIFS('Datos - Temas'!$V$5:$V$1264,$A38,'Datos - Temas'!$M$5:$M$1264,"Química")+_xlfn.COUNTIFS('Datos - Temas'!$V$5:$V$1264,$A38,'Datos - Temas'!$M$5:$M$1264,"Física"))/K38)} -> 0.66666667 | F38: {=IF(L38=0,0,_xlfn.COUNTIFS('Datos - Temas'!$V$5:$V$1264,$A38,'Datos - Temas'!$AM$5:$AM$1264,$B38)/L38)} -> 0.625 | G38: {=((1-G$31)*C38+G$31*D38-((1-G$31)*E38+G$31*F38))*((1-G$31)*K38+G$31*L38)} -> -20.15 | H38: {=((1-H$31)*C38+H$31*D38-((1-H$31)*E38+H$31*F38))*((1-H$31)*K38+H$31*L38)} -> -21.342917 | I38: {=((1-I$31)*C38+I$31*D38-((1-I$31)*E38+I$31*F38))*((1-I$31)*K38+I$31*L38)} -> -22.44 | J38: {=((1-J$31)*C38+J$31*D38-((1-J$31)*E38+J$31*F38))*((1-J$31)*K38+J$31*L38)} -> -21.342917 | K38: {=_xlfn.COUNTIFS('Datos - Temas'!$V$5:$V$1264,$A38,'Datos - Temas'!$C$5:$C$1264,"Ciencias")-_xlfn.COUNTIFS('Datos - Temas'!$V$5:$V$1264,$A38,'Datos - Temas'!$K$5:$K$1264,"FUERA")-_xlfn.COUNTIFS('Datos - Temas'!$V$5:$V$1264,$A38,'Datos - Temas'!$K$5:$K$1264,"PENDIENTE")} -> 93 | L38: {=_xlfn.COUNTIFS('Datos - Temas'!$V$5:$V$1264,$A38,'Datos - Temas'!$AK$5:$AK$1264,"<>")-_xlfn.COUNTIFS('Datos - Temas'!$V$5:$V$1264,$A38,'Datos - Temas'!$AK$5:$AK$1264,"FUERA")} -> 88
A39: 8° | B39: Sistemas vivos | C39: 0.35 | D39: 0.37 | E39: {=IF(K39=0,0,(_xlfn.COUNTIFS('Datos - Temas'!$V$5:$V$1264,$A39,'Datos - Temas'!$M$5:$M$1264,"Biología"))/K39)} -> 0.29032258 | F39: {=IF(L39=0,0,_xlfn.COUNTIFS('Datos - Temas'!$V$5:$V$1264,$A39,'Datos - Temas'!$AM$5:$AM$1264,$B39)/L39)} -> 0.30681818 | G39: {=((1-G$31)*C39+G$31*D39-((1-G$31)*E39+G$31*F39))*((1-G$31)*K39+G$31*L39)} -> 5.55 | H39: {=((1-H$31)*C39+H$31*D39-((1-H$31)*E39+H$31*F39))*((1-H$31)*K39+H$31*L39)} -> 5.5593805 | I39: {=((1-I$31)*C39+I$31*D39-((1-I$31)*E39+I$31*F39))*((1-I$31)*K39+I$31*L39)} -> 5.56 | J39: {=((1-J$31)*C39+J$31*D39-((1-J$31)*E39+J$31*F39))*((1-J$31)*K39+J$31*L39)} -> 5.5593805 | K39: {=_xlfn.COUNTIFS('Datos - Temas'!$V$5:$V$1264,$A39,'Datos - Temas'!$C$5:$C$1264,"Ciencias")-_xlfn.COUNTIFS('Datos - Temas'!$V$5:$V$1264,$A39,'Datos - Temas'!$K$5:$K$1264,"FUERA")-_xlfn.COUNTIFS('Datos - Temas'!$V$5:$V$1264,$A39,'Datos - Temas'!$K$5:$K$1264,"PENDIENTE")} -> 93 | L39: {=_xlfn.COUNTIFS('Datos - Temas'!$V$5:$V$1264,$A39,'Datos - Temas'!$AK$5:$AK$1264,"<>")-_xlfn.COUNTIFS('Datos - Temas'!$V$5:$V$1264,$A39,'Datos - Temas'!$AK$5:$AK$1264,"FUERA")} -> 88
A40: 8° | B40: Sistemas de la Tierra y el espacio | C40: 0.2 | D40: 0.26 | E40: {=IF(K40=0,0,(_xlfn.COUNTIFS('Datos - Temas'!$V$5:$V$1264,$A40,'Datos - Temas'!$M$5:$M$1264,"Ciencias de la Tierra"))/K40)} -> 0.043010753 | F40: {=IF(L40=0,0,_xlfn.COUNTIFS('Datos - Temas'!$V$5:$V$1264,$A40,'Datos - Temas'!$AM$5:$AM$1264,$B40)/L40)} -> 0.068181818 | G40: {=((1-G$31)*C40+G$31*D40-((1-G$31)*E40+G$31*F40))*((1-G$31)*K40+G$31*L40)} -> 14.6 | H40: {=((1-H$31)*C40+H$31*D40-((1-H$31)*E40+H$31*F40))*((1-H$31)*K40+H$31*L40)} -> 15.783536 | I40: {=((1-I$31)*C40+I$31*D40-((1-I$31)*E40+I$31*F40))*((1-I$31)*K40+I$31*L40)} -> 16.88 | J40: {=((1-J$31)*C40+J$31*D40-((1-J$31)*E40+J$31*F40))*((1-J$31)*K40+J$31*L40)} -> 15.783536 | K40: {=_xlfn.COUNTIFS('Datos - Temas'!$V$5:$V$1264,$A40,'Datos - Temas'!$C$5:$C$1264,"Ciencias")-_xlfn.COUNTIFS('Datos - Temas'!$V$5:$V$1264,$A40,'Datos - Temas'!$K$5:$K$1264,"FUERA")-_xlfn.COUNTIFS('Datos - Temas'!$V$5:$V$1264,$A40,'Datos - Temas'!$K$5:$K$1264,"PENDIENTE")} -> 93 | L40: {=_xlfn.COUNTIFS('Datos - Temas'!$V$5:$V$1264,$A40,'Datos - Temas'!$AK$5:$AK$1264,"<>")-_xlfn.COUNTIFS('Datos - Temas'!$V$5:$V$1264,$A40,'Datos - Temas'!$AK$5:$AK$1264,"FUERA")} -> 88
B41: Coincidencia de balance | G41: {=1-(ABS((1-G$31)*C38+G$31*D38-((1-G$31)*E38+G$31*F38))+ABS((1-G$31)*C39+G$31*D39-((1-G$31)*E39+G$31*F39))+ABS((1-G$31)*C40+G$31*D40-((1-G$31)*E40+G$31*F40)))/2} -> 0.78333333 | H41: {=1-(ABS((1-H$31)*C38+H$31*D38-((1-H$31)*E38+H$31*F38))+ABS((1-H$31)*C39+H$31*D39-((1-H$31)*E39+H$31*F39))+ABS((1-H$31)*C40+H$31*D40-((1-H$31)*E40+H$31*F40)))/2} -> 0.76416667 | I41: {=1-(ABS((1-I$31)*C38+I$31*D38-((1-I$31)*E38+I$31*F38))+ABS((1-I$31)*C39+I$31*D39-((1-I$31)*E39+I$31*F39))+ABS((1-I$31)*C40+I$31*D40-((1-I$31)*E40+I$31*F40)))/2} -> 0.745 | J41: {=1-(ABS((1-J$31)*C38+J$31*D38-((1-J$31)*E38+J$31*F38))+ABS((1-J$31)*C39+J$31*D39-((1-J$31)*E39+J$31*F39))+ABS((1-J$31)*C40+J$31*D40-((1-J$31)*E40+J$31*F40)))/2} -> 0.76416667
B42: Índice de apego del escenario | G42: {=(1-G$31)*$F$14+G$31*$F$21} -> 0.74677419 | H42: {=(1-H$31)*$F$14+H$31*$F$21} -> 0.72872312 | I42: {=(1-I$31)*$F$14+I$31*$F$21} -> 0.71067204 | J42: {=(1-J$31)*$F$14+J$31*$F$21} -> 0.72872312
A45: C · Cómo usar los escenarios (recomendación)
A46: 1. Los tres escenarios pedidos (100 % TIMSS, 50/50, 100 % PISA) están lado a lado; la columna «Personalizado» toma el peso de la celda E4, para probar cualquier mezcla (p. ej. 70 % PISA).
A47: 2. Mezclar METAS solo tiene sentido en un eje común (los 3 sistemas). Las metas cognitivas NO se mezclan: TIMSS mide Conocer/Aplicar/Razonar y PISA tres competencias distintas; por eso el escenario mezcla los ÍNDICES de apego, no las metas cognitivas.
...

Sheet Presupuesto de temas
A1: Presupuesto de temas: qué insertar y qué fusionar para acercarse a las metas SIN aumentar el número de temas
A2: {="TIMSS 2027 (2.°–8.°) y PISA 2025 (7.°–9.°)"&" "&"● El total de temas no cambia: cada tema nuevo se paga uniendo dos temas que se repiten."&" "&"● TIMSS 2.°–4.°: "&FIXED(G9+H9,0)&" temas nuevos a cambio de "&FIXED(J9,0)&" uniones de temas repetidos. TIMSS 5.°–8.°: ya equilibrado; solo "&FIXED(G15+H15,0)&" tema nuevo (un objetivo que nadie enseña)."&" "&"● PISA 7.°–9.°: "&FIXED(G20+H20,0)&" temas nuevos de biología y Tierra a cambio de "&FIXED(J20,0)&" uniones en física y química."&" "&"→ Filtra «¿Entra en el presupuesto?» = Sí y anota tu decisión en la última columna."} -> TIMSS 2027 (2.°–8.°) y PISA 2025 (7.°–9.°) ● El total de temas no cambia: cada tema nuevo se paga uniendo dos temas que se repiten. ● TIMSS 2.°–4.°: 13 temas nuevos a cambio de 13 uniones de temas repetidos. TIMSS 5.°–8.°: ya equilibrado; solo 1 tema nuevo (un objetivo que nadie enseña). ● PISA 7.°–9.°: 33 temas nuevos de biología y Tierra a cambio de 33 uniones en física y química. → Filtra «¿Entra en el presupuesto?» = Sí y anota tu decisión en la última columna.
A3: Se trabaja por CICLO y no por grado: la meta del marco es para lo acumulado, y por grado salen brechas grandes que se compensan entre sí (p. ej. 5.°–8.°: Biología +19 en 5.° y −15 en 7.°, que se resuelve reubicando, no insertando y fusionando). 7.° y 8.° aparecen en el ciclo TIMSS 5.°–8.° y en el PISA 7.°–9.°: según el peso elegido en Apego TIMSS y PISA, seguir uno u otro bloque.
A5: Clave | B5: Ciclo | C5: Marco | D5: Área | E5: Brecha del ciclo (temas) | F5: Estado | G5: Inserciones por balance | H5: Inserciones por cobertura | I5: Temas a liberar con fusiones | J5: Temas que liberan las fusiones elegidas | K5: Saldo (insertados − liberados)
A6: 2-4|Biología | B6: Ciclo 2°–4° | C6: TIMSS 2027 4.° | D6: Biología | E6: {='TIMSS - Balance por ciclo'!I6} -> -12.1 | F6: {='TIMSS - Balance por ciclo'!K6} -> Sobran 12 temas | G6: {=IF(COUNTIF($F$6:$F$8,"En meta")=ROWS($F$6:$F$8),0,MAX(0,ROUND(E6,0)))} -> 0 | H6: {=_xlfn.COUNTIFS($B$24:$B$191,A6,$D$24:$D$191,"insertar",$E$24:$E$191,"cobertura")} -> 1 | I6: {=IF(COUNTIF($F$6:$F$8,"En meta")=ROWS($F$6:$F$8),0,MAX(0,ROUND(-E6,0)))+H6} -> 13 | J6: {=_xlfn.SUMIFS($O$24:$O$191,$B$24:$B$191,A6,$D$24:$D$191,"fusionar",$P$24:$P$191,"Sí")} -> 13 | K6: {=G6+H6-J6} -> -12
A7: 2-4|Ciencias físicas | B7: Ciclo 2°–4° | C7: TIMSS 2027 4.° | D7: Ciencias físicas | E7: {='TIMSS - Balance por ciclo'!I7} -> 8.7 | F7: {='TIMSS - Balance por ciclo'!K7} -> En meta | G7: {=IF(COUNTIF($F$6:$F$8,"En meta")=ROWS($F$6:$F$8),0,MAX(0,ROUND(E7,0)))} -> 9 | H7: {=_xlfn.COUNTIFS($B$24:$B$191,A7,$D$24:$D$191,"insertar",$E$24:$E$191,"cobertura")} -> 0 | I7: {=IF(COUNTIF($F$6:$F$8,"En meta")=ROWS($F$6:$F$8),0,MAX(0,ROUND(-E7,0)))+H7} -> 0 | J7: {=_xlfn.SUMIFS($O$24:$O$191,$B$24:$B$191,A7,$D$24:$D$191,"fusionar",$P$24:$P$191,"Sí")} -> 0 | K7: {=G7+H7-J7} -> 9
A8: 2-4|Ciencias de la Tierra | B8: Ciclo 2°–4° | C8: TIMSS 2027 4.° | D8: Ciencias de la Tierra | E8: {='TIMSS - Balance por ciclo'!I8} -> 3.4 | F8: {='TIMSS - Balance por ciclo'!K8} -> En meta | G8: {=IF(COUNTIF($F$6:$F$8,"En meta")=ROWS($F$6:$F$8),0,MAX(0,ROUND(E8,0)))} -> 3 | H8: {=_xlfn.COUNTIFS($B$24:$B$191,A8,$D$24:$D$191,"insertar",$E$24:$E$191,"cobertura")} -> 0 | I8: {=IF(COUNTIF($F$6:$F$8,"En meta")=ROWS($F$6:$F$8),0,MAX(0,ROUND(-E8,0)))+H8} -> 0 | J8: {=_xlfn.SUMIFS($O$24:$O$191,$B$24:$B$191,A8,$D$24:$D$191,"fusionar",$P$24:$P$191,"Sí")} -> 0 | K8: {=G8+H8-J8} -> 3
D9: Total Ciclo 2°–4° | G9: {=SUM(G6:G8)} -> 12 | H9: {=SUM(H6:H8)} -> 1 | I9: {=SUM(I6:I8)} -> 13 | J9: {=SUM(J6:J8)} -> 13 | K9: {=SUM(K6:K8)} -> 0
A11: 5-8|Biología | B11: Ciclo 5°–8° | C11: TIMSS 2027 8.° | D11: Biología | E11: {='TIMSS - Balance por ciclo'!I11} -> 2.7 | F11: {='TIMSS - Balance por ciclo'!K11} -> En meta | G11: {=IF(COUNTIF($F$11:$F$14,"En meta")=ROWS($F$11:$F$14),0,MAX(0,ROUND(E11,0)))} -> 0 | H11: {=_xlfn.COUNTIFS($B$24:$B$191,A11,$D$24:$D$191,"insertar",$E$24:$E$191,"cobertura")} -> 0 | I11: {=IF(COUNTIF($F$11:$F$14,"En meta")=ROWS($F$11:$F$14),0,MAX(0,ROUND(-E11,0)))+H11} -> 0 | J11: {=_xlfn.SUMIFS($O$24:$O$191,$B$24:$B$191,A11,$D$24:$D$191,"fusionar",$P$24:$P$191,"Sí")} -> 0 | K11: {=G11+H11-J11} -> 0
A12: 5-8|Química | B12: Ciclo 5°–8° | C12: TIMSS 2027 8.° | D12: Química | E12: {='TIMSS - Balance por ciclo'!I12} -> -2.6 | F12: {='TIMSS - Balance por ciclo'!K12} -> En meta | G12: {=IF(COUNTIF($F$11:$F$14,"En meta")=ROWS($F$11:$F$14),0,MAX(0,ROUND(E12,0)))} -> 0 | H12: {=_xlfn.COUNTIFS($B$24:$B$191,A12,$D$24:$D$191,"insertar",$E$24:$E$191,"cobertura")} -> 0 | I12: {=IF(COUNTIF($F$11:$F$14,"En meta")=ROWS($F$11:$F$14),0,MAX(0,ROUND(-E12,0)))+H12} -> 0 | J12: {=_xlfn.SUMIFS($O$24:$O$191,$B$24:$B$191,A12,$D$24:$D$191,"fusionar",$P$24:$P$191,"Sí")} -> 0 | K12: {=G12+H12-J12} -> 0
A13: 5-8|Física | B13: Ciclo 5°–8° | C13: TIMSS 2027 8.° | D13: Física | E13: {='TIMSS - Balance por ciclo'!I13} -> -7.5 | F13: {='TIMSS - Balance por ciclo'!K13} -> En meta | G13: {=IF(COUNTIF($F$11:$F$14,"En meta")=ROWS($F$11:$F$14),0,MAX(0,ROUND(E13,0)))} -> 0 | H13: {=_xlfn.COUNTIFS($B$24:$B$191,A13,$D$24:$D$191,"insertar",$E$24:$E$191,"cobertura")} -> 1 | I13: {=IF(COUNTIF($F$11:$F$14,"En meta")=ROWS($F$11:$F$14),0,MAX(0,ROUND(-E13,0)))+H13} -> 1 | J13: {=_xlfn.SUMIFS($O$24:$O$191,$B$24:$B$191,A13,$D$24:$D$191,"fusionar",$P$24:$P$191,"Sí")} -> 1 | K13: {=G13+H13-J13} -> 0
A14: 5-8|Ciencias de la Tierra | B14: Ciclo 5°–8° | C14: TIMSS 2027 8.° | D14: Ciencias de la Tierra | E14: {='TIMSS - Balance por ciclo'!I14} -> 7.4 | F14: {='TIMSS - Balance por ciclo'!K14} -> En meta | G14: {=IF(COUNTIF($F$11:$F$14,"En meta")=ROWS($F$11:$F$14),0,MAX(0,ROUND(E14,0)))} -> 0 | H14: {=_xlfn.COUNTIFS($B$24:$B$191,A14,$D$24:$D$191,"insertar",$E$24:$E$191,"cobertura")} -> 0 | I14: {=IF(COUNTIF($F$11:$F$14,"En meta")=ROWS($F$11:$F$14),0,MAX(0,ROUND(-E14,0)))+H14} -> 0 | J14: {=_xlfn.SUMIFS($O$24:$O$191,$B$24:$B$191,A14,$D$24:$D$191,"fusionar",$P$24:$P$191,"Sí")} -> 0 | K14: {=G14+H14-J14} -> 0
D15: Total Ciclo 5°–8° | G15: {=SUM(G11:G14)} -> 0 | H15: {=SUM(H11:H14)} -> 1 | I15: {=SUM(I11:I14)} -> 1 | J15: {=SUM(J11:J14)} -> 1 | K15: {=SUM(K11:K14)} -> 0
A17: 7-9|Sistemas físicos | B17: Ciclo 7°–9° | C17: PISA 2025 | D17: Sistemas físicos | E17: {='PISA - Contenidos'!I21} -> -33.06 | F17: {='PISA - Contenidos'!K21} -> Sobran 33 temas | G17: {=IF(COUNTIF($F$17:$F$19,"En meta")=ROWS($F$17:$F$19),0,MAX(0,ROUND(E17,0)))} -> 0 | H17: {=_xlfn.COUNTIFS($B$24:$B$191,A17,$D$24:$D$191,"insertar",$E$24:$E$191,"cobertura")} -> 0 | I17: {=IF(COUNTIF($F$17:$F$19,"En meta")=ROWS($F$17:$F$19),0,MAX(0,ROUND(-E17,0)))+H17} -> 33 | J17: {=_xlfn.SUMIFS($O$24:$O$191,$B$24:$B$191,A17,$D$24:$D$191,"fusionar",$P$24:$P$191,"Sí")} -> 33 | K17: {=G17+H17-J17} -> -33
