Workbook

Sheet Leeme
B1: Cobertura TIMSS de la malla de Ciencia y Tecnología — cómo se construyó y cómo leerla
B2: Versión 1 · 1 de octubre de 2026 · Elaborado con Claude (Cowork) a partir de las mallas compartidas por el equipo de Ciencias (MINED).
B4: Qué responde este libro
B5: 1. Balance: ¿el reparto de temas entre Vida / Física / Química / Tierra se parece al peso que TIMSS da a cada dominio? ¿Cuántos temas faltan o sobran para llegar a la meta?
B6: 2. Amplitud: ¿qué objetivos de contenido de TIMSS aparecen en la malla, en qué grado, con cuántos temas, y cuáles no aparecen?
B7: 3. Profundidad cognitiva: ¿la proporción Conocer / Aplicar / Razonar se parece a la de TIMSS?
B9: Proceso (de dónde salen los números)
B10: Paso 1 · Extracción. Se leyeron las 11 mallas (2.° a 9.° y Física, Química, Biología de 10.° y 11.°). Cada fila con «Procedimental» es un TEMA: 1.260 en total. Se conservan archivo, hoja y fila de origen (hoja Temas_TIMSS, columnas D-F) para poder volver a la malla.
B11: Paso 2 · Catálogo de referencia. Se armó la lista de objetivos de contenido de TIMSS 2023 (4.° grado: 32 objetivos; 8.° grado: 46) y de TIMSS Advanced 2015 Física (23), con su dominio y el % que TIMSS asigna a cada dominio (hoja Catalogo_TIMSS, en azul = valores tomados del marco).
B12: Paso 3 · Clasificación. Cada tema de 2.° a 9.° y de Física 10.°–11.° (889 temas) se asignó a UN objetivo principal y, si aplica, uno secundario, leyendo procedimental, contenido, indicador y evidencia. Lo hicieron agentes de IA con instrucciones fijas, tema por tema, dejando confianza (alta/media/baja) y una justificación corta. Los temas sin contenido TIMSS (medición general, método científico, tecnología/diseño, gestión de riesgos, electrónica digital, mecánica de fluidos en Bachillerato, etc.) se marcan «FUERA».
B13: Paso 4 · Reglas de grado. 2.°–4.° se comparan con TIMSS 4.°; 5.°–9.° con TIMSS 8.° (9.° solo como referencia, porque TIMSS 8.° evalúa hasta 8.°); Física 10.°–11.° con TIMSS Advanced. Química y Biología de Bachillerato no tienen marco TIMSS de contenido: solo entran en el análisis cognitivo.
B14: Paso 5 · Cálculo (todo con fórmulas). % actual = temas del dominio ÷ temas evaluables (sin FUERA). Temas esperados = meta × evaluables. Brecha = esperados − actuales (+ faltan, − sobran). «Temas a agregar sin quitar»: se busca el menor total que permite cumplir todas las metas sumando temas (lo fija el dominio más sobrerrepresentado: total = máx(actual ÷ meta)), y a cada dominio se le suma meta × total − actual, redondeado hacia arriba.
... B33: • 1.° grado no tiene malla, así que no entra en el ciclo 2.°–4.°.

Sheet Resumen
A1: Cobertura de la malla de Ciencias de El Salvador frente a TIMSS — resumen por grado
A2: Todo es fórmula sobre Temas_TIMSS. Balance = reparto de temas por dominio vs. metas TIMSS. Amplitud = objetivos TIMSS que aparecen. Profundidad cognitiva = Conocer/Aplicar/Razonar. Ver «Leeme» para el proceso completo.
A4: Grupo | B4: Marco de referencia | C4: Temas totales | D4: Temas fuera del marco | E4: % fuera del marco | F4: Dominio con mayor FALTANTE | G4: Faltan (temas) | H4: Dominio más SOBRErrepresentado | I4: Sobran (temas) | J4: Temas a agregar para cumplir todas las metas sin quitar | K4: Dominios en meta (±tolerancia) | L4: % Razonar actual | M4: % Razonar meta
A5: 2° | B5: TIMSS 2023 4.° | C5: =COUNTIFS(Temas_TIMSS!$V$5:$V$1264,$A5) -> 70 | D5: =Balance_grado!N6 -> 13 | E5: =IF(C5=0,0,D5/C5) -> 0.18571429 | F5: =INDEX(Balance_grado!$C$6:$C$8,MATCH(MAX(Balance_grado!$I$6:$I$8),Balance_grado!$I$6:$I$8,0)) -> Ciencias de la vida | G5: =ROUND(MAX(Balance_grado!$I$6:$I$8),0) -> 2 | H5: =INDEX(Balance_grado!$C$6:$C$8,MATCH(MIN(Balance_grado!$I$6:$I$8),Balance_grado!$I$6:$I$8,0)) -> Ciencias físicas | I5: =ROUND(-MIN(Balance_grado!$I$6:$I$8),0) -> 3 | J5: =Balance_grado!M9 -> 10 | K5: =COUNTIF(Balance_grado!$K$6:$K$8,"En meta")&" de "&ROWS(Balance_grado!$K$6:$K$8) -> 2 de 3 | L5: =Cognitivo_grado!I5 -> 0.27142857 | M5: =Cognitivo_grado!L5 -> 0.2
A6: 3° | B6: TIMSS 2023 4.° | C6: =COUNTIFS(Temas_TIMSS!$V$5:$V$1264,$A6) -> 66 | D6: =Balance_grado!N11 -> 9 | E6: =IF(C6=0,0,D6/C6) -> 0.13636364 | F6: =INDEX(Balance_grado!$C$11:$C$13,MATCH(MAX(Balance_grado!$I$11:$I$13),Balance_grado!$I$11:$I$13,0)) -> Ciencias físicas | G6: =ROUND(MAX(Balance_grado!$I$11:$I$13),0) -> 3 | H6: =INDEX(Balance_grado!$C$11:$C$13,MATCH(MIN(Balance_grado!$I$11:$I$13),Balance_grado!$I$11:$I$13,0)) -> Ciencias de la vida | I6: =ROUND(-MIN(Balance_grado!$I$11:$I$13),0) -> 5 | J6: =Balance_grado!M14 -> 13 | K6: =COUNTIF(Balance_grado!$K$11:$K$13,"En meta")&" de "&ROWS(Balance_grado!$K$11:$K$13) -> 1 de 3 | L6: =Cognitivo_grado!I6 -> 0.26515152 | M6: =Cognitivo_grado!L6 -> 0.2
A7: 4° | B7: TIMSS 2023 4.° | C7: =COUNTIFS(Temas_TIMSS!$V$5:$V$1264,$A7) -> 72 | D7: =Balance_grado!N16 -> 8 | E7: =IF(C7=0,0,D7/C7) -> 0.11111111 | F7: =INDEX(Balance_grado!$C$16:$C$18,MATCH(MAX(Balance_grado!$I$16:$I$18),Balance_grado!$I$16:$I$18,0)) -> Ciencias físicas | G7: =ROUND(MAX(Balance_grado!$I$16:$I$18),0) -> 13 | H7: =INDEX(Balance_grado!$C$16:$C$18,MATCH(MIN(Balance_grado!$I$16:$I$18),Balance_grado!$I$16:$I$18,0)) -> Ciencias de la vida | I7: =ROUND(-MIN(Balance_grado!$I$16:$I$18),0) -> 8 | J7: =Balance_grado!M19 -> 27 | K7: =COUNTIF(Balance_grado!$K$16:$K$18,"En meta")&" de "&ROWS(Balance_grado!$K$16:$K$18) -> 0 de 3 | L7: =Cognitivo_grado!I7 -> 0.20138889 | M7: =Cognitivo_grado!L7 -> 0.2
A8: 5° | B8: TIMSS 2023 8.° | C8: =COUNTIFS(Temas_TIMSS!$V$5:$V$1264,$A8) -> 72 | D8: =Balance_grado!N21 -> 14 | E8: =IF(C8=0,0,D8/C8) -> 0.19444444 | F8: =INDEX(Balance_grado!$C$21:$C$24,MATCH(MAX(Balance_grado!$I$21:$I$24),Balance_grado!$I$21:$I$24,0)) -> Biología | G8: =ROUND(MAX(Balance_grado!$I$21:$I$24),0) -> 19 | H8: =INDEX(Balance_grado!$C$21:$C$24,MATCH(MIN(Balance_grado!$I$21:$I$24),Balance_grado!$I$21:$I$24,0)) -> Ciencias de la Tierra | I8: =ROUND(-MIN(Balance_grado!$I$21:$I$24),0) -> 12 | J8: =Balance_grado!M25 -> 62 | K8: =COUNTIF(Balance_grado!$K$21:$K$24,"En meta")&" de "&ROWS(Balance_grado!$K$21:$K$24) -> 1 de 4 | L8: =Cognitivo_grado!I8 -> 0.24305556 | M8: =Cognitivo_grado!L8 -> 0.3
A9: 6° | B9: TIMSS 2023 8.° | C9: =COUNTIFS(Temas_TIMSS!$V$5:$V$1264,$A9) -> 68 | D9: =Balance_grado!N27 -> 0 | E9: =IF(C9=0,0,D9/C9) -> 0 | F9: =INDEX(Balance_grado!$C$27:$C$30,MATCH(MAX(Balance_grado!$I$27:$I$30),Balance_grado!$I$27:$I$30,0)) -> Ciencias de la Tierra | G9: =ROUND(MAX(Balance_grado!$I$27:$I$30),0) -> 14 | H9: =INDEX(Balance_grado!$C$27:$C$30,MATCH(MIN(Balance_grado!$I$27:$I$30),Balance_grado!$I$27:$I$30,0)) -> Biología | I9: =ROUND(-MIN(Balance_grado!$I$27:$I$30),0) -> 10 | J9: =Balance_grado!M31 -> 37 | K9: =COUNTIF(Balance_grado!$K$27:$K$30,"En meta")&" de "&ROWS(Balance_grado!$K$27:$K$30) -> 0 de 4 | L9: =Cognitivo_grado!I9 -> 0.19117647 | M9: =Cognitivo_grado!L9 -> 0.3
A10: 7° | B10: TIMSS 2023 8.° | C10: =COUNTIFS(Temas_TIMSS!$V$5:$V$1264,$A10) -> 91 | D10: =Balance_grado!N33 -> 6 | E10: =IF(C10=0,0,D10/C10) -> 0.065934066 | F10: =INDEX(Balance_grado!$C$33:$C$36,MATCH(MAX(Balance_grado!$I$33:$I$36),Balance_grado!$I$33:$I$36,0)) -> Física | G10: =ROUND(MAX(Balance_grado!$I$33:$I$36),0) -> 18 | H10: =INDEX(Balance_grado!$C$33:$C$36,MATCH(MIN(Balance_grado!$I$33:$I$36),Balance_grado!$I$33:$I$36,0)) -> Biología | I10: =ROUND(-MIN(Balance_grado!$I$33:$I$36),0) -> 18 | J10: =Balance_grado!M37 -> 54 | K10: =COUNTIF(Balance_grado!$K$33:$K$36,"En meta")&" de "&ROWS(Balance_grado!$K$33:$K$36) -> 0 de 4 | L10: =Cognitivo_grado!I10 -> 0.28571429 | M10: =Cognitivo_grado!L10 -> 0.3
A11: 8° | B11: TIMSS 2023 8.° | C11: =COUNTIFS(Temas_TIMSS!$V$5:$V$1264,$A11) -> 93 | D11: =Balance_grado!N39 -> 2 | E11: =IF(C11=0,0,D11/C11) -> 0.021505376 | F11: =INDEX(Balance_grado!$C$39:$C$42,MATCH(MAX(Balance_grado!$I$39:$I$42),Balance_grado!$I$39:$I$42,0)) -> Ciencias de la Tierra | G11: =ROUND(MAX(Balance_grado!$I$39:$I$42),0) -> 14 | H11: =INDEX(Balance_grado!$C$39:$C$42,MATCH(MIN(Balance_grado!$I$39:$I$42),Balance_grado!$I$39:$I$42,0)) -> Física | I11: =ROUND(-MIN(Balance_grado!$I$39:$I$42),0) -> 12 | J11: =Balance_grado!M43 -> 49 | K11: =COUNTIF(Balance_grado!$K$39:$K$42,"En meta")&" de "&ROWS(Balance_grado!$K$39:$K$42) -> 1 de 4 | L11: =Cognitivo_grado!I11 -> 0.20967742 | M11: =Cognitivo_grado!L11 -> 0.3
A12: 9° | B12: TIMSS 2023 8.° | C12: =COUNTIFS(Temas_TIMSS!$V$5:$V$1264,$A12) -> 90 | D12: =Balance_grado!N45 -> 8 | E12: =IF(C12=0,0,D12/C12) -> 0.088888889 | F12: =INDEX(Balance_grado!$C$45:$C$48,MATCH(MAX(Balance_grado!$I$45:$I$48),Balance_grado!$I$45:$I$48,0)) -> Biología | G12: =ROUND(MAX(Balance_grado!$I$45:$I$48),0) -> 25 | H12: =INDEX(Balance_grado!$C$45:$C$48,MATCH(MIN(Balance_grado!$I$45:$I$48),Balance_grado!$I$45:$I$48,0)) -> Física | I12: =ROUND(-MIN(Balance_grado!$I$45:$I$48),0) -> 18 | J12: =Balance_grado!M49 -> 72 | K12: =COUNTIF(Balance_grado!$K$45:$K$48,"En meta")&" de "&ROWS(Balance_grado!$K$45:$K$48) -> 2 de 4 | L12: =Cognitivo_grado!I12 -> 0.17777778 | M12: =Cognitivo_grado!L12 -> 0.3
A13: Física 10° | B13: TIMSS Advanced 2015 Física | C13: =COUNTIFS(Temas_TIMSS!$V$5:$V$1264,$A13) -> 121 | D13: =Balance_grado!N51 -> 41 | E13: =IF(C13=0,0,D13/C13) -> 0.33884298 | F13: =INDEX(Balance_grado!$C$51:$C$53,MATCH(MAX(Balance_grado!$I$51:$I$53),Balance_grado!$I$51:$I$53,0)) -> Electricidad y magnetismo | G13: =ROUND(MAX(Balance_grado!$I$51:$I$53),0) -> 20 | H13: =INDEX(Balance_grado!$C$51:$C$53,MATCH(MIN(Balance_grado!$I$51:$I$53),Balance_grado!$I$51:$I$53,0)) -> Mecánica y termodinámica | I13: =ROUND(-MIN(Balance_grado!$I$51:$I$53),0) -> 35 | J13: =Balance_grado!M54 -> 88 | K13: =COUNTIF(Balance_grado!$K$51:$K$53,"En meta")&" de "&ROWS(Balance_grado!$K$51:$K$53) -> 0 de 3 | L13: =Cognitivo_grado!I13 -> 0.48071625 | M13: =Cognitivo_grado!L13 -> 0.3
A14: Física 11° | B14: TIMSS Advanced 2015 Física | C14: =COUNTIFS(Temas_TIMSS!$V$5:$V$1264,$A14) -> 146 | D14: =Balance_grado!N56 -> 27 | E14: =IF(C14=0,0,D14/C14) -> 0.18493151 | F14: =INDEX(Balance_grado!$C$56:$C$58,MATCH(MAX(Balance_grado!$I$56:$I$58),Balance_grado!$I$56:$I$58,0)) -> Mecánica y termodinámica | G14: =ROUND(MAX(Balance_grado!$I$56:$I$58),0) -> 44 | H14: =INDEX(Balance_grado!$C$56:$C$58,MATCH(MIN(Balance_grado!$I$56:$I$58),Balance_grado!$I$56:$I$58,0)) -> Ondas y física atómica/nuclear | I14: =ROUND(-MIN(Balance_grado!$I$56:$I$58),0) -> 30 | J14: =Balance_grado!M59 -> 88 | K14: =COUNTIF(Balance_grado!$K$56:$K$58,"En meta")&" de "&ROWS(Balance_grado!$K$56:$K$58) -> 0 de 3 | L14: =Cognitivo_grado!I14 -> 0.46575342 | M14: =Cognitivo_grado!L14 -> 0.3
A16: Por ciclo (comparación acumulada)
A17: Ciclo | B17: Marco de referencia | C17: Temas evaluables | D17: Dominio con mayor FALTANTE | E17: Faltan (temas) | F17: Dominio más SOBRErrepresentado | G17: Sobran (temas) | H17: Temas a agregar sin quitar | I17: Dominios en meta | J17: Objetivos TIMSS del marco | K17: Objetivos cubiertos | L17: % amplitud | M17: Objetivos no cubiertos
A18: Ciclo 2°–4° | B18: TIMSS 2023 4.° | C18: =Balance_ciclo!E6 -> 178 | D18: =INDEX(Balance_ciclo!$C$6:$C$8,MATCH(MAX(Balance_ciclo!$I$6:$I$8),Balance_ciclo!$I$6:$I$8,0)) -> Ciencias físicas | E18: =ROUND(MAX(Balance_ciclo!$I$6:$I$8),0) -> 13 | F18: =INDEX(Balance_ciclo!$C$6:$C$8,MATCH(MIN(Balance_ciclo!$I$6:$I$8),Balance_ciclo!$I$6:$I$8,0)) -> Ciencias de la vida | G18: =ROUND(-MIN(Balance_ciclo!$I$6:$I$8),0) -> 12 | H18: =Balance_ciclo!M9 -> 27 | I18: =COUNTIF(Balance_ciclo!$K$6:$K$8,"En meta")&" de "&ROWS(Balance_ciclo!$K$6:$K$8) -> 1 de 3 | J18: =Cobertura_objetivos!C113 -> 32 | K18: =Cobertura_objetivos!D113 -> 31 | L18: =Cobertura_objetivos!E113 -> 0.96875 | M18: =Cobertura_objetivos!F113 -> 1
A19: Ciclo 5°–8° | B19: TIMSS 2023 8.° | C19: =Balance_ciclo!E11 -> 302 | D19: =INDEX(Balance_ciclo!$C$11:$C$14,MATCH(MAX(Balance_ciclo!$I$11:$I$14),Balance_ciclo!$I$11:$I$14,0)) -> Ciencias de la Tierra | E19: =ROUND(MAX(Balance_ciclo!$I$11:$I$14),0) -> 6 | F19: =INDEX(Balance_ciclo!$C$11:$C$14,MATCH(MIN(Balance_ciclo!$I$11:$I$14),Balance_ciclo!$I$11:$I$14,0)) -> Biología | G19: =ROUND(-MIN(Balance_ciclo!$I$11:$I$14),0) -> 5 | H19: =Balance_ciclo!M15 -> 17 | I19: =COUNTIF(Balance_ciclo!$K$11:$K$14,"En meta")&" de "&ROWS(Balance_ciclo!$K$11:$K$14) -> 4 de 4 | J19: =Cobertura_objetivos!C118 -> 46 | K19: =Cobertura_objetivos!D118 -> 43 | L19: =Cobertura_objetivos!E118 -> 0.93478261 | M19: =Cobertura_objetivos!F118 -> 3
A20: 9° | B20: TIMSS 2023 8.° | C20: =Balance_ciclo!E17 -> 82 | D20: =INDEX(Balance_ciclo!$C$17:$C$20,MATCH(MAX(Balance_ciclo!$I$17:$I$20),Balance_ciclo!$I$17:$I$20,0)) -> Biología | E20: =ROUND(MAX(Balance_ciclo!$I$17:$I$20),0) -> 25 | F20: =INDEX(Balance_ciclo!$C$17:$C$20,MATCH(MIN(Balance_ciclo!$I$17:$I$20),Balance_ciclo!$I$17:$I$20,0)) -> Física | G20: =ROUND(-MIN(Balance_ciclo!$I$17:$I$20),0) -> 18 | H20: =Balance_ciclo!M21 -> 72 | I20: =COUNTIF(Balance_ciclo!$K$17:$K$20,"En meta")&" de "&ROWS(Balance_ciclo!$K$17:$K$20) -> 2 de 4 | J20: — | K20: — | L20: — | M20: —
A21: Física 10°–11° | B21: TIMSS Advanced 2015 Física | C21: =Balance_ciclo!E23 -> 199 | D21: =INDEX(Balance_ciclo!$C$23:$C$25,MATCH(MAX(Balance_ciclo!$I$23:$I$25),Balance_ciclo!$I$23:$I$25,0)) -> Mecánica y termodinámica | E21: =ROUND(MAX(Balance_ciclo!$I$23:$I$25),0) -> 9 | F21: =INDEX(Balance_ciclo!$C$23:$C$25,MATCH(MIN(Balance_ciclo!$I$23:$I$25),Balance_ciclo!$I$23:$I$25,0)) -> Ondas y física atómica/nuclear | G21: =ROUND(-MIN(Balance_ciclo!$I$23:$I$25),0) -> 15 | H21: =Balance_ciclo!M26 -> 45 | I21: =COUNTIF(Balance_ciclo!$K$23:$K$25,"En meta")&" de "&ROWS(Balance_ciclo!$K$23:$K$25) -> 2 de 3 | J21: =Cobertura_objetivos!C122 -> 23 | K21: =Cobertura_objetivos!D122 -> 23 | L21: =Cobertura_objetivos!E122 -> 1 | M21: =Cobertura_objetivos!F122 -> 0

Sheet Balance_ciclo
A1: Balance de contenidos por ciclo (comparación acumulada, la más fiel a TIMSS)
A2: Tolerancia para considerar «en meta» (± puntos porcentuales): | H2: 0.05
A3: TIMSS 4.° evalúa lo aprendido hasta 4.° grado → se compara con el acumulado de 2.° a 4.° (1.° grado no tiene malla). TIMSS 8.° evalúa lo aprendido hasta 8.° → acumulado de 5.° a 8.°. 9.° se muestra contra TIMSS 8.° solo como referencia. Física de Bachillerato se compara con TIMSS Advanced 2015 (Física). Química y Biología de Bachillerato no tienen marco TIMSS de contenido.
A5: Grupo | B5: Marco de referencia | C5: Dominio | D5: Temas actuales en el dominio | E5: Temas evaluables del grupo (sin «fuera») | F5: % actual | G5: Meta TIMSS (%) | H5: Temas esperados según meta | I5: Brecha (temas): + faltan / − sobran | J5: Brecha (pp) | K5: Estado | L5: Escala para cumplir sin quitar temas (total evaluables) | M5: Temas a AGREGAR para llegar a la meta sin quitar | N5: Temas «fuera del marco» del grupo
A6: Ciclo 2°–4° | B6: TIMSS 2023 4.° | C6: Ciencias de la vida | D6: =COUNTIFS(Temas_TIMSS!$W$5:$W$1264,$A6,Temas_TIMSS!$M$5:$M$1264,$C6) -> 92 | E6: =COUNTIFS(Temas_TIMSS!$W$5:$W$1264,$A6)-COUNTIFS(Temas_TIMSS!$W$5:$W$1264,$A6,Temas_TIMSS!$K$5:$K$1264,"FUERA")-COUNTIFS(Temas_TIMSS!$W$5:$W$1264,$A6,Temas_TIMSS!$K$5:$K$1264,"PENDIENTE") -> 178 | F6: =IF(E6=0,0,D6/E6) -> 0.51685393 | G6: 0.45 | H6: =G6*E6 -> 80.1 | I6: =H6-D6 -> -11.9 | J6: =(G6-F6)*100 -> -6.6853933 | K6: =IF(ABS(G6-F6)<=$H$2,"En meta",IF(I6>0,"Faltan "&ROUND(I6,0)&" temas","Sobran "&ROUND(-I6,0)&" temas")) -> Sobran 12 temas | L6: =MAX(D6/G6,D7/G7,D8/G8) -> 204.44444 | M6: =MAX(0,ROUNDUP(G6*L6-D6,0)) -> 0 | N6: =COUNTIFS(Temas_TIMSS!$W$5:$W$1264,$A6,Temas_TIMSS!$K$5:$K$1264,"FUERA") -> 30
A7: Ciclo 2°–4° | B7: TIMSS 2023 4.° | C7: Ciencias físicas | D7: =COUNTIFS(Temas_TIMSS!$W$5:$W$1264,$A7,Temas_TIMSS!$M$5:$M$1264,$C7) -> 49 | E7: =COUNTIFS(Temas_TIMSS!$W$5:$W$1264,$A7)-COUNTIFS(Temas_TIMSS!$W$5:$W$1264,$A7,Temas_TIMSS!$K$5:$K$1264,"FUERA")-COUNTIFS(Temas_TIMSS!$W$5:$W$1264,$A7,Temas_TIMSS!$K$5:$K$1264,"PENDIENTE") -> 178 | F7: =IF(E7=0,0,D7/E7) -> 0.2752809 | G7: 0.35 | H7: =G7*E7 -> 62.3 | I7: =H7-D7 -> 13.3 | J7: =(G7-F7)*100 -> 7.4719101 | K7: =IF(ABS(G7-F7)<=$H$2,"En meta",IF(I7>0,"Faltan "&ROUND(I7,0)&" temas","Sobran "&ROUND(-I7,0)&" temas")) -> Faltan 13 temas | L7: =MAX(D6/G6,D7/G7,D8/G8) -> 204.44444 | M7: =MAX(0,ROUNDUP(G7*L7-D7,0)) -> 23 | N7: =COUNTIFS(Temas_TIMSS!$W$5:$W$1264,$A7,Temas_TIMSS!$K$5:$K$1264,"FUERA") -> 30
A8: Ciclo 2°–4° | B8: TIMSS 2023 4.° | C8: Ciencias de la Tierra | D8: =COUNTIFS(Temas_TIMSS!$W$5:$W$1264,$A8,Temas_TIMSS!$M$5:$M$1264,$C8) -> 37 | E8: =COUNTIFS(Temas_TIMSS!$W$5:$W$1264,$A8)-COUNTIFS(Temas_TIMSS!$W$5:$W$1264,$A8,Temas_TIMSS!$K$5:$K$1264,"FUERA")-COUNTIFS(Temas_TIMSS!$W$5:$W$1264,$A8,Temas_TIMSS!$K$5:$K$1264,"PENDIENTE") -> 178 | F8: =IF(E8=0,0,D8/E8) -> 0.20786517 | G8: 0.2 | H8: =G8*E8 -> 35.6 | I8: =H8-D8 -> -1.4 | J8: =(G8-F8)*100 -> -0.78651685 | K8: =IF(ABS(G8-F8)<=$H$2,"En meta",IF(I8>0,"Faltan "&ROUND(I8,0)&" temas","Sobran "&ROUND(-I8,0)&" temas")) -> En meta | L8: =MAX(D6/G6,D7/G7,D8/G8) -> 204.44444 | M8: =MAX(0,ROUNDUP(G8*L8-D8,0)) -> 4 | N8: =COUNTIFS(Temas_TIMSS!$W$5:$W$1264,$A8,Temas_TIMSS!$K$5:$K$1264,"FUERA") -> 30
C9: Total del grupo | D9: =SUM(D6:D8) -> 178 | G9: =SUM(G6:G8) -> 1 | M9: =SUM(M6:M8) -> 27
A11: Ciclo 5°–8° | B11: TIMSS 2023 8.° | C11: Biología | D11: =COUNTIFS(Temas_TIMSS!$W$5:$W$1264,$A11,Temas_TIMSS!$M$5:$M$1264,$C11) -> 111 | E11: =COUNTIFS(Temas_TIMSS!$W$5:$W$1264,$A11)-COUNTIFS(Temas_TIMSS!$W$5:$W$1264,$A11,Temas_TIMSS!$K$5:$K$1264,"FUERA")-COUNTIFS(Temas_TIMSS!$W$5:$W$1264,$A11,Temas_TIMSS!$K$5:$K$1264,"PENDIENTE") -> 302 | F11: =IF(E11=0,0,D11/E11) -> 0.36754967 | G11: 0.35 | H11: =G11*E11 -> 105.7 | I11: =H11-D11 -> -5.3 | J11: =(G11-F11)*100 -> -1.7549669 | K11: =IF(ABS(G11-F11)<=$H$2,"En meta",IF(I11>0,"Faltan "&ROUND(I11,0)&" temas","Sobran "&ROUND(-I11,0)&" temas")) -> En meta | L11: =MAX(D11/G11,D12/G12,D13/G13,D14/G14) -> 317.14286 | M11: =MAX(0,ROUNDUP(G11*L11-D11,0)) -> 0 | N11: =COUNTIFS(Temas_TIMSS!$W$5:$W$1264,$A11,Temas_TIMSS!$K$5:$K$1264,"FUERA") -> 22
A12: Ciclo 5°–8° | B12: TIMSS 2023 8.° | C12: Química | D12: =COUNTIFS(Temas_TIMSS!$W$5:$W$1264,$A12,Temas_TIMSS!$M$5:$M$1264,$C12) -> 58 | E12: =COUNTIFS(Temas_TIMSS!$W$5:$W$1264,$A12)-COUNTIFS(Temas_TIMSS!$W$5:$W$1264,$A12,Temas_TIMSS!$K$5:$K$1264,"FUERA")-COUNTIFS(Temas_TIMSS!$W$5:$W$1264,$A12,Temas_TIMSS!$K$5:$K$1264,"PENDIENTE") -> 302 | F12: =IF(E12=0,0,D12/E12) -> 0.19205298 | G12: 0.2 | H12: =G12*E12 -> 60.4 | I12: =H12-D12 -> 2.4 | J12: =(G12-F12)*100 -> 0.79470199 | K12: =IF(ABS(G12-F12)<=$H$2,"En meta",IF(I12>0,"Faltan "&ROUND(I12,0)&" temas","Sobran "&ROUND(-I12,0)&" temas")) -> En meta | L12: =MAX(D11/G11,D12/G12,D13/G13,D14/G14) -> 317.14286 | M12: =MAX(0,ROUNDUP(G12*L12-D12,0)) -> 6 | N12: =COUNTIFS(Temas_TIMSS!$W$5:$W$1264,$A12,Temas_TIMSS!$K$5:$K$1264,"FUERA") -> 22
A13: Ciclo 5°–8° | B13: TIMSS 2023 8.° | C13: Física | D13: =COUNTIFS(Temas_TIMSS!$W$5:$W$1264,$A13,Temas_TIMSS!$M$5:$M$1264,$C13) -> 79 | E13: =COUNTIFS(Temas_TIMSS!$W$5:$W$1264,$A13)-COUNTIFS(Temas_TIMSS!$W$5:$W$1264,$A13,Temas_TIMSS!$K$5:$K$1264,"FUERA")-COUNTIFS(Temas_TIMSS!$W$5:$W$1264,$A13,Temas_TIMSS!$K$5:$K$1264,"PENDIENTE") -> 302 | F13: =IF(E13=0,0,D13/E13) -> 0.2615894 | G13: 0.25 | H13: =G13*E13 -> 75.5 | I13: =H13-D13 -> -3.5 | J13: =(G13-F13)*100 -> -1.1589404 | K13: =IF(ABS(G13-F13)<=$H$2,"En meta",IF(I13>0,"Faltan "&ROUND(I13,0)&" temas","Sobran "&ROUND(-I13,0)&" temas")) -> En meta | L13: =MAX(D11/G11,D12/G12,D13/G13,D14/G14) -> 317.14286 | M13: =MAX(0,ROUNDUP(G13*L13-D13,0)) -> 1 | N13: =COUNTIFS(Temas_TIMSS!$W$5:$W$1264,$A13,Temas_TIMSS!$K$5:$K$1264,"FUERA") -> 22
A14: Ciclo 5°–8° | B14: TIMSS 2023 8.° | C14: Ciencias de la Tierra | D14: =COUNTIFS(Temas_TIMSS!$W$5:$W$1264,$A14,Temas_TIMSS!$M$5:$M$1264,$C14) -> 54 | E14: =COUNTIFS(Temas_TIMSS!$W$5:$W$1264,$A14)-COUNTIFS(Temas_TIMSS!$W$5:$W$1264,$A14,Temas_TIMSS!$K$5:$K$1264,"FUERA")-COUNTIFS(Temas_TIMSS!$W$5:$W$1264,$A14,Temas_TIMSS!$K$5:$K$1264,"PENDIENTE") -> 302 | F14: =IF(E14=0,0,D14/E14) -> 0.17880795 | G14: 0.2 | H14: =G14*E14 -> 60.4 | I14: =H14-D14 -> 6.4 | J14: =(G14-F14)*100 -> 2.1192053 | K14: =IF(ABS(G14-F14)<=$H$2,"En meta",IF(I14>0,"Faltan "&ROUND(I14,0)&" temas","Sobran "&ROUND(-I14,0)&" temas")) -> En meta | L14: =MAX(D11/G11,D12/G12,D13/G13,D14/G14) -> 317.14286 | M14: =MAX(0,ROUNDUP(G14*L14-D14,0)) -> 10 | N14: =COUNTIFS(Temas_TIMSS!$W$5:$W$1264,$A14,Temas_TIMSS!$K$5:$K$1264,"FUERA") -> 22
C15: Total del grupo | D15: =SUM(D11:D14) -> 302 | G15: =SUM(G11:G14) -> 1 | M15: =SUM(M11:M14) -> 17
A17: 9° | B17: TIMSS 2023 8.° | C17: Biología | D17: =COUNTIFS(Temas_TIMSS!$W$5:$W$1264,$A17,Temas_TIMSS!$M$5:$M$1264,$C17) -> 4 | E17: =COUNTIFS(Temas_TIMSS!$W$5:$W$1264,$A17)-COUNTIFS(Temas_TIMSS!$W$5:$W$1264,$A17,Temas_TIMSS!$K$5:$K$1264,"FUERA")-COUNTIFS(Temas_TIMSS!$W$5:$W$1264,$A17,Temas_TIMSS!$K$5:$K$1264,"PENDIENTE") -> 82 | F17: =IF(E17=0,0,D17/E17) -> 0.048780488 | G17: 0.35 | H17: =G17*E17 -> 28.7 | I17: =H17-D17 -> 24.7 | J17: =(G17-F17)*100 -> 30.121951 | K17: =IF(ABS(G17-F17)<=$H$2,"En meta",IF(I17>0,"Faltan "&ROUND(I17,0)&" temas","Sobran "&ROUND(-I17,0)&" temas")) -> Faltan 25 temas | L17: =MAX(D17/G17,D18/G18,D19/G19,D20/G20) -> 152 | M17: =MAX(0,ROUNDUP(G17*L17-D17,0)) -> 50 | N17: =COUNTIFS(Temas_TIMSS!$W$5:$W$1264,$A17,Temas_TIMSS!$K$5:$K$1264,"FUERA") -> 8
A18: 9° | B18: TIMSS 2023 8.° | C18: Química | D18: =COUNTIFS(Temas_TIMSS!$W$5:$W$1264,$A18,Temas_TIMSS!$M$5:$M$1264,$C18) -> 20 | E18: =COUNTIFS(Temas_TIMSS!$W$5:$W$1264,$A18)-COUNTIFS(Temas_TIMSS!$W$5:$W$1264,$A18,Temas_TIMSS!$K$5:$K$1264,"FUERA")-COUNTIFS(Temas_TIMSS!$W$5:$W$1264,$A18,Temas_TIMSS!$K$5:$K$1264,"PENDIENTE") -> 82 | F18: =IF(E18=0,0,D18/E18) -> 0.24390244 | G18: 0.2 | H18: =G18*E18 -> 16.4 | I18: =H18-D18 -> -3.6 | J18: =(G18-F18)*100 -> -4.3902439 | K18: =IF(ABS(G18-F18)<=$H$2,"En meta",IF(I18>0,"Faltan "&ROUND(I18,0)&" temas","Sobran "&ROUND(-I18,0)&" temas")) -> En meta | L18: =MAX(D17/G17,D18/G18,D19/G19,D20/G20) -> 152 | M18: =MAX(0,ROUNDUP(G18*L18-D18,0)) -> 11 | N18: =COUNTIFS(Temas_TIMSS!$W$5:$W$1264,$A18,Temas_TIMSS!$K$5:$K$1264,"FUERA") -> 8
A19: 9° | B19: TIMSS 2023 8.° | C19: Física | D19: =COUNTIFS(Temas_TIMSS!$W$5:$W$1264,$A19,Temas_TIMSS!$M$5:$M$1264,$C19) -> 38 | E19: =COUNTIFS(Temas_TIMSS!$W$5:$W$1264,$A19)-COUNTIFS(Temas_TIMSS!$W$5:$W$1264,$A19,Temas_TIMSS!$K$5:$K$1264,"FUERA")-COUNTIFS(Temas_TIMSS!$W$5:$W$1264,$A19,Temas_TIMSS!$K$5:$K$1264,"PENDIENTE") -> 82 | F19: =IF(E19=0,0,D19/E19) -> 0.46341463 | G19: 0.25 | H19: =G19*E19 -> 20.5 | I19: =H19-D19 -> -17.5 | J19: =(G19-F19)*100 -> -21.341463 | K19: =IF(ABS(G19-F19)<=$H$2,"En meta",IF(I19>0,"Faltan "&ROUND(I19,0)&" temas","Sobran "&ROUND(-I19,0)&" temas")) -> Sobran 18 temas | L19: =MAX(D17/G17,D18/G18,D19/G19,D20/G20) -> 152 | M19: =MAX(0,ROUNDUP(G19*L19-D19,0)) -> 0 | N19: =COUNTIFS(Temas_TIMSS!$W$5:$W$1264,$A19,Temas_TIMSS!$K$5:$K$1264,"FUERA") -> 8
A20: 9° | B20: TIMSS 2023 8.° | C20: Ciencias de la Tierra | D20: =COUNTIFS(Temas_TIMSS!$W$5:$W$1264,$A20,Temas_TIMSS!$M$5:$M$1264,$C20) -> 20 | E20: =COUNTIFS(Temas_TIMSS!$W$5:$W$1264,$A20)-COUNTIFS(Temas_TIMSS!$W$5:$W$1264,$A20,Temas_TIMSS!$K$5:$K$1264,"FUERA")-COUNTIFS(Temas_TIMSS!$W$5:$W$1264,$A20,Temas_TIMSS!$K$5:$K$1264,"PENDIENTE") -> 82 | F20: =IF(E20=0,0,D20/E20) -> 0.24390244 | G20: 0.2 | H20: =G20*E20 -> 16.4 | I20: =H20-D20 -> -3.6 | J20: =(G20-F20)*100 -> -4.3902439 | K20: =IF(ABS(G20-F20)<=$H$2,"En meta",IF(I20>0,"Faltan "&ROUND(I20,0)&" temas","Sobran "&ROUND(-I20,0)&" temas")) -> En meta | L20: =MAX(D17/G17,D18/G18,D19/G19,D20/G20) -> 152 | M20: =MAX(0,ROUNDUP(G20*L20-D20,0)) -> 11 | N20: =COUNTIFS(Temas_TIMSS!$W$5:$W$1264,$A20,Temas_TIMSS!$K$5:$K$1264,"FUERA") -> 8
C21: Total del grupo | D21: =SUM(D17:D20) -> 82 | G21: =SUM(G17:G20) -> 1 | M21: =SUM(M17:M20) -> 72
A23: Física 10°–11° | B23: TIMSS Advanced 2015 Física | C23: Mecánica y termodinámica | D23: =COUNTIFS(Temas_TIMSS!$W$5:$W$1264,$A23,Temas_TIMSS!$M$5:$M$1264,$C23) -> 71 | E23: =COUNTIFS(Temas_TIMSS!$W$5:$W$1264,$A23)-COUNTIFS(Temas_TIMSS!$W$5:$W$1264,$A23,Temas_TIMSS!$K$5:$K$1264,"FUERA")-COUNTIFS(Temas_TIMSS!$W$5:$W$1264,$A23,Temas_TIMSS!$K$5:$K$1264,"PENDIENTE") -> 199 | F23: =IF(E23=0,0,D23/E23) -> 0.35678392 | G23: 0.4 | H23: =G23*E23 -> 79.6 | I23: =H23-D23 -> 8.6 | J23: =(G23-F23)*100 -> 4.321608 | K23: =IF(ABS(G23-F23)<=$H$2,"En meta",IF(I23>0,"Faltan "&ROUND(I23,0)&" temas","Sobran "&ROUND(-I23,0)&" temas")) -> En meta | L23: =MAX(D23/G23,D24/G24,D25/G25) -> 242.85714 | M23: =MAX(0,ROUNDUP(G23*L23-D23,0)) -> 27 | N23: =COUNTIFS(Temas_TIMSS!$W$5:$W$1264,$A23,Temas_TIMSS!$K$5:$K$1264,"FUERA") -> 68
A24: Física 10°–11° | B24: TIMSS Advanced 2015 Física | C24: Electricidad y magnetismo | D24: =COUNTIFS(Temas_TIMSS!$W$5:$W$1264,$A24,Temas_TIMSS!$M$5:$M$1264,$C24) -> 43 | E24: =COUNTIFS(Temas_TIMSS!$W$5:$W$1264,$A24)-COUNTIFS(Temas_TIMSS!$W$5:$W$1264,$A24,Temas_TIMSS!$K$5:$K$1264,"FUERA")-COUNTIFS(Temas_TIMSS!$W$5:$W$1264,$A24,Temas_TIMSS!$K$5:$K$1264,"PENDIENTE") -> 199 | F24: =IF(E24=0,0,D24/E24) -> 0.2160804 | G24: 0.25 | H24: =G24*E24 -> 49.75 | I24: =H24-D24 -> 6.75 | J24: =(G24-F24)*100 -> 3.3919598 | K24: =IF(ABS(G24-F24)<=$H$2,"En meta",IF(I24>0,"Faltan "&ROUND(I24,0)&" temas","Sobran "&ROUND(-I24,0)&" temas")) -> En meta | L24: =MAX(D23/G23,D24/G24,D25/G25) -> 242.85714 | M24: =MAX(0,ROUNDUP(G24*L24-D24,0)) -> 18 | N24: =COUNTIFS(Temas_TIMSS!$W$5:$W$1264,$A24,Temas_TIMSS!$K$5:$K$1264,"FUERA") -> 68
A25: Física 10°–11° | B25: TIMSS Advanced 2015 Física | C25: Ondas y física atómica/nuclear | D25: =COUNTIFS(Temas_TIMSS!$W$5:$W$1264,$A25,Temas_TIMSS!$M$5:$M$1264,$C25) -> 85 | E25: =COUNTIFS(Temas_TIMSS!$W$5:$W$1264,$A25)-COUNTIFS(Temas_TIMSS!$W$5:$W$1264,$A25,Temas_TIMSS!$K$5:$K$1264,"FUERA")-COUNTIFS(Temas_TIMSS!$W$5:$W$1264,$A25,Temas_TIMSS!$K$5:$K$1264,"PENDIENTE") -> 199 | F25: =IF(E25=0,0,D25/E25) -> 0.42713568 | G25: 0.35 | H25: =G25*E25 -> 69.65 | I25: =H25-D25 -> -15.35 | J25: =(G25-F25)*100 -> -7.7135678 | K25: =IF(ABS(G25-F25)<=$H$2,"En meta",IF(I25>0,"Faltan "&ROUND(I25,0)&" temas","Sobran "&ROUND(-I25,0)&" temas")) -> Sobran 15 temas | L25: =MAX(D23/G23,D24/G24,D25/G25) -> 242.85714 | M25: =MAX(0,ROUNDUP(G25*L25-D25,0)) -> 0 | N25: =COUNTIFS(Temas_TIMSS!$W$5:$W$1264,$A25,Temas_TIMSS!$K$5:$K$1264,"FUERA") -> 68
C26: Total del grupo | D26: =SUM(D23:D25) -> 199 | G26: =SUM(G23:G25) -> 1 | M26: =SUM(M23:M25) -> 45

Sheet Balance_grado
A1: Balance de contenidos por grado frente a las metas de TIMSS
A2: Tolerancia para considerar «en meta» (± puntos porcentuales): | H2: 0.05
A3: Cómo leerlo: «% actual» = temas del dominio ÷ temas evaluables del grado (se excluyen los «fuera del marco»). «Brecha (temas)» = meta × evaluables − actuales: positivo = faltan temas en ese dominio si se redistribuye la misma carga; negativo = sobran. «Temas a AGREGAR» = cuántos temas habría que sumar a cada dominio para cumplir todas las metas SIN quitar ninguno (la escala la fija el dominio más sobrerrepresentado). Ojo: TIMSS fija pesos para la prueba acumulada (4.° y 8.°); aplicarlos a cada grado es una aproximación. La hoja Balance_ciclo hace la comparación acumulada.
A5: Grupo | B5: Marco de referencia | C5: Dominio | D5: Temas actuales en el dominio | E5: Temas evaluables del grupo (sin «fuera») | F5: % actual | G5: Meta TIMSS (%) | H5: Temas esperados según meta | I5: Brecha (temas): + faltan / − sobran | J5: Brecha (pp) | K5: Estado | L5: Escala para cumplir sin quitar temas (total evaluables) | M5: Temas a AGREGAR para llegar a la meta sin quitar | N5: Temas «fuera del marco» del grupo
A6: 2° | B6: TIMSS 2023 4.° | C6: Ciencias de la vida | D6: =COUNTIFS(Temas_TIMSS!$V$5:$V$1264,$A6,Temas_TIMSS!$M$5:$M$1264,$C6) -> 24 | E6: =COUNTIFS(Temas_TIMSS!$V$5:$V$1264,$A6)-COUNTIFS(Temas_TIMSS!$V$5:$V$1264,$A6,Temas_TIMSS!$K$5:$K$1264,"FUERA")-COUNTIFS(Temas_TIMSS!$V$5:$V$1264,$A6,Temas_TIMSS!$K$5:$K$1264,"PENDIENTE") -> 57 | F6: =IF(E6=0,0,D6/E6) -> 0.42105263 | G6: 0.45 | H6: =G6*E6 -> 25.65 | I6: =H6-D6 -> 1.65 | J6: =(G6-F6)*100 -> 2.8947368 | K6: =IF(ABS(G6-F6)<=$H$2,"En meta",IF(I6>0,"Faltan "&ROUND(I6,0)&" temas","Sobran "&ROUND(-I6,0)&" temas")) -> En meta | L6: =MAX(D6/G6,D7/G7,D8/G8) -> 65.714286 | M6: =MAX(0,ROUNDUP(G6*L6-D6,0)) -> 6 | N6: =COUNTIFS(Temas_TIMSS!$V$5:$V$1264,$A6,Temas_TIMSS!$K$5:$K$1264,"FUERA") -> 13
A7: 2° | B7: TIMSS 2023 4.° | C7: Ciencias físicas | D7: =COUNTIFS(Temas_TIMSS!$V$5:$V$1264,$A7,Temas_TIMSS!$M$5:$M$1264,$C7) -> 23 | E7: =COUNTIFS(Temas_TIMSS!$V$5:$V$1264,$A7)-COUNTIFS(Temas_TIMSS!$V$5:$V$1264,$A7,Temas_TIMSS!$K$5:$K$1264,"FUERA")-COUNTIFS(Temas_TIMSS!$V$5:$V$1264,$A7,Temas_TIMSS!$K$5:$K$1264,"PENDIENTE") -> 57 | F7: =IF(E7=0,0,D7/E7) -> 0.40350877 | G7: 0.35 | H7: =G7*E7 -> 19.95 | I7: =H7-D7 -> -3.05 | J7: =(G7-F7)*100 -> -5.3508772 | K7: =IF(ABS(G7-F7)<=$H$2,"En meta",IF(I7>0,"Faltan "&ROUND(I7,0)&" temas","Sobran "&ROUND(-I7,0)&" temas")) -> Sobran 3 temas | L7: =MAX(D6/G6,D7/G7,D8/G8) -> 65.714286 | M7: =MAX(0,ROUNDUP(G7*L7-D7,0)) -> 0 | N7: =COUNTIFS(Temas_TIMSS!$V$5:$V$1264,$A7,Temas_TIMSS!$K$5:$K$1264,"FUERA") -> 13
A8: 2° | B8: TIMSS 2023 4.° | C8: Ciencias de la Tierra | D8: =COUNTIFS(Temas_TIMSS!$V$5:$V$1264,$A8,Temas_TIMSS!$M$5:$M$1264,$C8) -> 10 | E8: =COUNTIFS(Temas_TIMSS!$V$5:$V$1264,$A8)-COUNTIFS(Temas_TIMSS!$V$5:$V$1264,$A8,Temas_TIMSS!$K$5:$K$1264,"FUERA")-COUNTIFS(Temas_TIMSS!$V$5:$V$1264,$A8,Temas_TIMSS!$K$5:$K$1264,"PENDIENTE") -> 57 | F8: =IF(E8=0,0,D8/E8) -> 0.1754386 | G8: 0.2 | H8: =G8*E8 -> 11.4 | I8: =H8-D8 -> 1.4 | J8: =(G8-F8)*100 -> 2.4561404 | K8: =IF(ABS(G8-F8)<=$H$2,"En meta",IF(I8>0,"Faltan "&ROUND(I8,0)&" temas","Sobran "&ROUND(-I8,0)&" temas")) -> En meta | L8: =MAX(D6/G6,D7/G7,D8/G8) -> 65.714286 | M8: =MAX(0,ROUNDUP(G8*L8-D8,0)) -> 4 | N8: =COUNTIFS(Temas_TIMSS!$V$5:$V$1264,$A8,Temas_TIMSS!$K$5:$K$1264,"FUERA") -> 13
C9: Total del grupo | D9: =SUM(D6:D8) -> 57 | G9: =SUM(G6:G8) -> 1 | M9: =SUM(M6:M8) -> 10
A11: 3° | B11: TIMSS 2023 4.° | C11: Ciencias de la vida | D11: =COUNTIFS(Temas_TIMSS!$V$5:$V$1264,$A11,Temas_TIMSS!$M$5:$M$1264,$C11) -> 31 | E11: =COUNTIFS(Temas_TIMSS!$V$5:$V$1264,$A11)-COUNTIFS(Temas_TIMSS!$V$5:$V$1264,$A11,Temas_TIMSS!$K$5:$K$1264,"FUERA")-COUNTIFS(Temas_TIMSS!$V$5:$V$1264,$A11,Temas_TIMSS!$K$5:$K$1264,"PENDIENTE") -> 57 | F11: =IF(E11=0,0,D11/E11) -> 0.54385965 | G11: 0.45 | H11: =G11*E11 -> 25.65 | I11: =H11-D11 -> -5.35 | J11: =(G11-F11)*100 -> -9.3859649 | K11: =IF(ABS(G11-F11)<=$H$2,"En meta",IF(I11>0,"Faltan "&ROUND(I11,0)&" temas","Sobran "&ROUND(-I11,0)&" temas")) -> Sobran 5 temas | L11: =MAX(D11/G11,D12/G12,D13/G13) -> 68.888889 | M11: =MAX(0,ROUNDUP(G11*L11-D11,0)) -> 0 | N11: =COUNTIFS(Temas_TIMSS!$V$5:$V$1264,$A11,Temas_TIMSS!$K$5:$K$1264,"FUERA") -> 9
A12: 3° | B12: TIMSS 2023 4.° | C12: Ciencias físicas | D12: =COUNTIFS(Temas_TIMSS!$V$5:$V$1264,$A12,Temas_TIMSS!$M$5:$M$1264,$C12) -> 17 | E12: =COUNTIFS(Temas_TIMSS!$V$5:$V$1264,$A12)-COUNTIFS(Temas_TIMSS!$V$5:$V$1264,$A12,Temas_TIMSS!$K$5:$K$1264,"FUERA")-COUNTIFS(Temas_TIMSS!$V$5:$V$1264,$A12,Temas_TIMSS!$K$5:$K$1264,"PENDIENTE") -> 57 | F12: =IF(E12=0,0,D12/E12) -> 0.29824561 | G12: 0.35 | H12: =G12*E12 -> 19.95 | I12: =H12-D12 -> 2.95 | J12: =(G12-F12)*100 -> 5.1754386 | K12: =IF(ABS(G12-F12)<=$H$2,"En meta",IF(I12>0,"Faltan "&ROUND(I12,0)&" temas","Sobran "&ROUND(-I12,0)&" temas")) -> Faltan 3 temas | L12: =MAX(D11/G11,D12/G12,D13/G13) -> 68.888889 | M12: =MAX(0,ROUNDUP(G12*L12-D12,0)) -> 8 | N12: =COUNTIFS(Temas_TIMSS!$V$5:$V$1264,$A12,Temas_TIMSS!$K$5:$K$1264,"FUERA") -> 9
A13: 3° | B13: TIMSS 2023 4.° | C13: Ciencias de la Tierra | D13: =COUNTIFS(Temas_TIMSS!$V$5:$V$1264,$A13,Temas_TIMSS!$M$5:$M$1264,$C13) -> 9 | E13: =COUNTIFS(Temas_TIMSS!$V$5:$V$1264,$A13)-COUNTIFS(Temas_TIMSS!$V$5:$V$1264,$A13,Temas_TIMSS!$K$5:$K$1264,"FUERA")-COUNTIFS(Temas_TIMSS!$V$5:$V$1264,$A13,Temas_TIMSS!$K$5:$K$1264,"PENDIENTE") -> 57 | F13: =IF(E13=0,0,D13/E13) -> 0.15789474 | G13: 0.2 | H13: =G13*E13 -> 11.4 | I13: =H13-D13 -> 2.4 | J13: =(G13-F13)*100 -> 4.2105263 | K13: =IF(ABS(G13-F13)<=$H$2,"En meta",IF(I13>0,"Faltan "&ROUND(I13,0)&" temas","Sobran "&ROUND(-I13,0)&" temas")) -> En meta | L13: =MAX(D11/G11,D12/G12,D13/G13) -> 68.888889 | M13: =MAX(0,ROUNDUP(G13*L13-D13,0)) -> 5 | N13: =COUNTIFS(Temas_TIMSS!$V$5:$V$1264,$A13,Temas_TIMSS!$K$5:$K$1264,"FUERA") -> 9
C14: Total del grupo | D14: =SUM(D11:D13) -> 57 | G14: =SUM(G11:G13) -> 1 | M14: =SUM(M11:M13) -> 13
A16: 4° | B16: TIMSS 2023 4.° | C16: Ciencias de la vida | D16: =COUNTIFS(Temas_TIMSS!$V$5:$V$1264,$A16,Temas_TIMSS!$M$5:$M$1264,$C16) -> 37 | E16: =COUNTIFS(Temas_TIMSS!$V$5:$V$1264,$A16)-COUNTIFS(Temas_TIMSS!$V$5:$V$1264,$A16,Temas_TIMSS!$K$5:$K$1264,"FUERA")-COUNTIFS(Temas_TIMSS!$V$5:$V$1264,$A16,Temas_TIMSS!$K$5:$K$1264,"PENDIENTE") -> 64 | F16: =IF(E16=0,0,D16/E16) -> 0.578125 | G16: 0.45 | H16: =G16*E16 -> 28.8 | I16: =H16-D16 -> -8.2 | J16: =(G16-F16)*100 -> -12.8125 | K16: =IF(ABS(G16-F16)<=$H$2,"En meta",IF(I16>0,"Faltan "&ROUND(I16,0)&" temas","Sobran "&ROUND(-I16,0)&" temas")) -> Sobran 8 temas | L16: =MAX(D16/G16,D17/G17,D18/G18) -> 90 | M16: =MAX(0,ROUNDUP(G16*L16-D16,0)) -> 4 | N16: =COUNTIFS(Temas_TIMSS!$V$5:$V$1264,$A16,Temas_TIMSS!$K$5:$K$1264,"FUERA") -> 8
A17: 4° | B17: TIMSS 2023 4.° | C17: Ciencias físicas | D17: =COUNTIFS(Temas_TIMSS!$V$5:$V$1264,$A17,Temas_TIMSS!$M$5:$M$1264,$C17) -> 9 | E17: =COUNTIFS(Temas_TIMSS!$V$5:$V$1264,$A17)-COUNTIFS(Temas_TIMSS!$V$5:$V$1264,$A17,Temas_TIMSS!$K$5:$K$1264,"FUERA")-COUNTIFS(Temas_TIMSS!$V$5:$V$1264,$A17,Temas_TIMSS!$K$5:$K$1264,"PENDIENTE") -> 64 | F17: =IF(E17=0,0,D17/E17) -> 0.140625 | G17: 0.35 | H17: =G17*E17 -> 22.4 | I17: =H17-D17 -> 13.4 | J17: =(G17-F17)*100 -> 20.9375 | K17: =IF(ABS(G17-F17)<=$H$2,"En meta",IF(I17>0,"Faltan "&ROUND(I17,0)&" temas","Sobran "&ROUND(-I17,0)&" temas")) -> Faltan 13 temas | L17: =MAX(D16/G16,D17/G17,D18/G18) -> 90 | M17: =MAX(0,ROUNDUP(G17*L17-D17,0)) -> 23 | N17: =COUNTIFS(Temas_TIMSS!$V$5:$V$1264,$A17,Temas_TIMSS!$K$5:$K$1264,"FUERA") -> 8
A18: 4° | B18: TIMSS 2023 4.° | C18: Ciencias de la Tierra | D18: =COUNTIFS(Temas_TIMSS!$V$5:$V$1264,$A18,Temas_TIMSS!$M$5:$M$1264,$C18) -> 18 | E18: =COUNTIFS(Temas_TIMSS!$V$5:$V$1264,$A18)-COUNTIFS(Temas_TIMSS!$V$5:$V$1264,$A18,Temas_TIMSS!$K$5:$K$1264,"FUERA")-COUNTIFS(Temas_TIMSS!$V$5:$V$1264,$A18,Temas_TIMSS!$K$5:$K$1264,"PENDIENTE") -> 64 | F18: =IF(E18=0,0,D18/E18) -> 0.28125 | G18: 0.2 | H18: =G18*E18 -> 12.8 | I18: =H18-D18 -> -5.2 | J18: =(G18-F18)*100 -> -8.125 | K18: =IF(ABS(G18-F18)<=$H$2,"En meta",IF(I18>0,"Faltan "&ROUND(I18,0)&" temas","Sobran "&ROUND(-I18,0)&" temas")) -> Sobran 5 temas | L18: =MAX(D16/G16,D17/G17,D18/G18) -> 90 | M18: =MAX(0,ROUNDUP(G18*L18-D18,0)) -> 0 | N18: =COUNTIFS(Temas_TIMSS!$V$5:$V$1264,$A18,Temas_TIMSS!$K$5:$K$1264,"FUERA") -> 8
C19: Total del grupo | D19: =SUM(D16:D18) -> 64 | G19: =SUM(G16:G18) -> 1 | M19: =SUM(M16:M18) -> 27
A21: 5° | B21: TIMSS 2023 8.° | C21: Biología | D21: =COUNTIFS(Temas_TIMSS!$V$5:$V$1264,$A21,Temas_TIMSS!$M$5:$M$1264,$C21) -> 1 | E21: =COUNTIFS(Temas_TIMSS!$V$5:$V$1264,$A21)-COUNTIFS(Temas_TIMSS!$V$5:$V$1264,$A21,Temas_TIMSS!$K$5:$K$1264,"FUERA")-COUNTIFS(Temas_TIMSS!$V$5:$V$1264,$A21,Temas_TIMSS!$K$5:$K$1264,"PENDIENTE") -> 58 | F21: =IF(E21=0,0,D21/E21) -> 0.017241379 | G21: 0.35 | H21: =G21*E21 -> 20.3 | I21: =H21-D21 -> 19.3 | J21: =(G21-F21)*100 -> 33.275862 | K21: =IF(ABS(G21-F21)<=$H$2,"En meta",IF(I21>0,"Faltan "&ROUND(I21,0)&" temas","Sobran "&ROUND(-I21,0)&" temas")) -> Faltan 19 temas | L21: =MAX(D21/G21,D22/G22,D23/G23,D24/G24) -> 120 | M21: =MAX(0,ROUNDUP(G21*L21-D21,0)) -> 41 | N21: =COUNTIFS(Temas_TIMSS!$V$5:$V$1264,$A21,Temas_TIMSS!$K$5:$K$1264,"FUERA") -> 14
A22: 5° | B22: TIMSS 2023 8.° | C22: Química | D22: =COUNTIFS(Temas_TIMSS!$V$5:$V$1264,$A22,Temas_TIMSS!$M$5:$M$1264,$C22) -> 18 | E22: =COUNTIFS(Temas_TIMSS!$V$5:$V$1264,$A22)-COUNTIFS(Temas_TIMSS!$V$5:$V$1264,$A22,Temas_TIMSS!$K$5:$K$1264,"FUERA")-COUNTIFS(Temas_TIMSS!$V$5:$V$1264,$A22,Temas_TIMSS!$K$5:$K$1264,"PENDIENTE") -> 58 | F22: =IF(E22=0,0,D22/E22) -> 0.31034483 | G22: 0.2 | H22: =G22*E22 -> 11.6 | I22: =H22-D22 -> -6.4 | J22: =(G22-F22)*100 -> -11.034483 | K22: =IF(ABS(G22-F22)<=$H$2,"En meta",IF(I22>0,"Faltan "&ROUND(I22,0)&" temas","Sobran "&ROUND(-I22,0)&" temas")) -> Sobran 6 temas | L22: =MAX(D21/G21,D22/G22,D23/G23,D24/G24) -> 120 | M22: =MAX(0,ROUNDUP(G22*L22-D22,0)) -> 6 | N22: =COUNTIFS(Temas_TIMSS!$V$5:$V$1264,$A22,Temas_TIMSS!$K$5:$K$1264,"FUERA") -> 14
A23: 5° | B23: TIMSS 2023 8.° | C23: Física | D23: =COUNTIFS(Temas_TIMSS!$V$5:$V$1264,$A23,Temas_TIMSS!$M$5:$M$1264,$C23) -> 15 | E23: =COUNTIFS(Temas_TIMSS!$V$5:$V$1264,$A23)-COUNTIFS(Temas_TIMSS!$V$5:$V$1264,$A23,Temas_TIMSS!$K$5:$K$1264,"FUERA")-COUNTIFS(Temas_TIMSS!$V$5:$V$1264,$A23,Temas_TIMSS!$K$5:$K$1264,"PENDIENTE") -> 58 | F23: =IF(E23=0,0,D23/E23) -> 0.25862069 | G23: 0.25 | H23: =G23*E23 -> 14.5 | I23: =H23-D23 -> -0.5 | J23: =(G23-F23)*100 -> -0.86206897 | K23: =IF(ABS(G23-F23)<=$H$2,"En meta",IF(I23>0,"Faltan "&ROUND(I23,0)&" temas","Sobran "&ROUND(-I23,0)&" temas")) -> En meta | L23: =MAX(D21/G21,D22/G22,D23/G23,D24/G24) -> 120 | M23: =MAX(0,ROUNDUP(G23*L23-D23,0)) -> 15 | N23: =COUNTIFS(Temas_TIMSS!$V$5:$V$1264,$A23,Temas_TIMSS!$K$5:$K$1264,"FUERA") -> 14
A24: 5° | B24: TIMSS 2023 8.° | C24: Ciencias de la Tierra | D24: =COUNTIFS(Temas_TIMSS!$V$5:$V$1264,$A24,Temas_TIMSS!$M$5:$M$1264,$C24) -> 24 | E24: =COUNTIFS(Temas_TIMSS!$V$5:$V$1264,$A24)-COUNTIFS(Temas_TIMSS!$V$5:$V$1264,$A24,Temas_TIMSS!$K$5:$K$1264,"FUERA")-COUNTIFS(Temas_TIMSS!$V$5:$V$1264,$A24,Temas_TIMSS!$K$5:$K$1264,"PENDIENTE") -> 58 | F24: =IF(E24=0,0,D24/E24) -> 0.4137931 | G24: 0.2 | H24: =G24*E24 -> 11.6 | I24: =H24-D24 -> -12.4 | J24: =(G24-F24)*100 -> -21.37931 | K24: =IF(ABS(G24-F24)<=$H$2,"En meta",IF(I24>0,"Faltan "&ROUND(I24,0)&" temas","Sobran "&ROUND(-I24,0)&" temas")) -> Sobran 12 temas | L24: =MAX(D21/G21,D22/G22,D23/G23,D24/G24) -> 120 | M24: =MAX(0,ROUNDUP(G24*L24-D24,0)) -> 0 | N24: =COUNTIFS(Temas_TIMSS!$V$5:$V$1264,$A24,Temas_TIMSS!$K$5:$K$1264,"FUERA") -> 14
C25: Total del grupo | D25: =SUM(D21:D24) -> 58 | G25: =SUM(G21:G24) -> 1 | M25: =SUM(M21:M24) -> 62
A27: 6° | B27: TIMSS 2023 8.° | C27: Biología | D27: =COUNTIFS(Temas_TIMSS!$V$5:$V$1264,$A27,Temas_TIMSS!$M$5:$M$1264,$C27) -> 34 | E27: =COUNTIFS(Temas_TIMSS!$V$5:$V$1264,$A27)-COUNTIFS(Temas_TIMSS!$V$5:$V$1264,$A27,Temas_TIMSS!$K$5:$K$1264,"FUERA")-COUNTIFS(Temas_TIMSS!$V$5:$V$1264,$A27,Temas_TIMSS!$K$5:$K$1264,"PENDIENTE") -> 68 | F27: =IF(E27=0,0,D27/E27) -> 0.5 | G27: 0.35 | H27: =G27*E27 -> 23.8 | I27: =H27-D27 -> -10.2 | J27: =(G27-F27)*100 -> -15 | K27: =IF(ABS(G27-F27)<=$H$2,"En meta",IF(I27>0,"Faltan "&ROUND(I27,0)&" temas","Sobran "&ROUND(-I27,0)&" temas")) -> Sobran 10 temas | L27: =MAX(D27/G27,D28/G28,D29/G29,D30/G30) -> 104 | M27: =MAX(0,ROUNDUP(G27*L27-D27,0)) -> 3 | N27: =COUNTIFS(Temas_TIMSS!$V$5:$V$1264,$A27,Temas_TIMSS!$K$5:$K$1264,"FUERA") -> 0
A28: 6° | B28: TIMSS 2023 8.° | C28: Química | D28: =COUNTIFS(Temas_TIMSS!$V$5:$V$1264,$A28,Temas_TIMSS!$M$5:$M$1264,$C28) -> 8 | E28: =COUNTIFS(Temas_TIMSS!$V$5:$V$1264,$A28)-COUNTIFS(Temas_TIMSS!$V$5:$V$1264,$A28,Temas_TIMSS!$K$5:$K$1264,"FUERA")-COUNTIFS(Temas_TIMSS!$V$5:$V$1264,$A28,Temas_TIMSS!$K$5:$K$1264,"PENDIENTE") -> 68 | F28: =IF(E28=0,0,D28/E28) -> 0.11764706 | G28: 0.2 | H28: =G28*E28 -> 13.6 | I28: =H28-D28 -> 5.6 | J28: =(G28-F28)*100 -> 8.2352941 | K28: =IF(ABS(G28-F28)<=$H$2,"En meta",IF(I28>0,"Faltan "&ROUND(I28,0)&" temas","Sobran "&ROUND(-I28,0)&" temas")) -> Faltan 6 temas | L28: =MAX(D27/G27,D28/G28,D29/G29,D30/G30) -> 104 | M28: =MAX(0,ROUNDUP(G28*L28-D28,0)) -> 13 | N28: =COUNTIFS(Temas_TIMSS!$V$5:$V$1264,$A28,Temas_TIMSS!$K$5:$K$1264,"FUERA") -> 0
A29: 6° | B29: TIMSS 2023 8.° | C29: Física | D29: =COUNTIFS(Temas_TIMSS!$V$5:$V$1264,$A29,Temas_TIMSS!$M$5:$M$1264,$C29) -> 26 | E29: =COUNTIFS(Temas_TIMSS!$V$5:$V$1264,$A29)-COUNTIFS(Temas_TIMSS!$V$5:$V$1264,$A29,Temas_TIMSS!$K$5:$K$1264,"FUERA")-COUNTIFS(Temas_TIMSS!$V$5:$V$1264,$A29,Temas_TIMSS!$K$5:$K$1264,"PENDIENTE") -> 68 | F29: =IF(E29=0,0,D29/E29) -> 0.38235294 | G29: 0.25 | H29: =G29*E29 -> 17 | I29: =H29-D29 -> -9 | J29: =(G29-F29)*100 -> -13.235294 | K29: =IF(ABS(G29-F29)<=$H$2,"En meta",IF(I29>0,"Faltan "&ROUND(I29,0)&" temas","Sobran "&ROUND(-I29,0)&" temas")) -> Sobran 9 temas | L29: =MAX(D27/G27,D28/G28,D29/G29,D30/G30) -> 104 | M29: =MAX(0,ROUNDUP(G29*L29-D29,0)) -> 0 | N29: =COUNTIFS(Temas_TIMSS!$V$5:$V$1264,$A29,Temas_TIMSS!$K$5:$K$1264,"FUERA") -> 0
A30: 6° | B30: TIMSS 2023 8.° | C30: Ciencias de la Tierra | D30: =COUNTIFS(Temas_TIMSS!$V$5:$V$1264,$A30,Temas_TIMSS!$M$5:$M$1264,$C30) -> 0 | E30: =COUNTIFS(Temas_TIMSS!$V$5:$V$1264,$A30)-COUNTIFS(Temas_TIMSS!$V$5:$V$1264,$A30,Temas_TIMSS!$K$5:$K$1264,"FUERA")-COUNTIFS(Temas_TIMSS!$V$5:$V$1264,$A30,Temas_TIMSS!$K$5:$K$1264,"PENDIENTE") -> 68 | F30: =IF(E30=0,0,D30/E30) -> 0 | G30: 0.2 | H30: =G30*E30 -> 13.6 | I30: =H30-D30 -> 13.6 | J30: =(G30-F30)*100 -> 20 | K30: =IF(ABS(G30-F30)<=$H$2,"En meta",IF(I30>0,"Faltan "&ROUND(I30,0)&" temas","Sobran "&ROUND(-I30,0)&" temas")) -> Faltan 14 temas | L30: =MAX(D27/G27,D28/G28,D29/G29,D30/G30) -> 104 | M30: =MAX(0,ROUNDUP(G30*L30-D30,0)) -> 21 | N30: =COUNTIFS(Temas_TIMSS!$V$5:$V$1264,$A30,Temas_TIMSS!$K$5:$K$1264,"FUERA") -> 0
C31: Total del grupo | D31: =SUM(D27:D30) -> 68 | G31: =SUM(G27:G30) -> 1 | M31: =SUM(M27:M30) -> 37
A33: 7° | B33: TIMSS 2023 8.° | C33: Biología | D33: =COUNTIFS(Temas_TIMSS!$V$5:$V$1264,$A33,Temas_TIMSS!$M$5:$M$1264,$C33) -> 48 | E33: =COUNTIFS(Temas_TIMSS!$V$5:$V$1264,$A33)-COUNTIFS(Temas_TIMSS!$V$5:$V$1264,$A33,Temas_TIMSS!$K$5:$K$1264,"FUERA")-COUNTIFS(Temas_TIMSS!$V$5:$V$1264,$A33,Temas_TIMSS!$K$5:$K$1264,"PENDIENTE") -> 85 | F33: =IF(E33=0,0,D33/E33) -> 0.56470588 | G33: 0.35 | H33: =G33*E33 -> 29.75 | I33: =H33-D33 -> -18.25 | J33: =(G33-F33)*100 -> -21.470588 | K33: =IF(ABS(G33-F33)<=$H$2,"En meta",IF(I33>0,"Faltan "&ROUND(I33,0)&" temas","Sobran "&ROUND(-I33,0)&" temas")) -> Sobran 18 temas | L33: =MAX(D33/G33,D34/G34,D35/G35,D36/G36) -> 137.14286 | M33: =MAX(0,ROUNDUP(G33*L33-D33,0)) -> 0 | N33: =COUNTIFS(Temas_TIMSS!$V$5:$V$1264,$A33,Temas_TIMSS!$K$5:$K$1264,"FUERA") -> 6
A34: 7° | B34: TIMSS 2023 8.° | C34: Química | D34: =COUNTIFS(Temas_TIMSS!$V$5:$V$1264,$A34,Temas_TIMSS!$M$5:$M$1264,$C34) -> 8 | E34: =COUNTIFS(Temas_TIMSS!$V$5:$V$1264,$A34)-COUNTIFS(Temas_TIMSS!$V$5:$V$1264,$A34,Temas_TIMSS!$K$5:$K$1264,"FUERA")-COUNTIFS(Temas_TIMSS!$V$5:$V$1264,$A34,Temas_TIMSS!$K$5:$K$1264,"PENDIENTE") -> 85 | F34: =IF(E34=0,0,D34/E34) -> 0.094117647 | G34: 0.2 | H34: =G34*E34 -> 17 | I34: =H34-D34 -> 9 | J34: =(G34-F34)*100 -> 10.588235 | K34: =IF(ABS(G34-F34)<=$H$2,"En meta",IF(I34>0,"Faltan "&ROUND(I34,0)&" temas","Sobran "&ROUND(-I34,0)&" temas")) -> Faltan 9 temas | L34: =MAX(D33/G33,D34/G34,D35/G35,D36/G36) -> 137.14286 | M34: =MAX(0,ROUNDUP(G34*L34-D34,0)) -> 20 | N34: =COUNTIFS(Temas_TIMSS!$V$5:$V$1264,$A34,Temas_TIMSS!$K$5:$K$1264,"FUERA") -> 6
A35: 7° | B35: TIMSS 2023 8.° | C35: Física | D35: =COUNTIFS(Temas_TIMSS!$V$5:$V$1264,$A35,Temas_TIMSS!$M$5:$M$1264,$C35) -> 3 | E35: =COUNTIFS(Temas_TIMSS!$V$5:$V$1264,$A35)-COUNTIFS(Temas_TIMSS!$V$5:$V$1264,$A35,Temas_TIMSS!$K$5:$K$1264,"FUERA")-COUNTIFS(Temas_TIMSS!$V$5:$V$1264,$A35,Temas_TIMSS!$K$5:$K$1264,"PENDIENTE") -> 85 | F35: =IF(E35=0,0,D35/E35) -> 0.035294118 | G35: 0.25 | H35: =G35*E35 -> 21.25 | I35: =H35-D35 -> 18.25 | J35: =(G35-F35)*100 -> 21.470588 | K35: =IF(ABS(G35-F35)<=$H$2,"En meta",IF(I35>0,"Faltan "&ROUND(I35,0)&" temas","Sobran "&ROUND(-I35,0)&" temas")) -> Faltan 18 temas | L35: =MAX(D33/G33,D34/G34,D35/G35,D36/G36) -> 137.14286 | M35: =MAX(0,ROUNDUP(G35*L35-D35,0)) -> 32 | N35: =COUNTIFS(Temas_TIMSS!$V$5:$V$1264,$A35,Temas_TIMSS!$K$5:$K$1264,"FUERA") -> 6
A36: 7° | B36: TIMSS 2023 8.° | C36: Ciencias de la Tierra | D36: =COUNTIFS(Temas_TIMSS!$V$5:$V$1264,$A36,Temas_TIMSS!$M$5:$M$1264,$C36) -> 26 | E36: =COUNTIFS(Temas_TIMSS!$V$5:$V$1264,$A36)-COUNTIFS(Temas_TIMSS!$V$5:$V$1264,$A36,Temas_TIMSS!$K$5:$K$1264,"FUERA")-COUNTIFS(Temas_TIMSS!$V$5:$V$1264,$A36,Temas_TIMSS!$K$5:$K$1264,"PENDIENTE") -> 85 | F36: =IF(E36=0,0,D36/E36) -> 0.30588235 | G36: 0.2 | H36: =G36*E36 -> 17 | I36: =H36-D36 -> -9 | J36: =(G36-F36)*100 -> -10.588235 | K36: =IF(ABS(G36-F36)<=$H$2,"En meta",IF(I36>0,"Faltan "&ROUND(I36,0)&" temas","Sobran "&ROUND(-I36,0)&" temas")) -> Sobran 9 temas | L36: =MAX(D33/G33,D34/G34,D35/G35,D36/G36) -> 137.14286 | M36: =MAX(0,ROUNDUP(G36*L36-D36,0)) -> 2 | N36: =COUNTIFS(Temas_TIMSS!$V$5:$V$1264,$A36,Temas_TIMSS!$K$5:$K$1264,"FUERA") -> 6
C37: Total del grupo | D37: =SUM(D33:D36) -> 85 | G37: =SUM(G33:G36) -> 1 | M37: =SUM(M33:M36) -> 54
A39: 8° | B39: TIMSS 2023 8.° | C39: Biología | D39: =COUNTIFS(Temas_TIMSS!$V$5:$V$1264,$A39,Temas_TIMSS!$M$5:$M$1264,$C39) -> 28 | E39: =COUNTIFS(Temas_TIMSS!$V$5:$V$1264,$A39)-COUNTIFS(Temas_TIMSS!$V$5:$V$1264,$A39,Temas_TIMSS!$K$5:$K$1264,"FUERA")-COUNTIFS(Temas_TIMSS!$V$5:$V$1264,$A39,Temas_TIMSS!$K$5:$K$1264,"PENDIENTE") -> 91 | F39: =IF(E39=0,0,D39/E39) -> 0.30769231 | G39: 0.35 | H39: =G39*E39 -> 31.85 | I39: =H39-D39 -> 3.85 | J39: =(G39-F39)*100 -> 4.2307692 | K39: =IF(ABS(G39-F39)<=$H$2,"En meta",IF(I39>0,"Faltan "&ROUND(I39,0)&" temas","Sobran "&ROUND(-I39,0)&" temas")) -> En meta | L39: =MAX(D39/G39,D40/G40,D41/G41,D42/G42) -> 140 | M39: =MAX(0,ROUNDUP(G39*L39-D39,0)) -> 21 | N39: =COUNTIFS(Temas_TIMSS!$V$5:$V$1264,$A39,Temas_TIMSS!$K$5:$K$1264,"FUERA") -> 2
A40: 8° | B40: TIMSS 2023 8.° | C40: Química | D40: =COUNTIFS(Temas_TIMSS!$V$5:$V$1264,$A40,Temas_TIMSS!$M$5:$M$1264,$C40) -> 24 | E40: =COUNTIFS(Temas_TIMSS!$V$5:$V$1264,$A40)-COUNTIFS(Temas_TIMSS!$V$5:$V$1264,$A40,Temas_TIMSS!$K$5:$K$1264,"FUERA")-COUNTIFS(Temas_TIMSS!$V$5:$V$1264,$A40,Temas_TIMSS!$K$5:$K$1264,"PENDIENTE") -> 91 | F40: =IF(E40=0,0,D40/E40) -> 0.26373626 | G40: 0.2 | H40: =G40*E40 -> 18.2 | I40: =H40-D40 -> -5.8 | J40: =(G40-F40)*100 -> -6.3736264 | K40: =IF(ABS(G40-F40)<=$H$2,"En meta",IF(I40>0,"Faltan "&ROUND(I40,0)&" temas","Sobran "&ROUND(-I40,0)&" temas")) -> Sobran 6 temas | L40: =MAX(D39/G39,D40/G40,D41/G41,D42/G42) -> 140 | M40: =MAX(0,ROUNDUP(G40*L40-D40,0)) -> 4 | N40: =COUNTIFS(Temas_TIMSS!$V$5:$V$1264,$A40,Temas_TIMSS!$K$5:$K$1264,"FUERA") -> 2
A41: 8° | B41: TIMSS 2023 8.° | C41: Física | D41: =COUNTIFS(Temas_TIMSS!$V$5:$V$1264,$A41,Temas_TIMSS!$M$5:$M$1264,$C41) -> 35 | E41: =COUNTIFS(Temas_TIMSS!$V$5:$V$1264,$A41)-COUNTIFS(Temas_TIMSS!$V$5:$V$1264,$A41,Temas_TIMSS!$K$5:$K$1264,"FUERA")-COUNTIFS(Temas_TIMSS!$V$5:$V$1264,$A41,Temas_TIMSS!$K$5:$K$1264,"PENDIENTE") -> 91 | F41: =IF(E41=0,0,D41/E41) -> 0.38461538 | G41: 0.25 | H41: =G41*E41 -> 22.75 | I41: =H41-D41 -> -12.25 | J41: =(G41-F41)*100 -> -13.461538 | K41: =IF(ABS(G41-F41)<=$H$2,"En meta",IF(I41>0,"Faltan "&ROUND(I41,0)&" temas","Sobran "&ROUND(-I41,0)&" temas")) -> Sobran 12 temas | L41: =MAX(D39/G39,D40/G40,D41/G41,D42/G42) -> 140 | M41: =MAX(0,ROUNDUP(G41*L41-D41,0)) -> 0 | N41: =COUNTIFS(Temas_TIMSS!$V$5:$V$1264,$A41,Temas_TIMSS!$K$5:$K$1264,"FUERA") -> 2
A42: 8° | B42: TIMSS 2023 8.° | C42: Ciencias de la Tierra | D42: =COUNTIFS(Temas_TIMSS!$V$5:$V$1264,$A42,Temas_TIMSS!$M$5:$M$1264,$C42) -> 4 | E42: =COUNTIFS(Temas_TIMSS!$V$5:$V$1264,$A42)-COUNTIFS(Temas_TIMSS!$V$5:$V$1264,$A42,Temas_TIMSS!$K$5:$K$1264,"FUERA")-COUNTIFS(Temas_TIMSS!$V$5:$V$1264,$A42,Temas_TIMSS!$K$5:$K$1264,"PENDIENTE") -> 91 | F42: =IF(E42=0,0,D42/E42) -> 0.043956044 | G42: 0.2 | H42: =G42*E42 -> 18.2 | I42: =H42-D42 -> 14.2 | J42: =(G42-F42)*100 -> 15.604396 | K42: =IF(ABS(G42-F42)<=$H$2,"En meta",IF(I42>0,"Faltan "&ROUND(I42,0)&" temas","Sobran "&ROUND(-I42,0)&" temas")) -> Faltan 14 temas | L42: =MAX(D39/G39,D40/G40,D41/G41,D42/G42) -> 140 | M42: =MAX(0,ROUNDUP(G42*L42-D42,0)) -> 24 | N42: =COUNTIFS(Temas_TIMSS!$V$5:$V$1264,$A42,Temas_TIMSS!$K$5:$K$1264,"FUERA") -> 2
C43: Total del grupo | D43: =SUM(D39:D42) -> 91 | G43: =SUM(G39:G42) -> 1 | M43: =SUM(M39:M42) -> 49
A45: 9° | B45: TIMSS 2023 8.° | C45: Biología | D45: =COUNTIFS(Temas_TIMSS!$V$5:$V$1264,$A45,Temas_TIMSS!$M$5:$M$1264,$C45) -> 4 | E45: =COUNTIFS(Temas_TIMSS!$V$5:$V$1264,$A45)-COUNTIFS(Temas_TIMSS!$V$5:$V$1264,$A45,Temas_TIMSS!$K$5:$K$1264,"FUERA")-COUNTIFS(Temas_TIMSS!$V$5:$V$1264,$A45,Temas_TIMSS!$K$5:$K$1264,"PENDIENTE") -> 82 | F45: =IF(E45=0,0,D45/E45) -> 0.048780488 | G45: 0.35 | H45: =G45*E45 -> 28.7 | I45: =H45-D45 -> 24.7 | J45: =(G45-F45)*100 -> 30.121951 | K45: =IF(ABS(G45-F45)<=$H$2,"En meta",IF(I45>0,"Faltan "&ROUND(I45,0)&" temas","Sobran "&ROUND(-I45,0)&" temas")) -> Faltan 25 temas | L45: =MAX(D45/G45,D46/G46,D47/G47,D48/G48) -> 152 | M45: =MAX(0,ROUNDUP(G45*L45-D45,0)) -> 50 | N45: =COUNTIFS(Temas_TIMSS!$V$5:$V$1264,$A45,Temas_TIMSS!$K$5:$K$1264,"FUERA") -> 8
A46: 9° | B46: TIMSS 2023 8.° | C46: Química | D46: =COUNTIFS(Temas_TIMSS!$V$5:$V$1264,$A46,Temas_TIMSS!$M$5:$M$1264,$C46) -> 20 | E46: =COUNTIFS(Temas_TIMSS!$V$5:$V$1264,$A46)-COUNTIFS(Temas_TIMSS!$V$5:$V$1264,$A46,Temas_TIMSS!$K$5:$K$1264,"FUERA")-COUNTIFS(Temas_TIMSS!$V$5:$V$1264,$A46,Temas_TIMSS!$K$5:$K$1264,"PENDIENTE") -> 82 | F46: =IF(E46=0,0,D46/E46) -> 0.24390244 | G46: 0.2 | H46: =G46*E46 -> 16.4 | I46: =H46-D46 -> -3.6 | J46: =(G46-F46)*100 -> -4.3902439 | K46: =IF(ABS(G46-F46)<=$H$2,"En meta",IF(I46>0,"Faltan "&ROUND(I46,0)&" temas","Sobran "&ROUND(-I46,0)&" temas")) -> En meta | L46: =MAX(D45/G45,D46/G46,D47/G47,D48/G48) -> 152 | M46: =MAX(0,ROUNDUP(G46*L46-D46,0)) -> 11 | N46: =COUNTIFS(Temas_TIMSS!$V$5:$V$1264,$A46,Temas_TIMSS!$K$5:$K$1264,"FUERA") -> 8
A47: 9° | B47: TIMSS 2023 8.° | C47: Física | D47: =COUNTIFS(Temas_TIMSS!$V$5:$V$1264,$A47,Temas_TIMSS!$M$5:$M$1264,$C47) -> 38 | E47: =COUNTIFS(Temas_TIMSS!$V$5:$V$1264,$A47)-COUNTIFS(Temas_TIMSS!$V$5:$V$1264,$A47,Temas_TIMSS!$K$5:$K$1264,"FUERA")-COUNTIFS(Temas_TIMSS!$V$5:$V$1264,$A47,Temas_TIMSS!$K$5:$K$1264,"PENDIENTE") -> 82 | F47: =IF(E47=0,0,D47/E47) -> 0.46341463 | G47: 0.25 | H47: =G47*E47 -> 20.5 | I47: =H47-D47 -> -17.5 | J47: =(G47-F47)*100 -> -21.341463 | K47: =IF(ABS(G47-F47)<=$H$2,"En meta",IF(I47>0,"Faltan "&ROUND(I47,0)&" temas","Sobran "&ROUND(-I47,0)&" temas")) -> Sobran 18 temas | L47: =MAX(D45/G45,D46/G46,D47/G47,D48/G48) -> 152 | M47: =MAX(0,ROUNDUP(G47*L47-D47,0)) -> 0 | N47: =COUNTIFS(Temas_TIMSS!$V$5:$V$1264,$A47,Temas_TIMSS!$K$5:$K$1264,"FUERA") -> 8
A48: 9° | B48: TIMSS 2023 8.° | C48: Ciencias de la Tierra | D48: =COUNTIFS(Temas_TIMSS!$V$5:$V$1264,$A48,Temas_TIMSS!$M$5:$M$1264,$C48) -> 20 | E48: =COUNTIFS(Temas_TIMSS!$V$5:$V$1264,$A48)-COUNTIFS(Temas_TIMSS!$V$5:$V$1264,$A48,Temas_TIMSS!$K$5:$K$1264,"FUERA")-COUNTIFS(Temas_TIMSS!$V$5:$V$1264,$A48,Temas_TIMSS!$K$5:$K$1264,"PENDIENTE") -> 82 | F48: =IF(E48=0,0,D48/E48) -> 0.24390244 | G48: 0.2 | H48: =G48*E48 -> 16.4 | I48: =H48-D48 -> -3.6 | J48: =(G48-F48)*100 -> -4.3902439 | K48: =IF(ABS(G48-F48)<=$H$2,"En meta",IF(I48>0,"Faltan "&ROUND(I48,0)&" temas","Sobran "&ROUND(-I48,0)&" temas")) -> En meta | L48: =MAX(D45/G45,D46/G46,D47/G47,D48/G48) -> 152 | M48: =MAX(0,ROUNDUP(G48*L48-D48,0)) -> 11 | N48: =COUNTIFS(Temas_TIMSS!$V$5:$V$1264,$A48,Temas_TIMSS!$K$5:$K$1264,"FUERA") -> 8
...

Sheet Cobertura_objetivos
A1: Amplitud: ¿qué objetivos TIMSS cubre la malla y en qué grado?
A2: Cada celda de grado = n.º de temas de ese grado que trabajan el objetivo como principal o secundario (COUNTIFS sobre Temas_TIMSS). «Total en su ciclo» suma solo los grados que evalúa cada marco: TIMSS 4.° → 2.°–4.°; TIMSS 8.° → 5.°–8.° (la columna 9.° es referencia); TIMSS Advanced → Física 10.°–11.°. «Profundidad»: 0 = no cubierto; 1 = débil; 2–3 = básica; 4+ = sólida.
A4: Código | B4: Marco | C4: Dominio | D4: Área temática | E4: Objetivo | F4: 2° | G4: 3° | H4: 4° | I4: 5° | J4: 6° | K4: 7° | L4: 8° | M4: 9° | N4: Física 10° | O4: Física 11° | P4: Total temas en su ciclo | Q4: Como principal (todos los grados) | R4: Cubierto en su ciclo | S4: Profundidad en su ciclo | T4: Primer grado donde aparece
A5: T4-V1.1 | B5: T4 | C5: Ciencias de la vida | D5: Características y procesos vitales de los organismos | E5: Distinguir seres vivos de no vivos; reconocer lo que necesitan para vivir | F5: =COUNTIFS(Temas_TIMSS!$V$5:$V$1264,F$4,Temas_TIMSS!$K$5:$K$1264,$A5)+COUNTIFS(Temas_TIMSS!$V$5:$V$1264,F$4,Temas_TIMSS!$L$5:$L$1264,$A5) -> 5 | G5: =COUNTIFS(Temas_TIMSS!$V$5:$V$1264,G$4,Temas_TIMSS!$K$5:$K$1264,$A5)+COUNTIFS(Temas_TIMSS!$V$5:$V$1264,G$4,Temas_TIMSS!$L$5:$L$1264,$A5) -> 5 | H5: =COUNTIFS(Temas_TIMSS!$V$5:$V$1264,H$4,Temas_TIMSS!$K$5:$K$1264,$A5)+COUNTIFS(Temas_TIMSS!$V$5:$V$1264,H$4,Temas_TIMSS!$L$5:$L$1264,$A5) -> 3 | I5: =COUNTIFS(Temas_TIMSS!$V$5:$V$1264,I$4,Temas_TIMSS!$K$5:$K$1264,$A5)+COUNTIFS(Temas_TIMSS!$V$5:$V$1264,I$4,Temas_TIMSS!$L$5:$L$1264,$A5) -> 0 | J5: =COUNTIFS(Temas_TIMSS!$V$5:$V$1264,J$4,Temas_TIMSS!$K$5:$K$1264,$A5)+COUNTIFS(Temas_TIMSS!$V$5:$V$1264,J$4,Temas_TIMSS!$L$5:$L$1264,$A5) -> 0 | K5: =COUNTIFS(Temas_TIMSS!$V$5:$V$1264,K$4,Temas_TIMSS!$K$5:$K$1264,$A5)+COUNTIFS(Temas_TIMSS!$V$5:$V$1264,K$4,Temas_TIMSS!$L$5:$L$1264,$A5) -> 0 | L5: =COUNTIFS(Temas_TIMSS!$V$5:$V$1264,L$4,Temas_TIMSS!$K$5:$K$1264,$A5)+COUNTIFS(Temas_TIMSS!$V$5:$V$1264,L$4,Temas_TIMSS!$L$5:$L$1264,$A5) -> 0 | M5: =COUNTIFS(Temas_TIMSS!$V$5:$V$1264,M$4,Temas_TIMSS!$K$5:$K$1264,$A5)+COUNTIFS(Temas_TIMSS!$V$5:$V$1264,M$4,Temas_TIMSS!$L$5:$L$1264,$A5) -> 0 | ... O5: =COUNTIFS(Temas_TIMSS!$V$5:$V$1264,O$4,Temas_TIMSS!$K$5:$K$1264,$A5)+COUNTIFS(Temas_TIMSS!$V$5:$V$1264,O$4,Temas_TIMSS!$L$5:$L$1264,$A5) -> 0 | P5: =IF($B5="T4",SUM(F5:H5),IF($B5="T8",SUM(I5:L5),SUM(N5:O5))) -> 13 | Q5: =COUNTIFS(Temas_TIMSS!$K$5:$K$1264,$A5) -> 6 | R5: =IF(P5>0,"Sí","No") -> Sí | S5: =IF(P5=0,"No cubierto",IF(P5=1,"Débil (1 tema)",IF(P5<=3,"Básica (2–3)","Sólida (4+)"))) -> Sólida (4+) | T5: =IFERROR(INDEX($F$4:$O$4,MATCH(TRUE(),INDEX(F5:O5>0,0),0)),"—") -> 2°
A6: T4-V1.2 | B6: T4 | C6: Ciencias de la vida | D6: Características y procesos vitales de los organismos | E6: Comparar rasgos físicos y de conducta de grandes grupos de animales y plantas | F6: =COUNTIFS(Temas_TIMSS!$V$5:$V$1264,F$4,Temas_TIMSS!$K$5:$K$1264,$A6)+COUNTIFS(Temas_TIMSS!$V$5:$V$1264,F$4,Temas_TIMSS!$L$5:$L$1264,$A6) -> 6 | G6: =COUNTIFS(Temas_TIMSS!$V$5:$V$1264,G$4,Temas_TIMSS!$K$5:$K$1264,$A6)+COUNTIFS(Temas_TIMSS!$V$5:$V$1264,G$4,Temas_TIMSS!$L$5:$L$1264,$A6) -> 15 | H6: =COUNTIFS(Temas_TIMSS!$V$5:$V$1264,H$4,Temas_TIMSS!$K$5:$K$1264,$A6)+COUNTIFS(Temas_TIMSS!$V$5:$V$1264,H$4,Temas_TIMSS!$L$5:$L$1264,$A6) -> 0 | I6: =COUNTIFS(Temas_TIMSS!$V$5:$V$1264,I$4,Temas_TIMSS!$K$5:$K$1264,$A6)+COUNTIFS(Temas_TIMSS!$V$5:$V$1264,I$4,Temas_TIMSS!$L$5:$L$1264,$A6) -> 0 | J6: =COUNTIFS(Temas_TIMSS!$V$5:$V$1264,J$4,Temas_TIMSS!$K$5:$K$1264,$A6)+COUNTIFS(Temas_TIMSS!$V$5:$V$1264,J$4,Temas_TIMSS!$L$5:$L$1264,$A6) -> 0 | K6: =COUNTIFS(Temas_TIMSS!$V$5:$V$1264,K$4,Temas_TIMSS!$K$5:$K$1264,$A6)+COUNTIFS(Temas_TIMSS!$V$5:$V$1264,K$4,Temas_TIMSS!$L$5:$L$1264,$A6) -> 0 | L6: =COUNTIFS(Temas_TIMSS!$V$5:$V$1264,L$4,Temas_TIMSS!$K$5:$K$1264,$A6)+COUNTIFS(Temas_TIMSS!$V$5:$V$1264,L$4,Temas_TIMSS!$L$5:$L$1264,$A6) -> 0 | M6: =COUNTIFS(Temas_TIMSS!$V$5:$V$1264,M$4,Temas_TIMSS!$K$5:$K$1264,$A6)+COUNTIFS(Temas_TIMSS!$V$5:$V$1264,M$4,Temas_TIMSS!$L$5:$L$1264,$A6) -> 0 | ... O6: =COUNTIFS(Temas_TIMSS!$V$5:$V$1264,O$4,Temas_TIMSS!$K$5:$K$1264,$A6)+COUNTIFS(Temas_TIMSS!$V$5:$V$1264,O$4,Temas_TIMSS!$L$5:$L$1264,$A6) -> 0 | P6: =IF($B6="T4",SUM(F6:H6),IF($B6="T8",SUM(I6:L6),SUM(N6:O6))) -> 21 | Q6: =COUNTIFS(Temas_TIMSS!$K$5:$K$1264,$A6) -> 20 | R6: =IF(P6>0,"Sí","No") -> Sí | S6: =IF(P6=0,"No cubierto",IF(P6=1,"Débil (1 tema)",IF(P6<=3,"Básica (2–3)","Sólida (4+)"))) -> Sólida (4+) | T6: =IFERROR(INDEX($F$4:$O$4,MATCH(TRUE(),INDEX(F6:O6>0,0),0)),"—") -> 2°
A7: T4-V1.3 | B7: T4 | C7: Ciencias de la vida | D7: Características y procesos vitales de los organismos | E7: Relacionar estructuras principales de los organismos con su función | F7: =COUNTIFS(Temas_TIMSS!$V$5:$V$1264,F$4,Temas_TIMSS!$K$5:$K$1264,$A7)+COUNTIFS(Temas_TIMSS!$V$5:$V$1264,F$4,Temas_TIMSS!$L$5:$L$1264,$A7) -> 2 | G7: =COUNTIFS(Temas_TIMSS!$V$5:$V$1264,G$4,Temas_TIMSS!$K$5:$K$1264,$A7)+COUNTIFS(Temas_TIMSS!$V$5:$V$1264,G$4,Temas_TIMSS!$L$5:$L$1264,$A7) -> 4 | H7: =COUNTIFS(Temas_TIMSS!$V$5:$V$1264,H$4,Temas_TIMSS!$K$5:$K$1264,$A7)+COUNTIFS(Temas_TIMSS!$V$5:$V$1264,H$4,Temas_TIMSS!$L$5:$L$1264,$A7) -> 18 | I7: =COUNTIFS(Temas_TIMSS!$V$5:$V$1264,I$4,Temas_TIMSS!$K$5:$K$1264,$A7)+COUNTIFS(Temas_TIMSS!$V$5:$V$1264,I$4,Temas_TIMSS!$L$5:$L$1264,$A7) -> 0 | J7: =COUNTIFS(Temas_TIMSS!$V$5:$V$1264,J$4,Temas_TIMSS!$K$5:$K$1264,$A7)+COUNTIFS(Temas_TIMSS!$V$5:$V$1264,J$4,Temas_TIMSS!$L$5:$L$1264,$A7) -> 0 | K7: =COUNTIFS(Temas_TIMSS!$V$5:$V$1264,K$4,Temas_TIMSS!$K$5:$K$1264,$A7)+COUNTIFS(Temas_TIMSS!$V$5:$V$1264,K$4,Temas_TIMSS!$L$5:$L$1264,$A7) -> 0 | L7: =COUNTIFS(Temas_TIMSS!$V$5:$V$1264,L$4,Temas_TIMSS!$K$5:$K$1264,$A7)+COUNTIFS(Temas_TIMSS!$V$5:$V$1264,L$4,Temas_TIMSS!$L$5:$L$1264,$A7) -> 0 | M7: =COUNTIFS(Temas_TIMSS!$V$5:$V$1264,M$4,Temas_TIMSS!$K$5:$K$1264,$A7)+COUNTIFS(Temas_TIMSS!$V$5:$V$1264,M$4,Temas_TIMSS!$L$5:$L$1264,$A7) -> 0 | ... O7: =COUNTIFS(Temas_TIMSS!$V$5:$V$1264,O$4,Temas_TIMSS!$K$5:$K$1264,$A7)+COUNTIFS(Temas_TIMSS!$V$5:$V$1264,O$4,Temas_TIMSS!$L$5:$L$1264,$A7) -> 0 | P7: =IF($B7="T4",SUM(F7:H7),IF($B7="T8",SUM(I7:L7),SUM(N7:O7))) -> 24 | Q7: =COUNTIFS(Temas_TIMSS!$K$5:$K$1264,$A7) -> 21 | R7: =IF(P7>0,"Sí","No") -> Sí | S7: =IF(P7=0,"No cubierto",IF(P7=1,"Débil (1 tema)",IF(P7<=3,"Básica (2–3)","Sólida (4+)"))) -> Sólida (4+) | T7: =IFERROR(INDEX($F$4:$O$4,MATCH(TRUE(),INDEX(F7:O7>0,0),0)),"—") -> 2°
A8: T4-V2.1 | B8: T4 | C8: Ciencias de la vida | D8: Ciclos de vida, reproducción y herencia | E8: Etapas del ciclo de vida de plantas con flor; comparar ciclos de plantas y animales | F8: =COUNTIFS(Temas_TIMSS!$V$5:$V$1264,F$4,Temas_TIMSS!$K$5:$K$1264,$A8)+COUNTIFS(Temas_TIMSS!$V$5:$V$1264,F$4,Temas_TIMSS!$L$5:$L$1264,$A8) -> 1 | G8: =COUNTIFS(Temas_TIMSS!$V$5:$V$1264,G$4,Temas_TIMSS!$K$5:$K$1264,$A8)+COUNTIFS(Temas_TIMSS!$V$5:$V$1264,G$4,Temas_TIMSS!$L$5:$L$1264,$A8) -> 1 | H8: =COUNTIFS(Temas_TIMSS!$V$5:$V$1264,H$4,Temas_TIMSS!$K$5:$K$1264,$A8)+COUNTIFS(Temas_TIMSS!$V$5:$V$1264,H$4,Temas_TIMSS!$L$5:$L$1264,$A8) -> 0 | I8: =COUNTIFS(Temas_TIMSS!$V$5:$V$1264,I$4,Temas_TIMSS!$K$5:$K$1264,$A8)+COUNTIFS(Temas_TIMSS!$V$5:$V$1264,I$4,Temas_TIMSS!$L$5:$L$1264,$A8) -> 0 | J8: =COUNTIFS(Temas_TIMSS!$V$5:$V$1264,J$4,Temas_TIMSS!$K$5:$K$1264,$A8)+COUNTIFS(Temas_TIMSS!$V$5:$V$1264,J$4,Temas_TIMSS!$L$5:$L$1264,$A8) -> 0 | K8: =COUNTIFS(Temas_TIMSS!$V$5:$V$1264,K$4,Temas_TIMSS!$K$5:$K$1264,$A8)+COUNTIFS(Temas_TIMSS!$V$5:$V$1264,K$4,Temas_TIMSS!$L$5:$L$1264,$A8) -> 0 | L8: =COUNTIFS(Temas_TIMSS!$V$5:$V$1264,L$4,Temas_TIMSS!$K$5:$K$1264,$A8)+COUNTIFS(Temas_TIMSS!$V$5:$V$1264,L$4,Temas_TIMSS!$L$5:$L$1264,$A8) -> 0 | M8: =COUNTIFS(Temas_TIMSS!$V$5:$V$1264,M$4,Temas_TIMSS!$K$5:$K$1264,$A8)+COUNTIFS(Temas_TIMSS!$V$5:$V$1264,M$4,Temas_TIMSS!$L$5:$L$1264,$A8) -> 0 | ... O8: =COUNTIFS(Temas_TIMSS!$V$5:$V$1264,O$4,Temas_TIMSS!$K$5:$K$1264,$A8)+COUNTIFS(Temas_TIMSS!$V$5:$V$1264,O$4,Temas_TIMSS!$L$5:$L$1264,$A8) -> 0 | P8: =IF($B8="T4",SUM(F8:H8),IF($B8="T8",SUM(I8:L8),SUM(N8:O8))) -> 2 | Q8: =COUNTIFS(Temas_TIMSS!$K$5:$K$1264,$A8) -> 2 | R8: =IF(P8>0,"Sí","No") -> Sí | S8: =IF(P8=0,"No cubierto",IF(P8=1,"Débil (1 tema)",IF(P8<=3,"Básica (2–3)","Sólida (4+)"))) -> Básica (2–3) | T8: =IFERROR(INDEX($F$4:$O$4,MATCH(TRUE(),INDEX(F8:O8>0,0),0)),"—") -> 2°
