Workbook

Sheet Inicio
B1: Cobertura de la malla de Ciencia y Tecnología frente a TIMSS 2027 y PISA 2025 — hallazgos, cómo se construyó y cómo leerla
B2: Versión 3 (TIMSS 2027 + PISA 2025) · 2 de octubre de 2026 · Elaborado con Claude Code a partir de las mallas del equipo de Ciencias (MINED). Las versiones anteriores (TIMSS 2023) se conservan en Cobertura_TIMSS_Ciencias_SV.xlsx.
B3: ="TIMSS 2027 y PISA 2025"&" "&"BIEN · En lo acumulado la malla se parece a las pruebas: "&FIXED('Apego TIMSS y PISA'!F17*100,0)&" %"&" (TIMSS 4.°), "&FIXED('Apego TIMSS y PISA'!F18*100,0)&" %"&" (TIMSS 8.°) y "&FIXED('Apego TIMSS y PISA'!F23*100,0)&" %"&" (PISA) de apego."&" "&"OJO · TIMSS: falta Biología en 5.°, luz-sonido-electricidad en 4.° y más Razonar en 6.° y 8.°."&" "&"OJO · PISA: falta biología en 9.°, Tierra y espacio en 8.°, y enseñar a evaluar información y el porqué de la ciencia."&" "&"→ Empieza por «Resumen TIMSS y PISA» y «Presupuesto de temas». Las pestañas que empiezan con TIMSS o PISA tienen el detalle de cada prueba."
B5: Resumen ejecutivo (las cifras se recalculan con el libro)
B6: ="1. Apego general. En lo acumulado, la malla se parece mucho a lo que piden las pruebas: índice de apego de "&FIXED('Apego TIMSS y PISA'!F17*100,0)&" %"&" frente a TIMSS 4.° (2.°–4.°), "&FIXED('Apego TIMSS y PISA'!F18*100,0)&" %"&" frente a TIMSS 8.° (5.°–8.°) y "&FIXED('Apego TIMSS y PISA'!F23*100,0)&" %"&" frente a PISA (7.°–9.°). Cubre "&'TIMSS - Semáforo de objetivos'!D115&" de "&'TIMSS - Semáforo de objetivos'!C115&" objetivos de TIMSS 4.°, "&'TIMSS - Semáforo de objetivos'!D120&" de "&'TIMSS - Semáforo de objetivos'!C120&" de TIMSS 8.° y "&'PISA - Contenidos'!C55&" de 21 categorías de contenido de PISA. Los problemas están en el reparto entre grados y en las capas propias de PISA."
B7: ="2. Grados a mejorar. 5.° es el grado con menor apego ("&FIXED('Apego TIMSS y PISA'!F11*100,0)&" %"&"): le faltan unos "&FIXED('TIMSS - Balance por grado'!I21,0)&" temas de Biología del marco de 8.°, que Uruguay, Colombia y Singapur enseñan en 5.°–6.° y El Salvador recién en 6.°–7.°. En 4.° faltan unos "&FIXED('TIMSS - Balance por grado'!I17,0)&" temas de Ciencias físicas (luz, sonido, electricidad, imanes). 8.° tiene solo "&'PISA - Contenidos'!D13&" temas de Tierra y espacio y 9.° solo "&'PISA - Contenidos'!D17&" de sistemas vivos (ni célula, ni genética, ni salud humana). En 6.° y 8.° Razonar queda en "&FIXED('TIMSS - Conocer-Aplicar-Razonar'!I9*100,0)&" %"&" y "&FIXED('TIMSS - Conocer-Aplicar-Razonar'!I11*100,0)&" %"&" (meta TIMSS 30 %)."
B8: ="3. Competencias PISA. La malla declara una competencia y cinco subcompetencias por tema (columnas de la propia malla). En 7.°–9.° la competencia 3, «Investigar, evaluar y usar información para decidir», llega a "&FIXED('PISA - Competencias'!H16*100,0)&" %"&" de los temas (PISA: 24–36 %); distinguir evidencia de opinión (I2), criticar argumentos (I4) y formular hipótesis (E5) casi no aparecen. La competencia 2 está sobrerrepresentada ("&FIXED('PISA - Competencias'!G16*100,0)&" %"&")."
B9: ="4. Conocimiento procedimental y epistémico (lo que más agrega PISA). Solo "&FIXED('PISA - Tipos de conocimiento'!G16*100,0)&" %"&" de los temas de 7.°–9.° tienen como foco el conocimiento procedimental (PISA: 27–33 %) y ninguno el epistémico (24–30 %). "&'PISA - Tipos de conocimiento'!E57&" de los 20 elementos epistémicos (modelos frente a realidad, consenso, revisión por pares, límites de la certeza) no se trabajan en ningún tema."
B10: ="5. Contextos. "&FIXED('PISA - Contextos'!G16*100,0)&" %"&" de los temas de 7.°–9.° no sitúan la ciencia en una situación real ("&FIXED('PISA - Contextos'!G14*100,0)&" %"&" en 8.°). Cuando hay contexto, el reparto personal / local / global se parece al 1:2:1 de PISA."
B11: ="6. Frente a otros países, El Salvador introduce "&COUNTIF('TIMSS - Otros países'!$K$5:$K$84,"El Salvador llega más tarde")&" objetivos TIMSS más tarde que la mediana, "&COUNTIF('TIMSS - Otros países'!$K$5:$K$84,"El Salvador va adelantado")&" antes y no trabaja "&COUNTIF('TIMSS - Otros países'!$K$5:$K$84,"El Salvador no llega")&" que otros sí (herencia y propiedades de la luz)."
B13: Recomendaciones
B14: R1. Decidir el peso de PISA en 7.° y 8.° (hoja Apego TIMSS y PISA, celda E4). Sugerencia mientras se decide: PISA como guía en 7.° y 9.°, y 50/50 en 8.° si El Salvador rinde TIMSS 2027 (8.° es el grado que TIMSS evalúa).
B15: ="R2. 2.°–4.° (hoja Presupuesto de temas): fusionar temas repetidos de Biología para liberar "&FIXED('Presupuesto de temas'!J9,0)&" espacios e insertar "&FIXED('Presupuesto de temas'!G9,0)&" temas de Ciencias físicas y de la Tierra (luz, sonido, circuitos, imanes, tiempo atmosférico) y "&FIXED('Presupuesto de temas'!H9,0)&" de herencia (B2.2), sin cambiar el total."
B16: R3. 5.°–8.°: el total por dominio ya está en meta; no hace falta agregar temas. Conviene REUBICAR (Presupuesto, acción «reubicar»): adelantar Biología de 7.° a 5.°, insertar luz (con una fusión de Física) y traer al ciclo los movimientos de la Tierra y la Luna (hoy en 9.°), y subir tareas de Razonar en 6.° y 8.°.
B17: ="R4. 7.°–9.° (PISA): fusionar temas de física y química que se repiten (liberan "&FIXED('Presupuesto de temas'!J20,0)&") para insertar "&FIXED('Presupuesto de temas'!G20,0)&" temas de sistemas vivos (sobre todo en 9.°: célula, salud, genética, evolución) y de Tierra y espacio (sobre todo en 8.°: universo, historia de la Tierra)."
B18: R5. Capas PISA: en cada unidad de 7.°–9.°, al menos un tema o fase que trabaje lo epistémico (por qué se confía en un modelo o en una conclusión) y la competencia 3 (evaluar fuentes, distinguir evidencia de opinión, criticar argumentos con datos), situado en un contexto local o personal. No requiere temas nuevos: cambia la fase «Reforzar».
B19: R6. Validar antes de decidir: las clasificaciones y los candidatos del presupuesto son asistidos por IA. El equipo de Ciencias debe revisar primero los de confianza baja (columna «Decisión del equipo» en Presupuesto y outputs/revision_confianza_baja_timss2027.csv).
B21: Qué responde este libro
B22: 1. Balance: ¿el reparto de temas entre Vida / Física / Química / Tierra se parece al peso que TIMSS da a cada dominio? ¿Cuántos temas faltan o sobran para llegar a la meta?
B23: 2. Amplitud: ¿qué objetivos de contenido de TIMSS aparecen en la malla, en qué grado, con cuántos temas, y cuáles no aparecen?
B24: 3. Profundidad cognitiva: ¿la proporción Conocer / Aplicar / Razonar se parece a la de TIMSS? 4. PISA (7.°–9.°): ¿cubre los sistemas y categorías de contenido, las tres competencias y sus subcompetencias, el conocimiento procedimental y epistémico, y los contextos que PISA evalúa? 5. ¿Qué insertar y qué fusionar para acercarse a las metas sin aumentar la carga?
B26: Proceso (de dónde salen los números)
B27: Paso 1 · Extracción. Se leyeron las 11 mallas (2.° a 9.° y Física, Química, Biología de 10.° y 11.°). Cada fila con «Procedimental» es un TEMA: 1.260 en total. Se conservan archivo, hoja y fila de origen (hoja Datos - Temas, columnas D-F) para poder volver a la malla.
B28: Paso 2 · Catálogo de referencia. Objetivos de contenido de TIMSS 2027 (4.° grado: 32; 8.° grado: 48), construidos desde el PDF oficial con página citada, y TIMSS Advanced 2015 Física (23), con su dominio y el % que TIMSS asigna a cada dominio (hoja Datos - Catálogo TIMSS, celdas ámbar = valores tomados del marco y editables). Novedades 2027: áreas de Investigaciones en cada dominio y subescala de conocimiento ambiental.
B29: Paso 3 · Clasificación. Los 622 temas de 2.° a 9.° se reclasificaron contra TIMSS 2027 con agentes de IA (instrucciones fijas, un lote por grado), usando la clasificación 2023 y la tabla de equivalencias solo como referencia. Física 10.°–11.° conserva la clasificación TIMSS Advanced 2015. Un tema va a un área de Investigaciones solo si su foco es la práctica científica; si trabaja un contenido mediante indagación, la investigación va como secundaria.
B30: Paso 4 · Reglas de grado. 2.°–4.° → TIMSS 2027 4.°; 5.°–8.° → TIMSS 2027 8.°; 7.°–9.° → PISA 2025 (7.° y 8.° con los dos marcos, 9.° solo PISA); Física 10.°–11.° → TIMSS Advanced 2015. Química y Biología de Bachillerato no tienen marco de contenido.
B31: Paso 4-bis · PISA 2025. Catálogo desde el marco final (OECD 2026, cap. 2, con página). Los temas de 7.°–9.° se clasificaron con IA por categoría de contenido, tipo de conocimiento, elementos procedimentales y epistémicos, contexto, área de aplicación y demanda cognitiva. La competencia y las subcompetencias NO se clasificaron: salen de la propia malla (columnas «Competencia PISA 2025» y microhabilidades E/D/I por fase).
... B52: • 1.° grado no tiene malla, así que no entra en el ciclo 2.°–4.°.

Sheet Resumen TIMSS y PISA
A1: Resumen por grado: TIMSS 2027 (2.°–8.° y Física) arriba · PISA 2025 (7.°–9.°) abajo
A2: ="TIMSS 2027 y PISA 2025"&" "&"OJO · TIMSS (2.°–8.°): faltan "&FIXED(MAX($G$5:$G$11),0)&" temas de "&INDEX($F$5:$F$11,MATCH(MAX($G$5:$G$11),$G$5:$G$11,0))&" en "&SUBSTITUTE(INDEX($A$5:$A$11,MATCH(MAX($G$5:$G$11),$G$5:$G$11,0)),"°",".°")&", el grado más desbalanceado."&" "&"OJO · PISA (7.°–9.°): faltan "&FIXED(G25,0)&" temas de "&LOWER(F25)&" en 9.°; en 7.°–9.° sobran "&FIXED(I26,0)&" de "&LOWER(H26)&"."&" "&"● Arriba: tabla TIMSS. Abajo: tabla PISA. Al final: qué significa cada columna."
A3: Lo contrario de «sin objetivo en el marco» (objetivos que TIMSS evalúa y la malla NO trabaja) está en el bloque por ciclo, columna «Objetivos no cubiertos», y en rojo en TIMSS - Semáforo de objetivos. Al final de esta hoja hay una guía de cada columna.
A4: Grupo | B4: Marco de referencia | C4: Temas totales | D4: Temas de la malla SIN objetivo en el marco (la malla los tiene; TIMSS no los evalúa) | E4: % de temas sin objetivo en el marco | F4: Dominio TIMSS con MÁS temas faltantes (frente a su meta) | G4: Temas que faltan en ese dominio | H4: Dominio TIMSS con MÁS temas de sobra | I4: Temas que sobran en ese dominio | J4: Temas a AGREGAR, sin quitar ninguno, para que TODOS los dominios lleguen a su meta | K4: Dominios en meta (±tolerancia) | L4: % Razonar actual | M4: % Razonar meta
A5: 2° | B5: TIMSS 2027 4.° | C5: =COUNTIFS('Datos - Temas'!$V$5:$V$1264,$A5) | D5: ='TIMSS - Balance por grado'!N6 | E5: =IF(C5=0,0,D5/C5) | F5: =INDEX('TIMSS - Balance por grado'!$C$6:$C$8,MATCH(MAX('TIMSS - Balance por grado'!$I$6:$I$8),'TIMSS - Balance por grado'!$I$6:$I$8,0)) | G5: =ROUND(MAX('TIMSS - Balance por grado'!$I$6:$I$8),0) | H5: =INDEX('TIMSS - Balance por grado'!$C$6:$C$8,MATCH(MIN('TIMSS - Balance por grado'!$I$6:$I$8),'TIMSS - Balance por grado'!$I$6:$I$8,0)) | I5: =ROUND(-MIN('TIMSS - Balance por grado'!$I$6:$I$8),0) | J5: ='TIMSS - Balance por grado'!M9 | K5: =COUNTIF('TIMSS - Balance por grado'!$K$6:$K$8,"En meta")&" de "&ROWS('TIMSS - Balance por grado'!$K$6:$K$8) | L5: ='TIMSS - Conocer-Aplicar-Razonar'!I5 | M5: ='TIMSS - Conocer-Aplicar-Razonar'!L5
A6: 3° | B6: TIMSS 2027 4.° | C6: =COUNTIFS('Datos - Temas'!$V$5:$V$1264,$A6) | D6: ='TIMSS - Balance por grado'!N11 | E6: =IF(C6=0,0,D6/C6) | F6: =INDEX('TIMSS - Balance por grado'!$C$11:$C$13,MATCH(MAX('TIMSS - Balance por grado'!$I$11:$I$13),'TIMSS - Balance por grado'!$I$11:$I$13,0)) | G6: =ROUND(MAX('TIMSS - Balance por grado'!$I$11:$I$13),0) | H6: =INDEX('TIMSS - Balance por grado'!$C$11:$C$13,MATCH(MIN('TIMSS - Balance por grado'!$I$11:$I$13),'TIMSS - Balance por grado'!$I$11:$I$13,0)) | I6: =ROUND(-MIN('TIMSS - Balance por grado'!$I$11:$I$13),0) | J6: ='TIMSS - Balance por grado'!M14 | K6: =COUNTIF('TIMSS - Balance por grado'!$K$11:$K$13,"En meta")&" de "&ROWS('TIMSS - Balance por grado'!$K$11:$K$13) | L6: ='TIMSS - Conocer-Aplicar-Razonar'!I6 | M6: ='TIMSS - Conocer-Aplicar-Razonar'!L6
A7: 4° | B7: TIMSS 2027 4.° | C7: =COUNTIFS('Datos - Temas'!$V$5:$V$1264,$A7) | D7: ='TIMSS - Balance por grado'!N16 | E7: =IF(C7=0,0,D7/C7) | F7: =INDEX('TIMSS - Balance por grado'!$C$16:$C$18,MATCH(MAX('TIMSS - Balance por grado'!$I$16:$I$18),'TIMSS - Balance por grado'!$I$16:$I$18,0)) | G7: =ROUND(MAX('TIMSS - Balance por grado'!$I$16:$I$18),0) | H7: =INDEX('TIMSS - Balance por grado'!$C$16:$C$18,MATCH(MIN('TIMSS - Balance por grado'!$I$16:$I$18),'TIMSS - Balance por grado'!$I$16:$I$18,0)) | I7: =ROUND(-MIN('TIMSS - Balance por grado'!$I$16:$I$18),0) | J7: ='TIMSS - Balance por grado'!M19 | K7: =COUNTIF('TIMSS - Balance por grado'!$K$16:$K$18,"En meta")&" de "&ROWS('TIMSS - Balance por grado'!$K$16:$K$18) | L7: ='TIMSS - Conocer-Aplicar-Razonar'!I7 | M7: ='TIMSS - Conocer-Aplicar-Razonar'!L7
A8: 5° | B8: TIMSS 2027 8.° | C8: =COUNTIFS('Datos - Temas'!$V$5:$V$1264,$A8) | D8: ='TIMSS - Balance por grado'!N21 | E8: =IF(C8=0,0,D8/C8) | F8: =INDEX('TIMSS - Balance por grado'!$C$21:$C$24,MATCH(MAX('TIMSS - Balance por grado'!$I$21:$I$24),'TIMSS - Balance por grado'!$I$21:$I$24,0)) | G8: =ROUND(MAX('TIMSS - Balance por grado'!$I$21:$I$24),0) | H8: =INDEX('TIMSS - Balance por grado'!$C$21:$C$24,MATCH(MIN('TIMSS - Balance por grado'!$I$21:$I$24),'TIMSS - Balance por grado'!$I$21:$I$24,0)) | I8: =ROUND(-MIN('TIMSS - Balance por grado'!$I$21:$I$24),0) | J8: ='TIMSS - Balance por grado'!M25 | K8: =COUNTIF('TIMSS - Balance por grado'!$K$21:$K$24,"En meta")&" de "&ROWS('TIMSS - Balance por grado'!$K$21:$K$24) | L8: ='TIMSS - Conocer-Aplicar-Razonar'!I8 | M8: ='TIMSS - Conocer-Aplicar-Razonar'!L8
A9: 6° | B9: TIMSS 2027 8.° | C9: =COUNTIFS('Datos - Temas'!$V$5:$V$1264,$A9) | D9: ='TIMSS - Balance por grado'!N27 | E9: =IF(C9=0,0,D9/C9) | F9: =INDEX('TIMSS - Balance por grado'!$C$27:$C$30,MATCH(MAX('TIMSS - Balance por grado'!$I$27:$I$30),'TIMSS - Balance por grado'!$I$27:$I$30,0)) | G9: =ROUND(MAX('TIMSS - Balance por grado'!$I$27:$I$30),0) | H9: =INDEX('TIMSS - Balance por grado'!$C$27:$C$30,MATCH(MIN('TIMSS - Balance por grado'!$I$27:$I$30),'TIMSS - Balance por grado'!$I$27:$I$30,0)) | I9: =ROUND(-MIN('TIMSS - Balance por grado'!$I$27:$I$30),0) | J9: ='TIMSS - Balance por grado'!M31 | K9: =COUNTIF('TIMSS - Balance por grado'!$K$27:$K$30,"En meta")&" de "&ROWS('TIMSS - Balance por grado'!$K$27:$K$30) | L9: ='TIMSS - Conocer-Aplicar-Razonar'!I9 | M9: ='TIMSS - Conocer-Aplicar-Razonar'!L9
A10: 7° | B10: TIMSS 2027 8.° | C10: =COUNTIFS('Datos - Temas'!$V$5:$V$1264,$A10) | D10: ='TIMSS - Balance por grado'!N33 | E10: =IF(C10=0,0,D10/C10) | F10: =INDEX('TIMSS - Balance por grado'!$C$33:$C$36,MATCH(MAX('TIMSS - Balance por grado'!$I$33:$I$36),'TIMSS - Balance por grado'!$I$33:$I$36,0)) | G10: =ROUND(MAX('TIMSS - Balance por grado'!$I$33:$I$36),0) | H10: =INDEX('TIMSS - Balance por grado'!$C$33:$C$36,MATCH(MIN('TIMSS - Balance por grado'!$I$33:$I$36),'TIMSS - Balance por grado'!$I$33:$I$36,0)) | I10: =ROUND(-MIN('TIMSS - Balance por grado'!$I$33:$I$36),0) | J10: ='TIMSS - Balance por grado'!M37 | K10: =COUNTIF('TIMSS - Balance por grado'!$K$33:$K$36,"En meta")&" de "&ROWS('TIMSS - Balance por grado'!$K$33:$K$36) | L10: ='TIMSS - Conocer-Aplicar-Razonar'!I10 | M10: ='TIMSS - Conocer-Aplicar-Razonar'!L10
A11: 8° | B11: TIMSS 2027 8.° | C11: =COUNTIFS('Datos - Temas'!$V$5:$V$1264,$A11) | D11: ='TIMSS - Balance por grado'!N39 | E11: =IF(C11=0,0,D11/C11) | F11: =INDEX('TIMSS - Balance por grado'!$C$39:$C$42,MATCH(MAX('TIMSS - Balance por grado'!$I$39:$I$42),'TIMSS - Balance por grado'!$I$39:$I$42,0)) | G11: =ROUND(MAX('TIMSS - Balance por grado'!$I$39:$I$42),0) | H11: =INDEX('TIMSS - Balance por grado'!$C$39:$C$42,MATCH(MIN('TIMSS - Balance por grado'!$I$39:$I$42),'TIMSS - Balance por grado'!$I$39:$I$42,0)) | I11: =ROUND(-MIN('TIMSS - Balance por grado'!$I$39:$I$42),0) | J11: ='TIMSS - Balance por grado'!M43 | K11: =COUNTIF('TIMSS - Balance por grado'!$K$39:$K$42,"En meta")&" de "&ROWS('TIMSS - Balance por grado'!$K$39:$K$42) | L11: ='TIMSS - Conocer-Aplicar-Razonar'!I11 | M11: ='TIMSS - Conocer-Aplicar-Razonar'!L11
A12: Física 10° | B12: TIMSS Advanced 2015 Física | C12: =COUNTIFS('Datos - Temas'!$V$5:$V$1264,$A12) | D12: ='TIMSS - Balance por grado'!N45 | E12: =IF(C12=0,0,D12/C12) | F12: =INDEX('TIMSS - Balance por grado'!$C$45:$C$47,MATCH(MAX('TIMSS - Balance por grado'!$I$45:$I$47),'TIMSS - Balance por grado'!$I$45:$I$47,0)) | G12: =ROUND(MAX('TIMSS - Balance por grado'!$I$45:$I$47),0) | H12: =INDEX('TIMSS - Balance por grado'!$C$45:$C$47,MATCH(MIN('TIMSS - Balance por grado'!$I$45:$I$47),'TIMSS - Balance por grado'!$I$45:$I$47,0)) | I12: =ROUND(-MIN('TIMSS - Balance por grado'!$I$45:$I$47),0) | J12: ='TIMSS - Balance por grado'!M48 | K12: =COUNTIF('TIMSS - Balance por grado'!$K$45:$K$47,"En meta")&" de "&ROWS('TIMSS - Balance por grado'!$K$45:$K$47) | L12: ='TIMSS - Conocer-Aplicar-Razonar'!I12 | M12: ='TIMSS - Conocer-Aplicar-Razonar'!L12
A13: Física 11° | B13: TIMSS Advanced 2015 Física | C13: =COUNTIFS('Datos - Temas'!$V$5:$V$1264,$A13) | D13: ='TIMSS - Balance por grado'!N50 | E13: =IF(C13=0,0,D13/C13) | F13: =INDEX('TIMSS - Balance por grado'!$C$50:$C$52,MATCH(MAX('TIMSS - Balance por grado'!$I$50:$I$52),'TIMSS - Balance por grado'!$I$50:$I$52,0)) | G13: =ROUND(MAX('TIMSS - Balance por grado'!$I$50:$I$52),0) | H13: =INDEX('TIMSS - Balance por grado'!$C$50:$C$52,MATCH(MIN('TIMSS - Balance por grado'!$I$50:$I$52),'TIMSS - Balance por grado'!$I$50:$I$52,0)) | I13: =ROUND(-MIN('TIMSS - Balance por grado'!$I$50:$I$52),0) | J13: ='TIMSS - Balance por grado'!M53 | K13: =COUNTIF('TIMSS - Balance por grado'!$K$50:$K$52,"En meta")&" de "&ROWS('TIMSS - Balance por grado'!$K$50:$K$52) | L13: ='TIMSS - Conocer-Aplicar-Razonar'!I13 | M13: ='TIMSS - Conocer-Aplicar-Razonar'!L13
A15: Por ciclo (comparación acumulada)
A16: Ciclo | B16: Marco de referencia | C16: Temas evaluables | D16: Dominio con mayor FALTANTE | E16: Faltan (temas) | F16: Dominio más SOBRErrepresentado | G16: Sobran (temas) | H16: Temas a agregar sin quitar | I16: Dominios en meta | J16: Objetivos TIMSS del marco | K16: Objetivos cubiertos | L16: % amplitud | M16: Objetivos del marco que la malla NO trabaja | N16: Objetivos cubiertos (2023) | O16: % amplitud (2023) | P16: Dominio con mayor FALTANTE (2023) | Q16: Cambio vs 2023 | R16: % temas ambientales (ref. ≈25 %) | S16: Temas en Investigaciones (principal)
A17: Ciclo 2°–4° | B17: TIMSS 2027 4.° | C17: ='TIMSS - Balance por ciclo'!E6 | D17: =INDEX('TIMSS - Balance por ciclo'!$C$6:$C$8,MATCH(MAX('TIMSS - Balance por ciclo'!$I$6:$I$8),'TIMSS - Balance por ciclo'!$I$6:$I$8,0)) | E17: =ROUND(MAX('TIMSS - Balance por ciclo'!$I$6:$I$8),0) | F17: =INDEX('TIMSS - Balance por ciclo'!$C$6:$C$8,MATCH(MIN('TIMSS - Balance por ciclo'!$I$6:$I$8),'TIMSS - Balance por ciclo'!$I$6:$I$8,0)) | G17: =ROUND(-MIN('TIMSS - Balance por ciclo'!$I$6:$I$8),0) | H17: ='TIMSS - Balance por ciclo'!M9 | I17: =COUNTIF('TIMSS - Balance por ciclo'!$K$6:$K$8,"En meta")&" de "&ROWS('TIMSS - Balance por ciclo'!$K$6:$K$8) | J17: ='TIMSS - Semáforo de objetivos'!C115 | K17: ='TIMSS - Semáforo de objetivos'!D115 | L17: ='TIMSS - Semáforo de objetivos'!E115 | M17: ='TIMSS - Semáforo de objetivos'!F115 | N17: ='Datos - TIMSS 2023'!C110 | O17: ='Datos - TIMSS 2023'!D110 | P17: =INDEX('Datos - TIMSS 2023'!$C$117:$C$119,MATCH(MAX('Datos - TIMSS 2023'!$G$117:$G$119),'Datos - TIMSS 2023'!$G$117:$G$119,0)) | Q17: ="Cubiertos: "&N17&" de "&'Datos - TIMSS 2023'!B110&" (2023) → "&K17&" de "&J17&" (2027) · Mayor faltante: "&P17&" (2023) → "&D17&" (2027)" | R17: ='TIMSS - Medio ambiente'!E16 | S17: ='TIMSS - Investigación'!C15
A18: Ciclo 5°–8° | B18: TIMSS 2027 8.° | C18: ='TIMSS - Balance por ciclo'!E11 | D18: =INDEX('TIMSS - Balance por ciclo'!$C$11:$C$14,MATCH(MAX('TIMSS - Balance por ciclo'!$I$11:$I$14),'TIMSS - Balance por ciclo'!$I$11:$I$14,0)) | E18: =ROUND(MAX('TIMSS - Balance por ciclo'!$I$11:$I$14),0) | F18: =INDEX('TIMSS - Balance por ciclo'!$C$11:$C$14,MATCH(MIN('TIMSS - Balance por ciclo'!$I$11:$I$14),'TIMSS - Balance por ciclo'!$I$11:$I$14,0)) | G18: =ROUND(-MIN('TIMSS - Balance por ciclo'!$I$11:$I$14),0) | H18: ='TIMSS - Balance por ciclo'!M15 | I18: =COUNTIF('TIMSS - Balance por ciclo'!$K$11:$K$14,"En meta")&" de "&ROWS('TIMSS - Balance por ciclo'!$K$11:$K$14) | J18: ='TIMSS - Semáforo de objetivos'!C120 | K18: ='TIMSS - Semáforo de objetivos'!D120 | L18: ='TIMSS - Semáforo de objetivos'!E120 | M18: ='TIMSS - Semáforo de objetivos'!F120 | N18: ='Datos - TIMSS 2023'!C111 | O18: ='Datos - TIMSS 2023'!D111 | P18: =INDEX('Datos - TIMSS 2023'!$C$121:$C$124,MATCH(MAX('Datos - TIMSS 2023'!$G$121:$G$124),'Datos - TIMSS 2023'!$G$121:$G$124,0)) | Q18: ="Cubiertos: "&N18&" de "&'Datos - TIMSS 2023'!B111&" (2023) → "&K18&" de "&J18&" (2027) · Mayor faltante: "&P18&" (2023) → "&D18&" (2027)" | R18: ='TIMSS - Medio ambiente'!E17 | S18: ='TIMSS - Investigación'!C16
A19: Física 10°–11° | B19: TIMSS Advanced 2015 Física | C19: ='TIMSS - Balance por ciclo'!E17 | D19: =INDEX('TIMSS - Balance por ciclo'!$C$17:$C$19,MATCH(MAX('TIMSS - Balance por ciclo'!$I$17:$I$19),'TIMSS - Balance por ciclo'!$I$17:$I$19,0)) | E19: =ROUND(MAX('TIMSS - Balance por ciclo'!$I$17:$I$19),0) | F19: =INDEX('TIMSS - Balance por ciclo'!$C$17:$C$19,MATCH(MIN('TIMSS - Balance por ciclo'!$I$17:$I$19),'TIMSS - Balance por ciclo'!$I$17:$I$19,0)) | G19: =ROUND(-MIN('TIMSS - Balance por ciclo'!$I$17:$I$19),0) | H19: ='TIMSS - Balance por ciclo'!M20 | I19: =COUNTIF('TIMSS - Balance por ciclo'!$K$17:$K$19,"En meta")&" de "&ROWS('TIMSS - Balance por ciclo'!$K$17:$K$19) | J19: ='TIMSS - Semáforo de objetivos'!C124 | K19: ='TIMSS - Semáforo de objetivos'!D124 | L19: ='TIMSS - Semáforo de objetivos'!E124 | M19: ='TIMSS - Semáforo de objetivos'!F124 | N19: ='Datos - TIMSS 2023'!C112 | O19: ='Datos - TIMSS 2023'!D112 | P19: =INDEX('Datos - TIMSS 2023'!$C$131:$C$133,MATCH(MAX('Datos - TIMSS 2023'!$G$131:$G$133),'Datos - TIMSS 2023'!$G$131:$G$133,0)) | Q19: ="Sin cambio de marco: Física sigue con TIMSS Advanced 2015" | R19: — | S19: —
A21: PISA 2025 (7.°, 8.°, 9.° y acumulado 7.°–9.°): 9.° se compara solo con PISA; 7.° y 8.° con los dos marcos (ver Apego TIMSS y PISA)
A22: Grupo | B22: Marco de referencia | C22: Temas totales | D22: Temas sin contenido PISA (la malla los tiene; PISA no los evalúa) | E22: % sin contenido PISA | F22: Sistema PISA con MÁS temas faltantes | G22: Temas que faltan | H22: Sistema PISA con MÁS temas de sobra | I22: Temas que sobran | J22: Temas a AGREGAR, sin quitar, para que todos los sistemas lleguen a su meta | K22: Sistemas en meta | L22: % competencia 3 «Investigar, evaluar y usar información» (meta 24–36 %) | M22: ÍNDICE DE APEGO PISA
A23: 7° | B23: PISA 2025 | C23: =COUNTIFS('Datos - Temas'!$V$5:$V$1264,$A23,'Datos - Temas'!$AK$5:$AK$1264,"<>") | D23: ='PISA - Contenidos'!N6 | E23: =IF(C23=0,0,D23/C23) | F23: =INDEX('PISA - Contenidos'!$C$6:$C$8,MATCH(MAX('PISA - Contenidos'!$I$6:$I$8),'PISA - Contenidos'!$I$6:$I$8,0)) | G23: =ROUND(MAX('PISA - Contenidos'!$I$6:$I$8),0) | H23: =INDEX('PISA - Contenidos'!$C$6:$C$8,MATCH(MIN('PISA - Contenidos'!$I$6:$I$8),'PISA - Contenidos'!$I$6:$I$8,0)) | I23: =ROUND(-MIN('PISA - Contenidos'!$I$6:$I$8),0) | J23: ='PISA - Contenidos'!M9 | K23: =COUNTIF('PISA - Contenidos'!$K$6:$K$8,"En meta")&" de "&ROWS('PISA - Contenidos'!$K$6:$K$8) | L23: ='PISA - Competencias'!H13 | M23: ='Apego TIMSS y PISA'!F20
A24: 8° | B24: PISA 2025 | C24: =COUNTIFS('Datos - Temas'!$V$5:$V$1264,$A24,'Datos - Temas'!$AK$5:$AK$1264,"<>") | D24: ='PISA - Contenidos'!N11 | E24: =IF(C24=0,0,D24/C24) | F24: =INDEX('PISA - Contenidos'!$C$11:$C$13,MATCH(MAX('PISA - Contenidos'!$I$11:$I$13),'PISA - Contenidos'!$I$11:$I$13,0)) | G24: =ROUND(MAX('PISA - Contenidos'!$I$11:$I$13),0) | H24: =INDEX('PISA - Contenidos'!$C$11:$C$13,MATCH(MIN('PISA - Contenidos'!$I$11:$I$13),'PISA - Contenidos'!$I$11:$I$13,0)) | I24: =ROUND(-MIN('PISA - Contenidos'!$I$11:$I$13),0) | J24: ='PISA - Contenidos'!M14 | K24: =COUNTIF('PISA - Contenidos'!$K$11:$K$13,"En meta")&" de "&ROWS('PISA - Contenidos'!$K$11:$K$13) | L24: ='PISA - Competencias'!H14 | M24: ='Apego TIMSS y PISA'!F21
A25: 9° | B25: PISA 2025 | C25: =COUNTIFS('Datos - Temas'!$V$5:$V$1264,$A25,'Datos - Temas'!$AK$5:$AK$1264,"<>") | D25: ='PISA - Contenidos'!N16 | E25: =IF(C25=0,0,D25/C25) | F25: =INDEX('PISA - Contenidos'!$C$16:$C$18,MATCH(MAX('PISA - Contenidos'!$I$16:$I$18),'PISA - Contenidos'!$I$16:$I$18,0)) | G25: =ROUND(MAX('PISA - Contenidos'!$I$16:$I$18),0) | H25: =INDEX('PISA - Contenidos'!$C$16:$C$18,MATCH(MIN('PISA - Contenidos'!$I$16:$I$18),'PISA - Contenidos'!$I$16:$I$18,0)) | I25: =ROUND(-MIN('PISA - Contenidos'!$I$16:$I$18),0) | J25: ='PISA - Contenidos'!M19 | K25: =COUNTIF('PISA - Contenidos'!$K$16:$K$18,"En meta")&" de "&ROWS('PISA - Contenidos'!$K$16:$K$18) | L25: ='PISA - Competencias'!H15 | M25: ='Apego TIMSS y PISA'!F22
A26: Ciclo 7°–9° | B26: PISA 2025 | C26: =COUNTIFS('Datos - Temas'!$AV$5:$AV$1264,$A26,'Datos - Temas'!$AK$5:$AK$1264,"<>") | D26: ='PISA - Contenidos'!N21 | E26: =IF(C26=0,0,D26/C26) | F26: =INDEX('PISA - Contenidos'!$C$21:$C$23,MATCH(MAX('PISA - Contenidos'!$I$21:$I$23),'PISA - Contenidos'!$I$21:$I$23,0)) | G26: =ROUND(MAX('PISA - Contenidos'!$I$21:$I$23),0) | H26: =INDEX('PISA - Contenidos'!$C$21:$C$23,MATCH(MIN('PISA - Contenidos'!$I$21:$I$23),'PISA - Contenidos'!$I$21:$I$23,0)) | I26: =ROUND(-MIN('PISA - Contenidos'!$I$21:$I$23),0) | J26: ='PISA - Contenidos'!M24 | K26: =COUNTIF('PISA - Contenidos'!$K$21:$K$23,"En meta")&" de "&ROWS('PISA - Contenidos'!$K$21:$K$23) | L26: ='PISA - Competencias'!H16 | M26: ='Apego TIMSS y PISA'!F23
A28: Cómo leer cada columna
A29: • Temas SIN objetivo en el marco: temas que la malla SÍ enseña pero que el marco no evalúa (p. ej. medición general, electrónica digital, gestión de riesgos). No son un error: indican cuánto de la malla va más allá de la prueba. Lo contrario —objetivos del marco que la malla NO trabaja— está en «Objetivos del marco que la malla NO trabaja».
A30: • Dominio TIMSS con MÁS temas faltantes: de los dominios de TIMSS (Biología, Química, Física, Tierra), el que más se queda por debajo del peso que TIMSS le da en la prueba. «Temas que faltan» = cuántos temas habría que pasar a ese dominio, con el mismo total de temas, para llegar a la meta.
A31: • Temas a AGREGAR sin quitar: si no se quiere quitar ningún tema, cuántos habría que SUMAR en total para que todos los dominios lleguen a su meta. Ejemplo: con 100 temas, 60 % Biología y meta 45 %, habría que llegar a 60 ÷ 0,45 ≈ 133 temas, sumando 33 en los otros dominios. Por eso suele ser una cifra alta: la alternativa realista (fusionar e insertar con el mismo total) está en la hoja Presupuesto de temas.
A32: • Dominios en meta: cuántos dominios están a ±5 puntos porcentuales de su meta (tolerancia editable en TIMSS - Balance por grado, celda H2).
A33: • ÍNDICE DE APEGO: parte del reparto de la malla que ya coincide con el del marco (100 % = igual). Detalle y escenarios TIMSS/PISA en Apego TIMSS y PISA.
A35: Cómo se calcula: Todo es fórmula sobre Temas. Balance = reparto de temas por dominio vs. metas TIMSS. Amplitud = objetivos TIMSS que aparecen. Profundidad cognitiva = Conocer/Aplicar/Razonar. Ver «Inicio» para el proceso completo.

Sheet Apego TIMSS y PISA
A1: Apego a los marcos: índice por grado y escenarios TIMSS / PISA para 7.° y 8.°
A2: ="TIMSS 2027 y PISA 2025"&" "&IF(MIN(F17,F18,F23)>=$H$4,"BIEN · ","OJO · ")&"Acumulado: TIMSS 4.° "&FIXED((F17)*100,0)&" %"&", TIMSS 8.° "&FIXED((F18)*100,0)&" %"&", PISA "&FIXED((F23)*100,0)&" %"&" de apego (alto = 85 % o más)."&" "&"OJO · Grado más flojo en TIMSS: "&SUBSTITUTE(INDEX($A$8:$A$14,MATCH(MIN($F$8:$F$14),$F$8:$F$14,0)),"°",".°")&" ("&FIXED((MIN($F$8:$F$14))*100,0)&" %"&"). En PISA: 9.° ("&FIXED((F22)*100,0)&" %"&")."&" "&"● 7.° y 8.° se miden con los dos marcos: el peso de PISA se elige en la celda E4 (hoy "&FIXED((E4)*100,0)&" %"&")."
A4: Peso de PISA en 7.° y 8.° (0 % = solo TIMSS): | E4: 0.5 | G4: Lectura: alto desde | H4: 0.85 | I4: medio desde | J4: 0.7
A6: A · Índice de apego por grado y ciclo
A7: Grado / ciclo | B7: Marco | C7: Coincidencia de balance | D7: Coincidencia cognitiva | E7: Amplitud (ciclo) | F7: ÍNDICE DE APEGO | G7: Lectura
A8: 2° | B8: TIMSS 2027 4.° | C8: ='TIMSS - Balance por grado'!O9 | D8: ='TIMSS - Conocer-Aplicar-Razonar'!O5 | E8: — | F8: =AVERAGE(C8:E8) | G8: =IF(F8>=$H$4,"Alto",IF(F8>=$J$4,"Medio","Bajo: revisar"))
A9: 3° | B9: TIMSS 2027 4.° | C9: ='TIMSS - Balance por grado'!O14 | D9: ='TIMSS - Conocer-Aplicar-Razonar'!O6 | E9: — | F9: =AVERAGE(C9:E9) | G9: =IF(F9>=$H$4,"Alto",IF(F9>=$J$4,"Medio","Bajo: revisar"))
A10: 4° | B10: TIMSS 2027 4.° | C10: ='TIMSS - Balance por grado'!O19 | D10: ='TIMSS - Conocer-Aplicar-Razonar'!O7 | E10: — | F10: =AVERAGE(C10:E10) | G10: =IF(F10>=$H$4,"Alto",IF(F10>=$J$4,"Medio","Bajo: revisar"))
A11: 5° | B11: TIMSS 2027 8.° | C11: ='TIMSS - Balance por grado'!O25 | D11: ='TIMSS - Conocer-Aplicar-Razonar'!O8 | E11: — | F11: =AVERAGE(C11:E11) | G11: =IF(F11>=$H$4,"Alto",IF(F11>=$J$4,"Medio","Bajo: revisar"))
A12: 6° | B12: TIMSS 2027 8.° | C12: ='TIMSS - Balance por grado'!O31 | D12: ='TIMSS - Conocer-Aplicar-Razonar'!O9 | E12: — | F12: =AVERAGE(C12:E12) | G12: =IF(F12>=$H$4,"Alto",IF(F12>=$J$4,"Medio","Bajo: revisar"))
A13: 7° | B13: TIMSS 2027 8.° | C13: ='TIMSS - Balance por grado'!O37 | D13: ='TIMSS - Conocer-Aplicar-Razonar'!O10 | E13: — | F13: =AVERAGE(C13:E13) | G13: =IF(F13>=$H$4,"Alto",IF(F13>=$J$4,"Medio","Bajo: revisar"))
A14: 8° | B14: TIMSS 2027 8.° | C14: ='TIMSS - Balance por grado'!O43 | D14: ='TIMSS - Conocer-Aplicar-Razonar'!O11 | E14: — | F14: =AVERAGE(C14:E14) | G14: =IF(F14>=$H$4,"Alto",IF(F14>=$J$4,"Medio","Bajo: revisar"))
A15: Física 10° | B15: TIMSS Advanced 2015 Física | C15: ='TIMSS - Balance por grado'!O48 | D15: ='TIMSS - Conocer-Aplicar-Razonar'!O12 | E15: — | F15: =AVERAGE(C15:E15) | G15: =IF(F15>=$H$4,"Alto",IF(F15>=$J$4,"Medio","Bajo: revisar"))
A16: Física 11° | B16: TIMSS Advanced 2015 Física | C16: ='TIMSS - Balance por grado'!O53 | D16: ='TIMSS - Conocer-Aplicar-Razonar'!O13 | E16: — | F16: =AVERAGE(C16:E16) | G16: =IF(F16>=$H$4,"Alto",IF(F16>=$J$4,"Medio","Bajo: revisar"))
A17: Ciclo 2°–4° | B17: TIMSS 2027 4.° | C17: ='TIMSS - Balance por ciclo'!O9 | D17: =1-(ABS(SUMIFS('Datos - Temas'!$S$5:$S$1264,'Datos - Temas'!$W$5:$W$1264,$A17)/COUNTIFS('Datos - Temas'!$W$5:$W$1264,$A17)-0.35)+ABS(SUMIFS('Datos - Temas'!$T$5:$T$1264,'Datos - Temas'!$W$5:$W$1264,$A17)/COUNTIFS('Datos - Temas'!$W$5:$W$1264,$A17)-0.4)+ABS(SUMIFS('Datos - Temas'!$U$5:$U$1264,'Datos - Temas'!$W$5:$W$1264,$A17)/COUNTIFS('Datos - Temas'!$W$5:$W$1264,$A17)-0.25))/2 | E17: ='TIMSS - Semáforo de objetivos'!E115 | F17: =AVERAGE(C17:E17) | G17: =IF(F17>=$H$4,"Alto",IF(F17>=$J$4,"Medio","Bajo: revisar"))
A18: Ciclo 5°–8° | B18: TIMSS 2027 8.° | C18: ='TIMSS - Balance por ciclo'!O15 | D18: =1-(ABS(SUMIFS('Datos - Temas'!$S$5:$S$1264,'Datos - Temas'!$W$5:$W$1264,$A18)/COUNTIFS('Datos - Temas'!$W$5:$W$1264,$A18)-0.35)+ABS(SUMIFS('Datos - Temas'!$T$5:$T$1264,'Datos - Temas'!$W$5:$W$1264,$A18)/COUNTIFS('Datos - Temas'!$W$5:$W$1264,$A18)-0.35)+ABS(SUMIFS('Datos - Temas'!$U$5:$U$1264,'Datos - Temas'!$W$5:$W$1264,$A18)/COUNTIFS('Datos - Temas'!$W$5:$W$1264,$A18)-0.3))/2 | E18: ='TIMSS - Semáforo de objetivos'!E120 | F18: =AVERAGE(C18:E18) | G18: =IF(F18>=$H$4,"Alto",IF(F18>=$J$4,"Medio","Bajo: revisar"))
A19: Física 10°–11° | B19: TIMSS Advanced 2015 Física | C19: ='TIMSS - Balance por ciclo'!O20 | D19: =1-(ABS(SUMIFS('Datos - Temas'!$S$5:$S$1264,'Datos - Temas'!$W$5:$W$1264,$A19)/COUNTIFS('Datos - Temas'!$W$5:$W$1264,$A19)-0.3)+ABS(SUMIFS('Datos - Temas'!$T$5:$T$1264,'Datos - Temas'!$W$5:$W$1264,$A19)/COUNTIFS('Datos - Temas'!$W$5:$W$1264,$A19)-0.4)+ABS(SUMIFS('Datos - Temas'!$U$5:$U$1264,'Datos - Temas'!$W$5:$W$1264,$A19)/COUNTIFS('Datos - Temas'!$W$5:$W$1264,$A19)-0.3))/2 | E19: ='TIMSS - Semáforo de objetivos'!E124 | F19: =AVERAGE(C19:E19) | G19: =IF(F19>=$H$4,"Alto",IF(F19>=$J$4,"Medio","Bajo: revisar"))
A20: 7° · PISA | B20: PISA 2025 | C20: ='PISA - Contenidos'!O9 | D20: ='PISA - Competencias'!L13 | E20: — | F20: =AVERAGE(C20:E20) | G20: =IF(F20>=$H$4,"Alto",IF(F20>=$J$4,"Medio","Bajo: revisar"))
A21: 8° · PISA | B21: PISA 2025 | C21: ='PISA - Contenidos'!O14 | D21: ='PISA - Competencias'!L14 | E21: — | F21: =AVERAGE(C21:E21) | G21: =IF(F21>=$H$4,"Alto",IF(F21>=$J$4,"Medio","Bajo: revisar"))
A22: 9° · PISA | B22: PISA 2025 | C22: ='PISA - Contenidos'!O19 | D22: ='PISA - Competencias'!L15 | E22: — | F22: =AVERAGE(C22:E22) | G22: =IF(F22>=$H$4,"Alto",IF(F22>=$J$4,"Medio","Bajo: revisar"))
A23: Ciclo 7°–9° · PISA | B23: PISA 2025 | C23: ='PISA - Contenidos'!O24 | D23: ='PISA - Competencias'!L16 | E23: ='PISA - Contenidos'!D55 | F23: =AVERAGE(C23:E23) | G23: =IF(F23>=$H$4,"Alto",IF(F23>=$J$4,"Medio","Bajo: revisar"))
A24: 7° · escenario elegido | B24: Mezcla según el peso de E4 | F24: =(1-$E$4)*F13+$E$4*F20 | G24: =IF(F24>=$H$4,"Alto",IF(F24>=$J$4,"Medio","Bajo: revisar"))
A25: 8° · escenario elegido | B25: Mezcla según el peso de E4 | F25: =(1-$E$4)*F14+$E$4*F21 | G25: =IF(F25>=$H$4,"Alto",IF(F25>=$J$4,"Medio","Bajo: revisar"))
A28: B · Escenarios para 7.° y 8.°: ¿cuántos temas faltan (+) o sobran (−) en cada sistema según el peso de cada marco?
A29: El eje común son los 3 sistemas de PISA. Las metas de TIMSS 8.° se agrupan igual: Sistemas físicos = Química 20 % + Física 25 %; vivos = Biología 35 %; Tierra y espacio = Ciencias de la Tierra 20 %. En cada escenario: meta = (1 − p)·TIMSS + p·PISA y % actual = (1 − p)·actual TIMSS + p·actual PISA (cada marco con su propia clasificación). Brecha (temas) = (meta − actual) × temas evaluables.
A30: Grado | B30: Sistema | C30: Meta TIMSS (agrupada) | D30: Meta PISA | E30: % actual TIMSS | F30: % actual PISA | G30: 100 % TIMSS · brecha (temas) | H30: 50 / 50 · brecha (temas) | I30: 100 % PISA · brecha (temas) | J30: Personalizado · brecha (temas) | K30: Evaluables TIMSS | L30: Evaluables PISA
A31: Peso de PISA → | G31: 0 | H31: 0.5 | I31: 1 | J31: =$E$4
A32: 7° | B32: Sistemas físicos | C32: 0.45 | D32: 0.37 | E32: =IF(K32=0,0,(COUNTIFS('Datos - Temas'!$V$5:$V$1264,$A32,'Datos - Temas'!$M$5:$M$1264,"Química")+COUNTIFS('Datos - Temas'!$V$5:$V$1264,$A32,'Datos - Temas'!$M$5:$M$1264,"Física"))/K32) | F32: =IF(L32=0,0,COUNTIFS('Datos - Temas'!$V$5:$V$1264,$A32,'Datos - Temas'!$AM$5:$AM$1264,$B32)/L32) | G32: =((1-G$31)*C32+G$31*D32-((1-G$31)*E32+G$31*F32))*((1-G$31)*K32+G$31*L32) | H32: =((1-H$31)*C32+H$31*D32-((1-H$31)*E32+H$31*F32))*((1-H$31)*K32+H$31*L32) | I32: =((1-I$31)*C32+I$31*D32-((1-I$31)*E32+I$31*F32))*((1-I$31)*K32+I$31*L32) | J32: =((1-J$31)*C32+J$31*D32-((1-J$31)*E32+J$31*F32))*((1-J$31)*K32+J$31*L32) | K32: =COUNTIFS('Datos - Temas'!$V$5:$V$1264,$A32,'Datos - Temas'!$C$5:$C$1264,"Ciencias")-COUNTIFS('Datos - Temas'!$V$5:$V$1264,$A32,'Datos - Temas'!$K$5:$K$1264,"FUERA")-COUNTIFS('Datos - Temas'!$V$5:$V$1264,$A32,'Datos - Temas'!$K$5:$K$1264,"PENDIENTE") | L32: =COUNTIFS('Datos - Temas'!$V$5:$V$1264,$A32,'Datos - Temas'!$AK$5:$AK$1264,"<>")-COUNTIFS('Datos - Temas'!$V$5:$V$1264,$A32,'Datos - Temas'!$AK$5:$AK$1264,"FUERA")
A33: 7° | B33: Sistemas vivos | C33: 0.35 | D33: 0.37 | E33: =IF(K33=0,0,(COUNTIFS('Datos - Temas'!$V$5:$V$1264,$A33,'Datos - Temas'!$M$5:$M$1264,"Biología"))/K33) | F33: =IF(L33=0,0,COUNTIFS('Datos - Temas'!$V$5:$V$1264,$A33,'Datos - Temas'!$AM$5:$AM$1264,$B33)/L33) | G33: =((1-G$31)*C33+G$31*D33-((1-G$31)*E33+G$31*F33))*((1-G$31)*K33+G$31*L33) | H33: =((1-H$31)*C33+H$31*D33-((1-H$31)*E33+H$31*F33))*((1-H$31)*K33+H$31*L33) | I33: =((1-I$31)*C33+I$31*D33-((1-I$31)*E33+I$31*F33))*((1-I$31)*K33+I$31*L33) | J33: =((1-J$31)*C33+J$31*D33-((1-J$31)*E33+J$31*F33))*((1-J$31)*K33+J$31*L33) | K33: =COUNTIFS('Datos - Temas'!$V$5:$V$1264,$A33,'Datos - Temas'!$C$5:$C$1264,"Ciencias")-COUNTIFS('Datos - Temas'!$V$5:$V$1264,$A33,'Datos - Temas'!$K$5:$K$1264,"FUERA")-COUNTIFS('Datos - Temas'!$V$5:$V$1264,$A33,'Datos - Temas'!$K$5:$K$1264,"PENDIENTE") | L33: =COUNTIFS('Datos - Temas'!$V$5:$V$1264,$A33,'Datos - Temas'!$AK$5:$AK$1264,"<>")-COUNTIFS('Datos - Temas'!$V$5:$V$1264,$A33,'Datos - Temas'!$AK$5:$AK$1264,"FUERA")
A34: 7° | B34: Sistemas de la Tierra y el espacio | C34: 0.2 | D34: 0.26 | E34: =IF(K34=0,0,(COUNTIFS('Datos - Temas'!$V$5:$V$1264,$A34,'Datos - Temas'!$M$5:$M$1264,"Ciencias de la Tierra"))/K34) | F34: =IF(L34=0,0,COUNTIFS('Datos - Temas'!$V$5:$V$1264,$A34,'Datos - Temas'!$AM$5:$AM$1264,$B34)/L34) | G34: =((1-G$31)*C34+G$31*D34-((1-G$31)*E34+G$31*F34))*((1-G$31)*K34+G$31*L34) | H34: =((1-H$31)*C34+H$31*D34-((1-H$31)*E34+H$31*F34))*((1-H$31)*K34+H$31*L34) | I34: =((1-I$31)*C34+I$31*D34-((1-I$31)*E34+I$31*F34))*((1-I$31)*K34+I$31*L34) | J34: =((1-J$31)*C34+J$31*D34-((1-J$31)*E34+J$31*F34))*((1-J$31)*K34+J$31*L34) | K34: =COUNTIFS('Datos - Temas'!$V$5:$V$1264,$A34,'Datos - Temas'!$C$5:$C$1264,"Ciencias")-COUNTIFS('Datos - Temas'!$V$5:$V$1264,$A34,'Datos - Temas'!$K$5:$K$1264,"FUERA")-COUNTIFS('Datos - Temas'!$V$5:$V$1264,$A34,'Datos - Temas'!$K$5:$K$1264,"PENDIENTE") | L34: =COUNTIFS('Datos - Temas'!$V$5:$V$1264,$A34,'Datos - Temas'!$AK$5:$AK$1264,"<>")-COUNTIFS('Datos - Temas'!$V$5:$V$1264,$A34,'Datos - Temas'!$AK$5:$AK$1264,"FUERA")
B35: Coincidencia de balance | G35: =1-(ABS((1-G$31)*C32+G$31*D32-((1-G$31)*E32+G$31*F32))+ABS((1-G$31)*C33+G$31*D33-((1-G$31)*E33+G$31*F33))+ABS((1-G$31)*C34+G$31*D34-((1-G$31)*E34+G$31*F34)))/2 | H35: =1-(ABS((1-H$31)*C32+H$31*D32-((1-H$31)*E32+H$31*F32))+ABS((1-H$31)*C33+H$31*D33-((1-H$31)*E33+H$31*F33))+ABS((1-H$31)*C34+H$31*D34-((1-H$31)*E34+H$31*F34)))/2 | I35: =1-(ABS((1-I$31)*C32+I$31*D32-((1-I$31)*E32+I$31*F32))+ABS((1-I$31)*C33+I$31*D33-((1-I$31)*E33+I$31*F33))+ABS((1-I$31)*C34+I$31*D34-((1-I$31)*E34+I$31*F34)))/2 | J35: =1-(ABS((1-J$31)*C32+J$31*D32-((1-J$31)*E32+J$31*F32))+ABS((1-J$31)*C33+J$31*D33-((1-J$31)*E33+J$31*F33))+ABS((1-J$31)*C34+J$31*D34-((1-J$31)*E34+J$31*F34)))/2
B36: Índice de apego del escenario | G36: =(1-G$31)*$F$13+G$31*$F$20 | H36: =(1-H$31)*$F$13+H$31*$F$20 | I36: =(1-I$31)*$F$13+I$31*$F$20 | J36: =(1-J$31)*$F$13+J$31*$F$20
A38: 8° | B38: Sistemas físicos | C38: 0.45 | D38: 0.37 | E38: =IF(K38=0,0,(COUNTIFS('Datos - Temas'!$V$5:$V$1264,$A38,'Datos - Temas'!$M$5:$M$1264,"Química")+COUNTIFS('Datos - Temas'!$V$5:$V$1264,$A38,'Datos - Temas'!$M$5:$M$1264,"Física"))/K38) | F38: =IF(L38=0,0,COUNTIFS('Datos - Temas'!$V$5:$V$1264,$A38,'Datos - Temas'!$AM$5:$AM$1264,$B38)/L38) | G38: =((1-G$31)*C38+G$31*D38-((1-G$31)*E38+G$31*F38))*((1-G$31)*K38+G$31*L38) | H38: =((1-H$31)*C38+H$31*D38-((1-H$31)*E38+H$31*F38))*((1-H$31)*K38+H$31*L38) | I38: =((1-I$31)*C38+I$31*D38-((1-I$31)*E38+I$31*F38))*((1-I$31)*K38+I$31*L38) | J38: =((1-J$31)*C38+J$31*D38-((1-J$31)*E38+J$31*F38))*((1-J$31)*K38+J$31*L38) | K38: =COUNTIFS('Datos - Temas'!$V$5:$V$1264,$A38,'Datos - Temas'!$C$5:$C$1264,"Ciencias")-COUNTIFS('Datos - Temas'!$V$5:$V$1264,$A38,'Datos - Temas'!$K$5:$K$1264,"FUERA")-COUNTIFS('Datos - Temas'!$V$5:$V$1264,$A38,'Datos - Temas'!$K$5:$K$1264,"PENDIENTE") | L38: =COUNTIFS('Datos - Temas'!$V$5:$V$1264,$A38,'Datos - Temas'!$AK$5:$AK$1264,"<>")-COUNTIFS('Datos - Temas'!$V$5:$V$1264,$A38,'Datos - Temas'!$AK$5:$AK$1264,"FUERA")
A39: 8° | B39: Sistemas vivos | C39: 0.35 | D39: 0.37 | E39: =IF(K39=0,0,(COUNTIFS('Datos - Temas'!$V$5:$V$1264,$A39,'Datos - Temas'!$M$5:$M$1264,"Biología"))/K39) | F39: =IF(L39=0,0,COUNTIFS('Datos - Temas'!$V$5:$V$1264,$A39,'Datos - Temas'!$AM$5:$AM$1264,$B39)/L39) | G39: =((1-G$31)*C39+G$31*D39-((1-G$31)*E39+G$31*F39))*((1-G$31)*K39+G$31*L39) | H39: =((1-H$31)*C39+H$31*D39-((1-H$31)*E39+H$31*F39))*((1-H$31)*K39+H$31*L39) | I39: =((1-I$31)*C39+I$31*D39-((1-I$31)*E39+I$31*F39))*((1-I$31)*K39+I$31*L39) | J39: =((1-J$31)*C39+J$31*D39-((1-J$31)*E39+J$31*F39))*((1-J$31)*K39+J$31*L39) | K39: =COUNTIFS('Datos - Temas'!$V$5:$V$1264,$A39,'Datos - Temas'!$C$5:$C$1264,"Ciencias")-COUNTIFS('Datos - Temas'!$V$5:$V$1264,$A39,'Datos - Temas'!$K$5:$K$1264,"FUERA")-COUNTIFS('Datos - Temas'!$V$5:$V$1264,$A39,'Datos - Temas'!$K$5:$K$1264,"PENDIENTE") | L39: =COUNTIFS('Datos - Temas'!$V$5:$V$1264,$A39,'Datos - Temas'!$AK$5:$AK$1264,"<>")-COUNTIFS('Datos - Temas'!$V$5:$V$1264,$A39,'Datos - Temas'!$AK$5:$AK$1264,"FUERA")
A40: 8° | B40: Sistemas de la Tierra y el espacio | C40: 0.2 | D40: 0.26 | E40: =IF(K40=0,0,(COUNTIFS('Datos - Temas'!$V$5:$V$1264,$A40,'Datos - Temas'!$M$5:$M$1264,"Ciencias de la Tierra"))/K40) | F40: =IF(L40=0,0,COUNTIFS('Datos - Temas'!$V$5:$V$1264,$A40,'Datos - Temas'!$AM$5:$AM$1264,$B40)/L40) | G40: =((1-G$31)*C40+G$31*D40-((1-G$31)*E40+G$31*F40))*((1-G$31)*K40+G$31*L40) | H40: =((1-H$31)*C40+H$31*D40-((1-H$31)*E40+H$31*F40))*((1-H$31)*K40+H$31*L40) | I40: =((1-I$31)*C40+I$31*D40-((1-I$31)*E40+I$31*F40))*((1-I$31)*K40+I$31*L40) | J40: =((1-J$31)*C40+J$31*D40-((1-J$31)*E40+J$31*F40))*((1-J$31)*K40+J$31*L40) | K40: =COUNTIFS('Datos - Temas'!$V$5:$V$1264,$A40,'Datos - Temas'!$C$5:$C$1264,"Ciencias")-COUNTIFS('Datos - Temas'!$V$5:$V$1264,$A40,'Datos - Temas'!$K$5:$K$1264,"FUERA")-COUNTIFS('Datos - Temas'!$V$5:$V$1264,$A40,'Datos - Temas'!$K$5:$K$1264,"PENDIENTE") | L40: =COUNTIFS('Datos - Temas'!$V$5:$V$1264,$A40,'Datos - Temas'!$AK$5:$AK$1264,"<>")-COUNTIFS('Datos - Temas'!$V$5:$V$1264,$A40,'Datos - Temas'!$AK$5:$AK$1264,"FUERA")
B41: Coincidencia de balance | G41: =1-(ABS((1-G$31)*C38+G$31*D38-((1-G$31)*E38+G$31*F38))+ABS((1-G$31)*C39+G$31*D39-((1-G$31)*E39+G$31*F39))+ABS((1-G$31)*C40+G$31*D40-((1-G$31)*E40+G$31*F40)))/2 | H41: =1-(ABS((1-H$31)*C38+H$31*D38-((1-H$31)*E38+H$31*F38))+ABS((1-H$31)*C39+H$31*D39-((1-H$31)*E39+H$31*F39))+ABS((1-H$31)*C40+H$31*D40-((1-H$31)*E40+H$31*F40)))/2 | I41: =1-(ABS((1-I$31)*C38+I$31*D38-((1-I$31)*E38+I$31*F38))+ABS((1-I$31)*C39+I$31*D39-((1-I$31)*E39+I$31*F39))+ABS((1-I$31)*C40+I$31*D40-((1-I$31)*E40+I$31*F40)))/2 | J41: =1-(ABS((1-J$31)*C38+J$31*D38-((1-J$31)*E38+J$31*F38))+ABS((1-J$31)*C39+J$31*D39-((1-J$31)*E39+J$31*F39))+ABS((1-J$31)*C40+J$31*D40-((1-J$31)*E40+J$31*F40)))/2
B42: Índice de apego del escenario | G42: =(1-G$31)*$F$14+G$31*$F$21 | H42: =(1-H$31)*$F$14+H$31*$F$21 | I42: =(1-I$31)*$F$14+I$31*$F$21 | J42: =(1-J$31)*$F$14+J$31*$F$21
A45: C · Cómo usar los escenarios (recomendación)
A46: 1. Los tres escenarios pedidos (100 % TIMSS, 50/50, 100 % PISA) están lado a lado; la columna «Personalizado» toma el peso de la celda E4, para probar cualquier mezcla (p. ej. 70 % PISA).
A47: 2. Mezclar METAS solo tiene sentido en un eje común (los 3 sistemas). Las metas cognitivas NO se mezclan: TIMSS mide Conocer/Aplicar/Razonar y PISA tres competencias distintas; por eso el escenario mezcla los ÍNDICES de apego, no las metas cognitivas.
...

Sheet Presupuesto de temas
A1: Presupuesto de temas: qué insertar y qué fusionar para acercarse a las metas SIN aumentar el número de temas
A2: ="TIMSS 2027 (2.°–8.°) y PISA 2025 (7.°–9.°)"&" "&"● El total de temas no cambia: cada tema nuevo se paga uniendo dos temas que se repiten."&" "&"● TIMSS 2.°–4.°: "&FIXED(G9+H9,0)&" temas nuevos a cambio de "&FIXED(J9,0)&" uniones de temas repetidos. TIMSS 5.°–8.°: ya equilibrado; solo "&FIXED(G15+H15,0)&" tema nuevo (un objetivo que nadie enseña)."&" "&"● PISA 7.°–9.°: "&FIXED(G20+H20,0)&" temas nuevos de biología y Tierra a cambio de "&FIXED(J20,0)&" uniones en física y química."&" "&"→ Filtra «¿Entra en el presupuesto?» = Sí y anota tu decisión en la última columna."
A3: Se trabaja por CICLO y no por grado: la meta del marco es para lo acumulado, y por grado salen brechas grandes que se compensan entre sí (p. ej. 5.°–8.°: Biología +19 en 5.° y −15 en 7.°, que se resuelve reubicando, no insertando y fusionando). 7.° y 8.° aparecen en el ciclo TIMSS 5.°–8.° y en el PISA 7.°–9.°: según el peso elegido en Apego TIMSS y PISA, seguir uno u otro bloque.
A5: Clave | B5: Ciclo | C5: Marco | D5: Área | E5: Brecha del ciclo (temas) | F5: Estado | G5: Inserciones por balance | H5: Inserciones por cobertura | I5: Temas a liberar con fusiones | J5: Temas que liberan las fusiones elegidas | K5: Saldo (insertados − liberados)
A6: 2-4|Biología | B6: Ciclo 2°–4° | C6: TIMSS 2027 4.° | D6: Biología | E6: ='TIMSS - Balance por ciclo'!I6 | F6: ='TIMSS - Balance por ciclo'!K6 | G6: =IF(COUNTIF($F$6:$F$8,"En meta")=ROWS($F$6:$F$8),0,MAX(0,ROUND(E6,0))) | H6: =COUNTIFS($B$24:$B$191,A6,$D$24:$D$191,"insertar",$E$24:$E$191,"cobertura") | I6: =IF(COUNTIF($F$6:$F$8,"En meta")=ROWS($F$6:$F$8),0,MAX(0,ROUND(-E6,0)))+H6 | J6: =SUMIFS($O$24:$O$191,$B$24:$B$191,A6,$D$24:$D$191,"fusionar",$P$24:$P$191,"Sí") | K6: =G6+H6-J6
A7: 2-4|Ciencias físicas | B7: Ciclo 2°–4° | C7: TIMSS 2027 4.° | D7: Ciencias físicas | E7: ='TIMSS - Balance por ciclo'!I7 | F7: ='TIMSS - Balance por ciclo'!K7 | G7: =IF(COUNTIF($F$6:$F$8,"En meta")=ROWS($F$6:$F$8),0,MAX(0,ROUND(E7,0))) | H7: =COUNTIFS($B$24:$B$191,A7,$D$24:$D$191,"insertar",$E$24:$E$191,"cobertura") | I7: =IF(COUNTIF($F$6:$F$8,"En meta")=ROWS($F$6:$F$8),0,MAX(0,ROUND(-E7,0)))+H7 | J7: =SUMIFS($O$24:$O$191,$B$24:$B$191,A7,$D$24:$D$191,"fusionar",$P$24:$P$191,"Sí") | K7: =G7+H7-J7
A8: 2-4|Ciencias de la Tierra | B8: Ciclo 2°–4° | C8: TIMSS 2027 4.° | D8: Ciencias de la Tierra | E8: ='TIMSS - Balance por ciclo'!I8 | F8: ='TIMSS - Balance por ciclo'!K8 | G8: =IF(COUNTIF($F$6:$F$8,"En meta")=ROWS($F$6:$F$8),0,MAX(0,ROUND(E8,0))) | H8: =COUNTIFS($B$24:$B$191,A8,$D$24:$D$191,"insertar",$E$24:$E$191,"cobertura") | I8: =IF(COUNTIF($F$6:$F$8,"En meta")=ROWS($F$6:$F$8),0,MAX(0,ROUND(-E8,0)))+H8 | J8: =SUMIFS($O$24:$O$191,$B$24:$B$191,A8,$D$24:$D$191,"fusionar",$P$24:$P$191,"Sí") | K8: =G8+H8-J8
D9: Total Ciclo 2°–4° | G9: =SUM(G6:G8) | H9: =SUM(H6:H8) | I9: =SUM(I6:I8) | J9: =SUM(J6:J8) | K9: =SUM(K6:K8)
A11: 5-8|Biología | B11: Ciclo 5°–8° | C11: TIMSS 2027 8.° | D11: Biología | E11: ='TIMSS - Balance por ciclo'!I11 | F11: ='TIMSS - Balance por ciclo'!K11 | G11: =IF(COUNTIF($F$11:$F$14,"En meta")=ROWS($F$11:$F$14),0,MAX(0,ROUND(E11,0))) | H11: =COUNTIFS($B$24:$B$191,A11,$D$24:$D$191,"insertar",$E$24:$E$191,"cobertura") | I11: =IF(COUNTIF($F$11:$F$14,"En meta")=ROWS($F$11:$F$14),0,MAX(0,ROUND(-E11,0)))+H11 | J11: =SUMIFS($O$24:$O$191,$B$24:$B$191,A11,$D$24:$D$191,"fusionar",$P$24:$P$191,"Sí") | K11: =G11+H11-J11
A12: 5-8|Química | B12: Ciclo 5°–8° | C12: TIMSS 2027 8.° | D12: Química | E12: ='TIMSS - Balance por ciclo'!I12 | F12: ='TIMSS - Balance por ciclo'!K12 | G12: =IF(COUNTIF($F$11:$F$14,"En meta")=ROWS($F$11:$F$14),0,MAX(0,ROUND(E12,0))) | H12: =COUNTIFS($B$24:$B$191,A12,$D$24:$D$191,"insertar",$E$24:$E$191,"cobertura") | I12: =IF(COUNTIF($F$11:$F$14,"En meta")=ROWS($F$11:$F$14),0,MAX(0,ROUND(-E12,0)))+H12 | J12: =SUMIFS($O$24:$O$191,$B$24:$B$191,A12,$D$24:$D$191,"fusionar",$P$24:$P$191,"Sí") | K12: =G12+H12-J12
A13: 5-8|Física | B13: Ciclo 5°–8° | C13: TIMSS 2027 8.° | D13: Física | E13: ='TIMSS - Balance por ciclo'!I13 | F13: ='TIMSS - Balance por ciclo'!K13 | G13: =IF(COUNTIF($F$11:$F$14,"En meta")=ROWS($F$11:$F$14),0,MAX(0,ROUND(E13,0))) | H13: =COUNTIFS($B$24:$B$191,A13,$D$24:$D$191,"insertar",$E$24:$E$191,"cobertura") | I13: =IF(COUNTIF($F$11:$F$14,"En meta")=ROWS($F$11:$F$14),0,MAX(0,ROUND(-E13,0)))+H13 | J13: =SUMIFS($O$24:$O$191,$B$24:$B$191,A13,$D$24:$D$191,"fusionar",$P$24:$P$191,"Sí") | K13: =G13+H13-J13
A14: 5-8|Ciencias de la Tierra | B14: Ciclo 5°–8° | C14: TIMSS 2027 8.° | D14: Ciencias de la Tierra | E14: ='TIMSS - Balance por ciclo'!I14 | F14: ='TIMSS - Balance por ciclo'!K14 | G14: =IF(COUNTIF($F$11:$F$14,"En meta")=ROWS($F$11:$F$14),0,MAX(0,ROUND(E14,0))) | H14: =COUNTIFS($B$24:$B$191,A14,$D$24:$D$191,"insertar",$E$24:$E$191,"cobertura") | I14: =IF(COUNTIF($F$11:$F$14,"En meta")=ROWS($F$11:$F$14),0,MAX(0,ROUND(-E14,0)))+H14 | J14: =SUMIFS($O$24:$O$191,$B$24:$B$191,A14,$D$24:$D$191,"fusionar",$P$24:$P$191,"Sí") | K14: =G14+H14-J14
D15: Total Ciclo 5°–8° | G15: =SUM(G11:G14) | H15: =SUM(H11:H14) | I15: =SUM(I11:I14) | J15: =SUM(J11:J14) | K15: =SUM(K11:K14)
A17: 7-9|Sistemas físicos | B17: Ciclo 7°–9° | C17: PISA 2025 | D17: Sistemas físicos | E17: ='PISA - Contenidos'!I21 | F17: ='PISA - Contenidos'!K21 | G17: =IF(COUNTIF($F$17:$F$19,"En meta")=ROWS($F$17:$F$19),0,MAX(0,ROUND(E17,0))) | H17: =COUNTIFS($B$24:$B$191,A17,$D$24:$D$191,"insertar",$E$24:$E$191,"cobertura") | I17: =IF(COUNTIF($F$17:$F$19,"En meta")=ROWS($F$17:$F$19),0,MAX(0,ROUND(-E17,0)))+H17 | J17: =SUMIFS($O$24:$O$191,$B$24:$B$191,A17,$D$24:$D$191,"fusionar",$P$24:$P$191,"Sí") | K17: =G17+H17-J17
A18: 7-9|Sistemas vivos | B18: Ciclo 7°–9° | C18: PISA 2025 | D18: Sistemas vivos | E18: ='PISA - Contenidos'!I22 | F18: ='PISA - Contenidos'!K22 | G18: =IF(COUNTIF($F$17:$F$19,"En meta")=ROWS($F$17:$F$19),0,MAX(0,ROUND(E18,0))) | H18: =COUNTIFS($B$24:$B$191,A18,$D$24:$D$191,"insertar",$E$24:$E$191,"cobertura") | I18: =IF(COUNTIF($F$17:$F$19,"En meta")=ROWS($F$17:$F$19),0,MAX(0,ROUND(-E18,0)))+H18 | J18: =SUMIFS($O$24:$O$191,$B$24:$B$191,A18,$D$24:$D$191,"fusionar",$P$24:$P$191,"Sí") | K18: =G18+H18-J18
A19: 7-9|Sistemas de la Tierra y el espacio | B19: Ciclo 7°–9° | C19: PISA 2025 | D19: Sistemas de la Tierra y el espacio | E19: ='PISA - Contenidos'!I23 | F19: ='PISA - Contenidos'!K23 | G19: =IF(COUNTIF($F$17:$F$19,"En meta")=ROWS($F$17:$F$19),0,MAX(0,ROUND(E19,0))) | H19: =COUNTIFS($B$24:$B$191,A19,$D$24:$D$191,"insertar",$E$24:$E$191,"cobertura") | I19: =IF(COUNTIF($F$17:$F$19,"En meta")=ROWS($F$17:$F$19),0,MAX(0,ROUND(-E19,0)))+H19 | J19: =SUMIFS($O$24:$O$191,$B$24:$B$191,A19,$D$24:$D$191,"fusionar",$P$24:$P$191,"Sí") | K19: =G19+H19-J19
D20: Total Ciclo 7°–9° | G20: =SUM(G17:G19) | H20: =SUM(H17:H19) | I20: =SUM(I17:I19) | J20: =SUM(J17:J19) | K20: =SUM(K17:K19)
A22: Candidatos propuestos (ordenados por ciclo, acción, área y prioridad). La columna «Decisión del equipo» es para que el equipo de Ciencias anote si acepta.
A23: ID | B23: Clave | C23: Ciclo | D23: Acción | E23: Motivo | F23: Área | G23: Prioridad | H23: Grado | I23: Unidad | J23: Temas involucrados (ID · procedimental) | K23: Objetivos del marco | L23: Propuesta | M23: Justificación | N23: Confianza | O23: Libera (temas) | P23: ¿Entra en el presupuesto? | Q23: Decisión del equipo
A24: 2-4-I20 | B24: ="2-4|"&F24 | C24: Ciclo 2°–4° | D24: insertar | E24: cobertura | F24: Biología | G24: 1 | H24: 3 | I24: 5. Los animales. | K24: T4_27-B2.2, T4_27-B2.1 | L24: Comparación de rasgos heredados y no heredados entre crías y progenitores, y de estrategias que favorecen la supervivencia de la descendencia (muchas semillas, cuidado de crías). | M24: B2.2 sin ningún tema en el ciclo; Uruguay lo introduce en 3.°, junto a etapas de desarrollo. | N24: alta | O24: 0 | P24: =IF(D24="reubicar","Opcional (no cambia el total)",IF(E24="cobertura","Sí (cobertura)",IF(D24="insertar",IF(G24<=IFERROR(INDEX($G$6:$G$20,MATCH(B24,$A$6:$A$20,0)),0),"Sí","Reserva"),IF(SUMIFS($O$24:$O$191,$B$24:$B$191,B24,$D$24:$D$191,"fusionar",$G$24:$G$191,"<"&G24)<IFERROR(INDEX($I$6:$I$20,MATCH(B24,$A$6:$A$20,0)),0),"Sí","Reserva"))))
A25: 2-4-I13 | B25: ="2-4|"&F25 | C25: Ciclo 2°–4° | D25: insertar | E25: balance | F25: Ciencias de la Tierra | G25: 1 | H25: 2 | I25: 3. El movimiento | K25: T4_27-E2.1, T4_27-E5.1 | L25: Registro diario del estado del tiempo (temperatura, lluvia, nubes y viento) con símbolos y un termómetro sencillo. | M25: E2.1-A débil y E5.1 con un tema; Colombia lo introduce en 2.°. | N25: alta | O25: 0 | P25: =IF(D25="reubicar","Opcional (no cambia el total)",IF(E25="cobertura","Sí (cobertura)",IF(D25="insertar",IF(G25<=IFERROR(INDEX($G$6:$G$20,MATCH(B25,$A$6:$A$20,0)),0),"Sí","Reserva"),IF(SUMIFS($O$24:$O$191,$B$24:$B$191,B25,$D$24:$D$191,"fusionar",$G$24:$G$191,"<"&G25)<IFERROR(INDEX($I$6:$I$20,MATCH(B25,$A$6:$A$20,0)),0),"Sí","Reserva"))))
A26: 2-4-I14 | B26: ="2-4|"&F26 | C26: Ciclo 2°–4° | D26: insertar | E26: balance | F26: Ciencias de la Tierra | G26: 2 | H26: 3 | I26: 2. Interacciones terrestres. | K26: T4_27-E1.2 | L26: Indagación sobre los fósiles como evidencia de seres vivos del pasado y de cambios en la superficie terrestre. | M26: E1.2-B (fósiles) sin cubrir; Uruguay lo introduce en 3.°. | N26: alta | O26: 0 | P26: =IF(D26="reubicar","Opcional (no cambia el total)",IF(E26="cobertura","Sí (cobertura)",IF(D26="insertar",IF(G26<=IFERROR(INDEX($G$6:$G$20,MATCH(B26,$A$6:$A$20,0)),0),"Sí","Reserva"),IF(SUMIFS($O$24:$O$191,$B$24:$B$191,B26,$D$24:$D$191,"fusionar",$G$24:$G$191,"<"&G26)<IFERROR(INDEX($I$6:$I$20,MATCH(B26,$A$6:$A$20,0)),0),"Sí","Reserva"))))
A27: 2-4-I15 | B27: ="2-4|"&F27 | C27: Ciclo 2°–4° | D27: insertar | E27: balance | F27: Ciencias de la Tierra | G27: 3 | H27: 3 | I27: 2. Interacciones terrestres. | K27: T4_27-E5.1, T4_27-E2.1 | L27: Construcción y uso de pluviómetro, veleta y termómetro para medir y comparar variables del tiempo atmosférico. | M27: E5.1 con un solo tema; equipo citado explícitamente por TIMSS. | N27: alta | O27: 0 | P27: =IF(D27="reubicar","Opcional (no cambia el total)",IF(E27="cobertura","Sí (cobertura)",IF(D27="insertar",IF(G27<=IFERROR(INDEX($G$6:$G$20,MATCH(B27,$A$6:$A$20,0)),0),"Sí","Reserva"),IF(SUMIFS($O$24:$O$191,$B$24:$B$191,B27,$D$24:$D$191,"fusionar",$G$24:$G$191,"<"&G27)<IFERROR(INDEX($I$6:$I$20,MATCH(B27,$A$6:$A$20,0)),0),"Sí","Reserva"))))
A28: 2-4-I16 | B28: ="2-4|"&F28 | C28: Ciclo 2°–4° | D28: insertar | E28: balance | F28: Ciencias de la Tierra | G28: 4 | H28: 3 | I28: 2. Interacciones terrestres. | K28: T4_27-E2.1 | L28: Reconocimiento del calentamiento global y de algunos de sus efectos en el clima y las lluvias de El Salvador. | M28: E2.1-B (calentamiento global) ausente; objetivo ambiental. | N28: alta | O28: 0 | P28: =IF(D28="reubicar","Opcional (no cambia el total)",IF(E28="cobertura","Sí (cobertura)",IF(D28="insertar",IF(G28<=IFERROR(INDEX($G$6:$G$20,MATCH(B28,$A$6:$A$20,0)),0),"Sí","Reserva"),IF(SUMIFS($O$24:$O$191,$B$24:$B$191,B28,$D$24:$D$191,"fusionar",$G$24:$G$191,"<"&G28)<IFERROR(INDEX($I$6:$I$20,MATCH(B28,$A$6:$A$20,0)),0),"Sí","Reserva"))))
A29: 2-4-I17 | B29: ="2-4|"&F29 | C29: Ciclo 2°–4° | D29: insertar | E29: balance | F29: Ciencias de la Tierra | G29: 5 | H29: 2 | I29: 6. Ambiente y salud. | K29: T4_27-E1.2 | L29: Modelación del efecto del agua y el viento sobre la arena y el suelo para explicar cómo cambia el paisaje. | M29: E1.2-A (erosión) sin tratar; Colombia lo introduce en 2.°. | N29: media | O29: 0 | P29: =IF(D29="reubicar","Opcional (no cambia el total)",IF(E29="cobertura","Sí (cobertura)",IF(D29="insertar",IF(G29<=IFERROR(INDEX($G$6:$G$20,MATCH(B29,$A$6:$A$20,0)),0),"Sí","Reserva"),IF(SUMIFS($O$24:$O$191,$B$24:$B$191,B29,$D$24:$D$191,"fusionar",$G$24:$G$191,"<"&G29)<IFERROR(INDEX($I$6:$I$20,MATCH(B29,$A$6:$A$20,0)),0),"Sí","Reserva"))))
A30: 2-4-I18 | B30: ="2-4|"&F30 | C30: Ciclo 2°–4° | D30: insertar | E30: balance | F30: Ciencias de la Tierra | G30: 6 | H30: 2 | I30: 3. El movimiento | K30: T4_27-E4.2, T4_27-P3.1 | L30: Observación y registro de la posición del Sol y del tamaño de las sombras a lo largo del día. | M30: E4.2 débil (3); patrón diario observable y sencillo para 2.°. | N30: media | O30: 0 | P30: =IF(D30="reubicar","Opcional (no cambia el total)",IF(E30="cobertura","Sí (cobertura)",IF(D30="insertar",IF(G30<=IFERROR(INDEX($G$6:$G$20,MATCH(B30,$A$6:$A$20,0)),0),"Sí","Reserva"),IF(SUMIFS($O$24:$O$191,$B$24:$B$191,B30,$D$24:$D$191,"fusionar",$G$24:$G$191,"<"&G30)<IFERROR(INDEX($I$6:$I$20,MATCH(B30,$A$6:$A$20,0)),0),"Sí","Reserva"))))
A31: 2-4-I19 | B31: ="2-4|"&F31 | C31: Ciclo 2°–4° | D31: insertar | E31: balance | F31: Ciencias de la Tierra | G31: 7 | H31: 2 | I31: 3. El movimiento | K31: T4_27-E1.1 | L31: Representación de la proporción de agua y tierra en la superficie terrestre usando un globo terráqueo, distinguiendo agua dulce y salada. | M31: E1.1-A solo en hidrosfera de 3.°; unidad de destino discutible. | N31: baja | O31: 0 | P31: =IF(D31="reubicar","Opcional (no cambia el total)",IF(E31="cobertura","Sí (cobertura)",IF(D31="insertar",IF(G31<=IFERROR(INDEX($G$6:$G$20,MATCH(B31,$A$6:$A$20,0)),0),"Sí","Reserva"),IF(SUMIFS($O$24:$O$191,$B$24:$B$191,B31,$D$24:$D$191,"fusionar",$G$24:$G$191,"<"&G31)<IFERROR(INDEX($I$6:$I$20,MATCH(B31,$A$6:$A$20,0)),0),"Sí","Reserva"))))
A32: 2-4-I01 | B32: ="2-4|"&F32 | C32: Ciclo 2°–4° | D32: insertar | E32: balance | F32: Ciencias físicas | G32: 1 | H32: 4 | I32: 1. Máquinas y energía. | K32: T4_27-P4.1 | L32: Construcción de circuitos eléctricos sencillos con pila, cables y bombillo, comparando circuitos abiertos y cerrados y su representación en diagramas. | M32: P4.1 débil (3); circuito completo no se trabaja; 4.° tiene la mayor brecha física. | N32: alta | O32: 0 | P32: =IF(D32="reubicar","Opcional (no cambia el total)",IF(E32="cobertura","Sí (cobertura)",IF(D32="insertar",IF(G32<=IFERROR(INDEX($G$6:$G$20,MATCH(B32,$A$6:$A$20,0)),0),"Sí","Reserva"),IF(SUMIFS($O$24:$O$191,$B$24:$B$191,B32,$D$24:$D$191,"fusionar",$G$24:$G$191,"<"&G32)<IFERROR(INDEX($I$6:$I$20,MATCH(B32,$A$6:$A$20,0)),0),"Sí","Reserva"))))
A33: 2-4-I02 | B33: ="2-4|"&F33 | C33: Ciclo 2°–4° | D33: insertar | E33: balance | F33: Ciencias físicas | G33: 2 | H33: 4 | I33: 1. Máquinas y energía. | K33: T4_27-P2.2, T4_27-P1.2 | L33: Experimentación con la transferencia de calor entre objetos calientes y fríos en contacto, y con materiales conductores y aislantes térmicos de uso cotidiano. | M33: P2.2 con un solo tema; Uruguay y Colombia lo introducen antes. | N33: alta | O33: 0 | P33: =IF(D33="reubicar","Opcional (no cambia el total)",IF(E33="cobertura","Sí (cobertura)",IF(D33="insertar",IF(G33<=IFERROR(INDEX($G$6:$G$20,MATCH(B33,$A$6:$A$20,0)),0),"Sí","Reserva"),IF(SUMIFS($O$24:$O$191,$B$24:$B$191,B33,$D$24:$D$191,"fusionar",$G$24:$G$191,"<"&G33)<IFERROR(INDEX($I$6:$I$20,MATCH(B33,$A$6:$A$20,0)),0),"Sí","Reserva"))))
A34: 2-4-I03 | B34: ="2-4|"&F34 | C34: Ciclo 2°–4° | D34: insertar | E34: balance | F34: Ciencias físicas | G34: 3 | H34: 4 | I34: 1. Máquinas y energía. | K34: T4_27-P3.2 | L34: Experimentación con la propagación del sonido en el aire, el agua y los sólidos (teléfono de vasos) y la formación del eco. | M34: P3.2 con un solo tema (2.°); eco no se trabaja. | N34: alta | O34: 0 | P34: =IF(D34="reubicar","Opcional (no cambia el total)",IF(E34="cobertura","Sí (cobertura)",IF(D34="insertar",IF(G34<=IFERROR(INDEX($G$6:$G$20,MATCH(B34,$A$6:$A$20,0)),0),"Sí","Reserva"),IF(SUMIFS($O$24:$O$191,$B$24:$B$191,B34,$D$24:$D$191,"fusionar",$G$24:$G$191,"<"&G34)<IFERROR(INDEX($I$6:$I$20,MATCH(B34,$A$6:$A$20,0)),0),"Sí","Reserva"))))
A35: 2-4-I04 | B35: ="2-4|"&F35 | C35: Ciclo 2°–4° | D35: insertar | E35: balance | F35: Ciencias físicas | G35: 4 | H35: 3 | I35: 1. Medidas y fuerzas. | K35: T4_27-P4.2 | L35: Experimentación con imanes para identificar sus polos, la atracción y repulsión entre ellos y los objetos que atraen. | M35: P4.2 con un solo tema; Singapur lo introduce en 3.°; encaja con fuerzas a distancia. | N35: alta | O35: 0 | P35: =IF(D35="reubicar","Opcional (no cambia el total)",IF(E35="cobertura","Sí (cobertura)",IF(D35="insertar",IF(G35<=IFERROR(INDEX($G$6:$G$20,MATCH(B35,$A$6:$A$20,0)),0),"Sí","Reserva"),IF(SUMIFS($O$24:$O$191,$B$24:$B$191,B35,$D$24:$D$191,"fusionar",$G$24:$G$191,"<"&G35)<IFERROR(INDEX($I$6:$I$20,MATCH(B35,$A$6:$A$20,0)),0),"Sí","Reserva"))))
... A43: 2-4-I12 | B43: ="2-4|"&F43 | C43: Ciclo 2°–4° | D43: insertar | E43: balance | F43: Ciencias físicas | G43: 12 | H43: 4 | I43: 1. Máquinas y energía. | K43: T4_27-P3.1 | L43: Experimentación con la propagación de la luz a través del agua y de lentes sencillos para observar cómo se desvía. | M43: Segundo tema de luz; refracción menos central en TIMSS 4.°. | N43: baja | O43: 0 | P43: =IF(D43="reubicar","Opcional (no cambia el total)",IF(E43="cobertura","Sí (cobertura)",IF(D43="insertar",IF(G43<=IFERROR(INDEX($G$6:$G$20,MATCH(B43,$A$6:$A$20,0)),0),"Sí","Reserva"),IF(SUMIFS($O$24:$O$191,$B$24:$B$191,B43,$D$24:$D$191,"fusionar",$G$24:$G$191,"<"&G43)<IFERROR(INDEX($I$6:$I$20,MATCH(B43,$A$6:$A$20,0)),0),"Sí","Reserva"))))
