Workbook

Sheet Datos
A1: Concepto | B1: Clase (IA) | C1: Grado SV V2 | D1: Grado SV en 2-8 | E1: AU nucleo | F1: EE nucleo | G1: ENG nucleo | H1: HK nucleo | I1: JP nucleo | J1: KR nucleo | K1: ON nucleo | L1: SG nucleo | M1: TW nucleo | N1: AU nucleo 2-8 | O1: EE nucleo 2-8 | P1: ENG nucleo 2-8 | Q1: HK nucleo 2-8 | R1: JP nucleo 2-8 | S1: KR nucleo 2-8 | T1: ON nucleo 2-8 | U1: SG nucleo 2-8 | V1: TW nucleo 2-8 | W1: AU esp | X1: EE esp | Y1: ENG esp | Z1: HK esp | AA1: JP esp | AB1: KR esp | AC1: ON esp | AD1: SG esp | AE1: TW esp | AF1: Grado SV solido | AG1: Lectura amplia | AH1: Lectura estricta
A2: Aguas subterráneas y acuíferos | B2: adelantado | C2: 3 | D2: 3 | F2: 5 | I2: 3 | J2: 7 | K2: 7 | M2: 4.5 | O2: 1 | R2: 1 | S2: 1 | T2: 1 | V2: 1 | AF2: 3 | AG2: adelantado | AH2: adelantado
A3: Amenazas naturales geológicas e hidrometeorológicas | B3: adelantado | C3: 2 | D3: 2 | F3: 5 | H3: 5 | I3: 5 | J3: 2.5 | K3: 3 | L3: 7.5 | M3: 2.5 | O3: 1 | Q3: 1 | R3: 1 | S3: 1 | T3: 1 | U3: 1 | V3: 1 | Z3: 1 | AF3: 2 | AG3: adelantado | AH3: adelantado
A4: Capas internas de la Tierra | B4: adelantado | C4: 3 | D4: 3 | F4: 8 | G4: 6 | H4: 3 | J4: 7 | M4: 7 | O4: 1 | P4: 1 | Q4: 1 | S4: 1 | V4: 1 | AF4: 3 | AG4: adelantado | AH4: adelantado
A5: Ciclo de las rocas | B5: adelantado | C5: 3 | D5: 3 | E5: 4 | G5: 2 | H5: 4 | I5: 5 | J5: 7 | K5: 3 | N5: 1 | P5: 1 | Q5: 1 | R5: 1 | S5: 1 | T5: 1 | AF5: 3 | AG5: adelantado | AH5: alineado
A6: Ciclo del agua | B6: adelantado | C6: 2 | D6: 2 | E6: 3 | F6: 5 | G6: 2 | H6: 2 | I6: 3 | J6: 4.5 | K6: 7 | L6: 5 | M6: 4.5 | N6: 1 | O6: 1 | P6: 1 | Q6: 1 | R6: 1 | S6: 1 | T6: 1 | U6: 1 | V6: 1 | Z6: 1 | AF6: 3 | AG6: adelantado | AH6: adelantado
A7: Abastecimiento y conservación del agua dulce | B7: adelantado | C7: 3 | D7: 3 | F7: 5 | H7: 2 | J7: 7 | K7: 7 | L7: 5 | M7: 2.5 | O7: 1 | Q7: 1 | S7: 1 | T7: 1 | U7: 1 | V7: 1 | Z7: 1 | AF7: 7 | AG7: adelantado | AH7: alineado
A8: Eclipses solares y lunares | B8: adelantado | C8: 4 | D8: 4 | E8: 6 | H8: 5 | J8: 7 | K8: 8 | M8: 7 | N8: 1 | Q8: 1 | S8: 1 | T8: 1 | V8: 1 | AF8: 4 | AG8: adelantado | AH8: adelantado
A9: El Sol como estrella | B9: adelantado | C9: 2 | D9: 2 | G9: 6 | H9: 4 | I9: 5 | J9: 2.5 | K9: 5 | M9: 7 | P9: 1 | Q9: 1 | R9: 1 | S9: 1 | T9: 1 | V9: 1 | AF9: 2 | AG9: adelantado | AH9: adelantado
A10: Fósiles y su formación | B10: adelantado | C10: 3 | D10: 3 | F10: 8 | G10: 2 | H10: 4 | I10: 5 | J10: 4.5 | K10: 3 | M10: 4.5 | O10: 1 | P10: 1 | Q10: 1 | R10: 1 | S10: 1 | T10: 1 | V10: 1 | AF10: 3 | AG10: adelantado | AH10: adelantado
A11: Fuentes de energía renovables y no renovables | B11: adelantado | C11: 2 | D11: 2 | F11: 5 | G11: 6 | H11: 3 | I11: 5 | J11: 4.5 | K11: 3 | L11: 4.5 | M11: 2.5 | O11: 1 | P11: 1 | Q11: 1 | R11: 1 | S11: 1 | T11: 1 | U11: 1 | V11: 1 | Z11: 1 | AF11: 2 | AG11: adelantado | AH11: adelantado
A12: Galaxias y escala del universo | B12: adelantado | C12: 4 | D12: 4 | G12: 6 | H12: 4 | J12: 7 | K12: 8 | M12: 7 | P12: 1 | Q12: 1 | S12: 1 | T12: 1 | V12: 1 | AF12: 5 | AG12: adelantado | AH12: adelantado
A13: Impacto de las actividades humanas en los recursos | B13: adelantado | C13: 2 | D13: 2 | F13: 5 | H13: 7 | I13: 8 | J13: 2.5 | K13: 2 | L13: 5 | M13: 2.5 | O13: 1 | Q13: 1 | R13: 1 | S13: 1 | T13: 1 | U13: 1 | V13: 1 | AF13: 2 | AG13: adelantado | AH13: adelantado
A14: Límites de placas: convergentes, divergentes y transformantes | B14: adelantado | C14: 5 | D14: 5 | E14: 7 | F14: 8 | J14: 7 | M14: 7 | N14: 1 | O14: 1 | S14: 1 | V14: 1 | AF14: 5 | AG14: adelantado | AH14: adelantado
A15: Origen del magma y vulcanismo | B15: adelantado | C15: 4 | D15: 4 | H15: 5 | I15: 6 | J15: 7 | M15: 7 | Q15: 1 | R15: 1 | S15: 1 | V15: 1 | AF15: 5 | AG15: adelantado | AH15: adelantado
A16: Calidad y tratamiento del agua | B16: adelantado | C16: 3 | D16: 3 | F16: 5 | G16: 8.5 | H16: 2 | K16: 7 | L16: 5 | M16: 7 | O16: 1 | P16: 1 | Q16: 1 | T16: 1 | U16: 1 | V16: 1 | AF16: 3 | AG16: adelantado | AH16: adelantado
A17: El océano: propiedades del agua de mar y zonas | B17: adelantado | C17: 3 | D17: 3 | F17: 5 | H17: 7 | J17: 2.5 | M17: 7 | O17: 1 | Q17: 1 | S17: 1 | V17: 1 | AF17: 3 | AG17: adelantado | AH17: adelantado
A18: Registro fósil y cambios ambientales del pasado | B18: adelantado | C18: 3 | D18: 3 | H18: 4 | I18: 6 | J18: 4.5 | K18: 3 | M18: 4.5 | Q18: 1 | R18: 1 | S18: 1 | T18: 1 | V18: 1 | AF18: 3 | AG18: adelantado | AH18: adelantado
A19: Riesgo de desastre: amenaza, vulnerabilidad y prevención | B19: adelantado | C19: 2 | D19: 2 | F19: 8 | H19: 5 | I19: 6 | J19: 2.5 | M19: 2.5 | O19: 1 | Q19: 1 | R19: 1 | S19: 1 | V19: 1 | Z19: 1 | AF19: 2 | AG19: adelantado | AH19: adelantado
A20: Sismos y fallas geológicas | B20: adelantado | C20: 2 | D20: 2 | F20: 8 | H20: 5 | I20: 5 | J20: 2.5 | M20: 2.5 | O20: 1 | Q20: 1 | R20: 1 | S20: 1 | V20: 1 | AF20: 2 | AG20: adelantado | AH20: adelantado
A21: Tectónica de placas | B21: adelantado | C21: 4 | D21: 4 | E21: 7 | F21: 8 | G21: 6 | H21: 4 | I21: 5 | J21: 7 | K21: 3 | M21: 2.5 | N21: 1 | O21: 1 | P21: 1 | Q21: 1 | R21: 1 | S21: 1 | T21: 1 | V21: 1 | AF21: 4 | AG21: adelantado | AH21: adelantado
A22: Traslación de la Tierra y el año | B22: adelantado | C22: 2 | D22: 2 | E22: 5 | G22: 3 | H22: 2 | I22: 8 | J22: 4.5 | K22: 5 | M22: 4.5 | N22: 1 | P22: 1 | Q22: 1 | R22: 1 | S22: 1 | T22: 1 | V22: 1 | AF22: 2 | AG22: adelantado | AH22: adelantado
A23: Volcanes: estructura, tipos y productos | B23: adelantado | C23: 3 | D23: 3 | F23: 8 | I23: 5 | J23: 2.5 | O23: 1 | R23: 1 | S23: 1 | AF23: 3 | AG23: adelantado | AH23: adelantado
A24: Calentamiento global | B24: alineado | C24: 7 | D24: 7 | F24: 8 | G24: 6 | H24: 3 | J24: 2.5 | K24: 6 | L24: 7.5 | M24: 7 | O24: 1 | P24: 1 | Q24: 1 | S24: 1 | T24: 1 | U24: 1 | V24: 1 | AF24: 7 | AG24: alineado | AH24: alineado
A25: Campo magnético terrestre | B25: alineado | C25: 5 | D25: 5 | E25: 3 | F25: 2.5 | G25: 2 | H25: 2 | I25: 2 | J25: 4.5 | L25: 3 | M25: 4.5 | N25: 1 | O25: 1 | P25: 1 | Q25: 1 | R25: 1 | S25: 1 | U25: 1 | V25: 1 | AF25: 5 | AG25: alineado | AH25: tardio
A26: Cambio climático: causas y efectos | B26: alineado | C26: 7 | D26: 7 | F26: 8 | G26: 6 | H26: 3 | J26: 2.5 | K26: 4 | L26: 7.5 | M26: 4.5 | O26: 1 | P26: 1 | Q26: 1 | S26: 1 | T26: 1 | U26: 1 | V26: 1 | AF26: 7 | AG26: alineado | AH26: alineado
A27: Ciclo del carbono en los sistemas terrestres | B27: alineado | C27: 3 | D27: 3 | E27: 8 | F27: 5 | G27: 6 | H27: 5 | J27: 4.5 | K27: 4 | L27: 7.5 | M27: 2.5 | N27: 1 | O27: 1 | P27: 1 | Q27: 1 | S27: 1 | T27: 1 | U27: 1 | V27: 1 | AF27: 6 | AG27: adelantado | AH27: alineado
A28: Combustibles fósiles: formación y uso | B28: alineado | C28: 7 | D28: 7 | F28: 8 | G28: 6 | H28: 3 | K28: 4 | M28: 7 | O28: 1 | P28: 1 | Q28: 1 | T28: 1 | V28: 1 | Z28: 1 | AF28: 7 | AG28: alineado | AH28: alineado
A29: La atmósfera y su composición | B29: alineado | C29: 3 | D29: 3 | G29: 6 | H29: 2 | J29: 2.5 | K29: 4 | M29: 4.5 | P29: 1 | Q29: 1 | S29: 1 | T29: 1 | V29: 1 | AF29: 3 | AG29: alineado | AH29: alineado
A30: Conservación de recursos, residuos y sostenibilidad | B30: alineado | C30: 2 | D30: 2 | F30: 5 | G30: 6 | H30: 2 | I30: 8 | J30: 2.5 | K30: 2 | M30: 2.5 | O30: 1 | P30: 1 | Q30: 1 | R30: 1 | S30: 1 | T30: 1 | V30: 1 | AF30: 2 | AG30: alineado | AH30: alineado
A31: Efecto invernadero | B31: alineado | C31: 7 | D31: 7 | G31: 6 | H31: 7 | J31: 7 | K31: 5 | L31: 7.5 | M31: 7 | P31: 1 | Q31: 1 | S31: 1 | T31: 1 | U31: 1 | V31: 1 | AF31: 7 | AG31: alineado | AH31: alineado
A32: Erosión, transporte y sedimentación | B32: alineado | C32: 5 | D32: 5 | E32: 4 | F32: 8 | G32: 6 | H32: 4 | I32: 4 | J32: 2.5 | K32: 2 | M32: 2.5 | N32: 1 | O32: 1 | P32: 1 | Q32: 1 | R32: 1 | S32: 1 | T32: 1 | V32: 1 | AF32: 5 | AG32: alineado | AH32: alineado
A33: Estrellas y nebulosas | B33: alineado | C33: 4 | D33: 4 | G33: 6 | I33: 3 | J33: 2.5 | K33: 5 | M33: 7 | P33: 1 | R33: 1 | S33: 1 | T33: 1 | V33: 1 | AF33: 5 | AG33: alineado | AH33: alineado
A34: Exploración espacial | B34: alineado | C34: 4 | D34: 4 | H34: 3 | I34: 4 | J34: 7 | K34: 5 | Q34: 1 | R34: 1 | S34: 1 | T34: 1 | AF34: 4 | AG34: alineado | AH34: alineado
A35: Fases de la Luna | B35: alineado | C35: 4 | D35: 4 | E35: 2 | G35: 3 | H35: 2 | I35: 3 | J35: 2.5 | K35: 8 | M35: 2.5 | N35: 1 | P35: 1 | Q35: 1 | R35: 1 | S35: 1 | T35: 1 | V35: 1 | AF35: 4 | AG35: alineado | AH35: alineado
A36: Gravedad y órbitas | B36: alineado | C36: 3 | D36: 3 | G36: 3 | H36: 2 | I36: 8 | J36: 7 | M36: 4.5 | P36: 1 | Q36: 1 | R36: 1 | S36: 1 | V36: 1 | AF36: 8 | AG36: alineado | AH36: alineado
A37: Hidrosfera: distribución del agua dulce y salada | B37: alineado | C37: 3 | D37: 3 | E37: 3 | F37: 5 | H37: 2 | J37: 2.5 | K37: 7 | M37: 4.5 | N37: 1 | O37: 1 | Q37: 1 | S37: 1 | T37: 1 | V37: 1 | AF37: 3 | AG37: adelantado | AH37: alineado
A38: Inclinación del eje terrestre y estaciones astronómicas | B38: alineado | C38: 2 | D38: 2 | E38: 5 | F38: 2.5 | G38: 2 | H38: 2 | I38: 8 | J38: 4.5 | K38: 8 | M38: 2.5 | N38: 1 | O38: 1 | P38: 1 | Q38: 1 | R38: 1 | S38: 1 | T38: 1 | V38: 1 | AF38: 4 | AG38: adelantado | AH38: alineado
A39: Interacción océano-atmósfera | B39: alineado | C39: 7 | D39: 7 | F39: 5 | I39: 7 | J39: 7 | K39: 7 | M39: 4.5 | O39: 1 | R39: 1 | S39: 1 | T39: 1 | V39: 1 | AF39: 8 | AG39: alineado | AH39: alineado
A40: La Luna: características y origen | B40: alineado | C40: 4 | D40: 4 | G40: 3 | H40: 2 | I40: 5 | J40: 2.5 | M40: 7 | P40: 1 | Q40: 1 | R40: 1 | S40: 1 | V40: 1 | AF40: 4 | AG40: alineado | AH40: alineado
...

Sheet Contraste
A1: Concepto | B1: Grado SV V2 | C1: Paises con nucleo | D1: Mediana nucleo | E1: Paises con especializacion | F1: Diferencia SV - mediana | G1: Grado SV en 2-8 | H1: Paises con nucleo en 2-8 | I1: Lectura (regla simplificada) | J1: Clase oficial
A2: =Datos!A2 | B2: =IF(Datos!C2="","",Datos!C2) | C2: =COUNT(Datos!E2:M2) | D2: =IF(C2=0,"",MEDIAN(Datos!E2:M2)) | E2: =COUNT(Datos!W2:AE2) | F2: =IF(OR(B2="",D2=""),"",B2-D2) | G2: =IF(Datos!D2="","",Datos!D2) | H2: =COUNT(Datos!N2:V2) | I2: =IF(B2="",IF(C2>=5,"falta en SV",""),IF(G2="",IF(B2>8,IF(C2>=5,"SV tarde","despues del tramo"),IF(H2>=5,"no retomado en 2-8","previo")),IF(B2<2,"retomado",IF(AND(C2<=1,E2>=3),"solo especializacion",IF(F2="","coherente",IF(F2<=-1.5,"SV adelantado",IF(F2>=2,"SV tarde","coherente"))))))) | J2: =Datos!B2
A3: =Datos!A3 | B3: =IF(Datos!C3="","",Datos!C3) | C3: =COUNT(Datos!E3:M3) | D3: =IF(C3=0,"",MEDIAN(Datos!E3:M3)) | E3: =COUNT(Datos!W3:AE3) | F3: =IF(OR(B3="",D3=""),"",B3-D3) | G3: =IF(Datos!D3="","",Datos!D3) | H3: =COUNT(Datos!N3:V3) | I3: =IF(B3="",IF(C3>=5,"falta en SV",""),IF(G3="",IF(B3>8,IF(C3>=5,"SV tarde","despues del tramo"),IF(H3>=5,"no retomado en 2-8","previo")),IF(B3<2,"retomado",IF(AND(C3<=1,E3>=3),"solo especializacion",IF(F3="","coherente",IF(F3<=-1.5,"SV adelantado",IF(F3>=2,"SV tarde","coherente"))))))) | J3: =Datos!B3
A4: =Datos!A4 | B4: =IF(Datos!C4="","",Datos!C4) | C4: =COUNT(Datos!E4:M4) | D4: =IF(C4=0,"",MEDIAN(Datos!E4:M4)) | E4: =COUNT(Datos!W4:AE4) | F4: =IF(OR(B4="",D4=""),"",B4-D4) | G4: =IF(Datos!D4="","",Datos!D4) | H4: =COUNT(Datos!N4:V4) | I4: =IF(B4="",IF(C4>=5,"falta en SV",""),IF(G4="",IF(B4>8,IF(C4>=5,"SV tarde","despues del tramo"),IF(H4>=5,"no retomado en 2-8","previo")),IF(B4<2,"retomado",IF(AND(C4<=1,E4>=3),"solo especializacion",IF(F4="","coherente",IF(F4<=-1.5,"SV adelantado",IF(F4>=2,"SV tarde","coherente"))))))) | J4: =Datos!B4
A5: =Datos!A5 | B5: =IF(Datos!C5="","",Datos!C5) | C5: =COUNT(Datos!E5:M5) | D5: =IF(C5=0,"",MEDIAN(Datos!E5:M5)) | E5: =COUNT(Datos!W5:AE5) | F5: =IF(OR(B5="",D5=""),"",B5-D5) | G5: =IF(Datos!D5="","",Datos!D5) | H5: =COUNT(Datos!N5:V5) | I5: =IF(B5="",IF(C5>=5,"falta en SV",""),IF(G5="",IF(B5>8,IF(C5>=5,"SV tarde","despues del tramo"),IF(H5>=5,"no retomado en 2-8","previo")),IF(B5<2,"retomado",IF(AND(C5<=1,E5>=3),"solo especializacion",IF(F5="","coherente",IF(F5<=-1.5,"SV adelantado",IF(F5>=2,"SV tarde","coherente"))))))) | J5: =Datos!B5
A6: =Datos!A6 | B6: =IF(Datos!C6="","",Datos!C6) | C6: =COUNT(Datos!E6:M6) | D6: =IF(C6=0,"",MEDIAN(Datos!E6:M6)) | E6: =COUNT(Datos!W6:AE6) | F6: =IF(OR(B6="",D6=""),"",B6-D6) | G6: =IF(Datos!D6="","",Datos!D6) | H6: =COUNT(Datos!N6:V6) | I6: =IF(B6="",IF(C6>=5,"falta en SV",""),IF(G6="",IF(B6>8,IF(C6>=5,"SV tarde","despues del tramo"),IF(H6>=5,"no retomado en 2-8","previo")),IF(B6<2,"retomado",IF(AND(C6<=1,E6>=3),"solo especializacion",IF(F6="","coherente",IF(F6<=-1.5,"SV adelantado",IF(F6>=2,"SV tarde","coherente"))))))) | J6: =Datos!B6
A7: =Datos!A7 | B7: =IF(Datos!C7="","",Datos!C7) | C7: =COUNT(Datos!E7:M7) | D7: =IF(C7=0,"",MEDIAN(Datos!E7:M7)) | E7: =COUNT(Datos!W7:AE7) | F7: =IF(OR(B7="",D7=""),"",B7-D7) | G7: =IF(Datos!D7="","",Datos!D7) | H7: =COUNT(Datos!N7:V7) | I7: =IF(B7="",IF(C7>=5,"falta en SV",""),IF(G7="",IF(B7>8,IF(C7>=5,"SV tarde","despues del tramo"),IF(H7>=5,"no retomado en 2-8","previo")),IF(B7<2,"retomado",IF(AND(C7<=1,E7>=3),"solo especializacion",IF(F7="","coherente",IF(F7<=-1.5,"SV adelantado",IF(F7>=2,"SV tarde","coherente"))))))) | J7: =Datos!B7
A8: =Datos!A8 | B8: =IF(Datos!C8="","",Datos!C8) | C8: =COUNT(Datos!E8:M8) | D8: =IF(C8=0,"",MEDIAN(Datos!E8:M8)) | E8: =COUNT(Datos!W8:AE8) | F8: =IF(OR(B8="",D8=""),"",B8-D8) | G8: =IF(Datos!D8="","",Datos!D8) | H8: =COUNT(Datos!N8:V8) | I8: =IF(B8="",IF(C8>=5,"falta en SV",""),IF(G8="",IF(B8>8,IF(C8>=5,"SV tarde","despues del tramo"),IF(H8>=5,"no retomado en 2-8","previo")),IF(B8<2,"retomado",IF(AND(C8<=1,E8>=3),"solo especializacion",IF(F8="","coherente",IF(F8<=-1.5,"SV adelantado",IF(F8>=2,"SV tarde","coherente"))))))) | J8: =Datos!B8
A9: =Datos!A9 | B9: =IF(Datos!C9="","",Datos!C9) | C9: =COUNT(Datos!E9:M9) | D9: =IF(C9=0,"",MEDIAN(Datos!E9:M9)) | E9: =COUNT(Datos!W9:AE9) | F9: =IF(OR(B9="",D9=""),"",B9-D9) | G9: =IF(Datos!D9="","",Datos!D9) | H9: =COUNT(Datos!N9:V9) | I9: =IF(B9="",IF(C9>=5,"falta en SV",""),IF(G9="",IF(B9>8,IF(C9>=5,"SV tarde","despues del tramo"),IF(H9>=5,"no retomado en 2-8","previo")),IF(B9<2,"retomado",IF(AND(C9<=1,E9>=3),"solo especializacion",IF(F9="","coherente",IF(F9<=-1.5,"SV adelantado",IF(F9>=2,"SV tarde","coherente"))))))) | J9: =Datos!B9
A10: =Datos!A10 | B10: =IF(Datos!C10="","",Datos!C10) | C10: =COUNT(Datos!E10:M10) | D10: =IF(C10=0,"",MEDIAN(Datos!E10:M10)) | E10: =COUNT(Datos!W10:AE10) | F10: =IF(OR(B10="",D10=""),"",B10-D10) | G10: =IF(Datos!D10="","",Datos!D10) | H10: =COUNT(Datos!N10:V10) | I10: =IF(B10="",IF(C10>=5,"falta en SV",""),IF(G10="",IF(B10>8,IF(C10>=5,"SV tarde","despues del tramo"),IF(H10>=5,"no retomado en 2-8","previo")),IF(B10<2,"retomado",IF(AND(C10<=1,E10>=3),"solo especializacion",IF(F10="","coherente",IF(F10<=-1.5,"SV adelantado",IF(F10>=2,"SV tarde","coherente"))))))) | J10: =Datos!B10
A11: =Datos!A11 | B11: =IF(Datos!C11="","",Datos!C11) | C11: =COUNT(Datos!E11:M11) | D11: =IF(C11=0,"",MEDIAN(Datos!E11:M11)) | E11: =COUNT(Datos!W11:AE11) | F11: =IF(OR(B11="",D11=""),"",B11-D11) | G11: =IF(Datos!D11="","",Datos!D11) | H11: =COUNT(Datos!N11:V11) | I11: =IF(B11="",IF(C11>=5,"falta en SV",""),IF(G11="",IF(B11>8,IF(C11>=5,"SV tarde","despues del tramo"),IF(H11>=5,"no retomado en 2-8","previo")),IF(B11<2,"retomado",IF(AND(C11<=1,E11>=3),"solo especializacion",IF(F11="","coherente",IF(F11<=-1.5,"SV adelantado",IF(F11>=2,"SV tarde","coherente"))))))) | J11: =Datos!B11
A12: =Datos!A12 | B12: =IF(Datos!C12="","",Datos!C12) | C12: =COUNT(Datos!E12:M12) | D12: =IF(C12=0,"",MEDIAN(Datos!E12:M12)) | E12: =COUNT(Datos!W12:AE12) | F12: =IF(OR(B12="",D12=""),"",B12-D12) | G12: =IF(Datos!D12="","",Datos!D12) | H12: =COUNT(Datos!N12:V12) | I12: =IF(B12="",IF(C12>=5,"falta en SV",""),IF(G12="",IF(B12>8,IF(C12>=5,"SV tarde","despues del tramo"),IF(H12>=5,"no retomado en 2-8","previo")),IF(B12<2,"retomado",IF(AND(C12<=1,E12>=3),"solo especializacion",IF(F12="","coherente",IF(F12<=-1.5,"SV adelantado",IF(F12>=2,"SV tarde","coherente"))))))) | J12: =Datos!B12
A13: =Datos!A13 | B13: =IF(Datos!C13="","",Datos!C13) | C13: =COUNT(Datos!E13:M13) | D13: =IF(C13=0,"",MEDIAN(Datos!E13:M13)) | E13: =COUNT(Datos!W13:AE13) | F13: =IF(OR(B13="",D13=""),"",B13-D13) | G13: =IF(Datos!D13="","",Datos!D13) | H13: =COUNT(Datos!N13:V13) | I13: =IF(B13="",IF(C13>=5,"falta en SV",""),IF(G13="",IF(B13>8,IF(C13>=5,"SV tarde","despues del tramo"),IF(H13>=5,"no retomado en 2-8","previo")),IF(B13<2,"retomado",IF(AND(C13<=1,E13>=3),"solo especializacion",IF(F13="","coherente",IF(F13<=-1.5,"SV adelantado",IF(F13>=2,"SV tarde","coherente"))))))) | J13: =Datos!B13
... A79: =Datos!A79 | B79: =IF(Datos!C79="","",Datos!C79) | C79: =COUNT(Datos!E79:M79) | D79: =IF(C79=0,"",MEDIAN(Datos!E79:M79)) | E79: =COUNT(Datos!W79:AE79) | F79: =IF(OR(B79="",D79=""),"",B79-D79) | G79: =IF(Datos!D79="","",Datos!D79) | H79: =COUNT(Datos!N79:V79) | I79: =IF(B79="",IF(C79>=5,"falta en SV",""),IF(G79="",IF(B79>8,IF(C79>=5,"SV tarde","despues del tramo"),IF(H79>=5,"no retomado en 2-8","previo")),IF(B79<2,"retomado",IF(AND(C79<=1,E79>=3),"solo especializacion",IF(F79="","coherente",IF(F79<=-1.5,"SV adelantado",IF(F79>=2,"SV tarde","coherente"))))))) | J79: =Datos!B79

Sheet Resumen
A1: Clase | B1: Conceptos
A2: faltante | B2: =COUNTIF(Datos!B2:B79,A2)
A3: tardio | B3: =COUNTIF(Datos!B2:B79,A3)
A4: posterior | B4: =COUNTIF(Datos!B2:B79,A4)
A5: adelantado | B5: =COUNTIF(Datos!B2:B79,A5)
A6: sin_referente | B6: =COUNTIF(Datos!B2:B79,A6)
A7: alineado | B7: =COUNTIF(Datos!B2:B79,A7)
A8: incierto | B8: =COUNTIF(Datos!B2:B79,A8)
A9: Total | B9: =SUM(B2:B8)
